Workbook

Sheet потребность
A1: Блок 14, ул. Токомбаева
A2: Арматура
A3: Диаметр | B3: Ед. изм. | C3: 1 этаж | G3: Итого | H3: Заказ (раскрой под прутки 11,7 м)
C4: Колонны, диафрагмы | D4: Плита перекрытия, балки, ригели | E4: Лестницы (ЛВ-1) | F4: Сетки-гребёнки С-1 | H4: Прутков 11,7 м, шт | I4: Масса заказа, кг | J4: Отход, %
A5: Диаметр 32 А500С | B5: кг | C5: ='1 этаж'!AI8 -> 2020.16 | D5: ='1 этаж'!AL8 -> 643.2947 | E5: ='1 этаж'!AO8 -> 0 | F5: ='1 этаж'!AR8 -> 0 | G5: =SUM(C5:F5) -> 2663.4547 | H5: ='Раскрой 11,7м'!F189 -> 44 | I5: ='Раскрой 11,7м'!I189 -> 3249.9324 | J5: ='Раскрой 11,7м'!L189 -> 0.18045843
A6: Диаметр 28 А500С | B6: кг | C6: ='1 этаж'!AI9 -> 2010.944 | D6: ='1 этаж'!AL9 -> 4612.1194 | E6: ='1 этаж'!AO9 -> 0 | F6: ='1 этаж'!AR9 -> 0 | G6: =SUM(C6:F6) -> 6623.0634 | H6: ='Раскрой 11,7м'!F190 -> 132 | I6: ='Раскрой 11,7м'!I190 -> 7465.6296 | J6: ='Раскрой 11,7м'!L190 -> 0.11285936
A7: Диаметр 25 А500С | B7: кг | C7: ='1 этаж'!AI10 -> 554.832 | D7: ='1 этаж'!AL10 -> 2915.1798 | E7: ='1 этаж'!AO10 -> 0 | F7: ='1 этаж'!AR10 -> 0 | G7: =SUM(C7:F7) -> 3470.0118 | H7: ='Раскрой 11,7м'!F191 -> 81 | I7: ='Раскрой 11,7м'!I191 -> 3651.4881 | J7: ='Раскрой 11,7м'!L191 -> 0.049699272
A8: Диаметр 22 А500С | B8: кг | C8: ='1 этаж'!AI11 -> 468.488 | D8: ='1 этаж'!AL11 -> 644.8424 | E8: ='1 этаж'!AO11 -> 0 | F8: ='1 этаж'!AR11 -> 0 | G8: =SUM(C8:F8) -> 1113.3304 | H8: ='Раскрой 11,7м'!F192 -> 35 | I8: ='Раскрой 11,7м'!I192 -> 1221.948 | J8: ='Раскрой 11,7м'!L192 -> 0.088888889
A9: Диаметр 20 А500С | B9: кг | C9: ='1 этаж'!AI12 -> 1732.8582 | D9: ='1 этаж'!AL12 -> 205.02324 | E9: ='1 этаж'!AO12 -> 0 | F9: ='1 этаж'!AR12 -> 0 | G9: =SUM(C9:F9) -> 1937.8814 | H9: ='Раскрой 11,7м'!F193 -> 87 | I9: ='Раскрой 11,7м'!I193 -> 2510.1414 | J9: ='Раскрой 11,7м'!L193 -> 0.22797917
A10: Диаметр 18 А500С | B10: кг | C10: ='1 этаж'!AI13 -> 280.99872 | D10: ='1 этаж'!AL13 -> 925.36171 | E10: ='1 этаж'!AO13 -> 0 | F10: ='1 этаж'!AR13 -> 0 | G10: =SUM(C10:F10) -> 1206.3604 | H10: ='Раскрой 11,7м'!F194 -> 53 | I10: ='Раскрой 11,7м'!I194 -> 1238.9598 | J10: ='Раскрой 11,7м'!L194 -> 0.026311885
A11: Диаметр 16 А500С | B11: кг | C11: ='1 этаж'!AI14 -> 693.3732 | D11: ='1 этаж'!AL14 -> 845.22098 | E11: ='1 этаж'!AO14 -> 0 | F11: ='1 этаж'!AR14 -> 0 | G11: =SUM(C11:F11) -> 1538.5942 | H11: ='Раскрой 11,7м'!F195 -> 85 | I11: ='Раскрой 11,7м'!I195 -> 1569.321 | J11: ='Раскрой 11,7м'!L195 -> 0.019579688
A12: Диаметр 14 А500С | B12: кг | C12: ='1 этаж'!AI15 -> 73.5672 | D12: ='1 этаж'!AL15 -> 216.90848 | E12: ='1 этаж'!AO15 -> 0 | F12: ='1 этаж'!AR15 -> 0 | G12: =SUM(C12:F12) -> 290.47568 | H12: ='Раскрой 11,7м'!F196 -> 21 | I12: ='Раскрой 11,7м'!I196 -> 296.8056 | J12: ='Раскрой 11,7м'!L196 -> 0.021326821
A13: Диаметр 12 А500С | B13: кг | C13: ='1 этаж'!AI16 -> 0 | D13: ='1 этаж'!AL16 -> 215.05939 | E13: ='1 этаж'!AO16 -> 0 | F13: ='1 этаж'!AR16 -> 0 | G13: =SUM(C13:F13) -> 215.05939 | H13: ='Раскрой 11,7м'!F197 -> 22 | I13: ='Раскрой 11,7м'!I197 -> 228.5712 | J13: ='Раскрой 11,7м'!L197 -> 0.059114219
A14: Диаметр 10 А500С | B14: кг | C14: ='1 этаж'!AI17 -> 7.5891 | D14: ='1 этаж'!AL17 -> 7425.632 | E14: ='1 этаж'!AO17 -> 0 | F14: ='1 этаж'!AR17 -> 590.8392 | G14: =SUM(C14:F14) -> 8024.0603 | H14: ='Раскрой 11,7м'!F198 -> 1121 | I14: ='Раскрой 11,7м'!I198 -> 8092.3869 | J14: ='Раскрой 11,7м'!L198 -> 0.008443316
A15: Диаметр 8 А500С | B15: кг | C15: ='1 этаж'!AI18 -> 0 | D15: ='1 этаж'!AL18 -> 0 | E15: ='1 этаж'!AO18 -> 0 | F15: ='1 этаж'!AR18 -> 0 | G15: =SUM(C15:F15) -> 0 | H15: ='Раскрой 11,7м'!F199 -> 0 | I15: ='Раскрой 11,7м'!I199 -> 0 | J15: ='Раскрой 11,7м'!L199 -> 0
A16: Диаметр 12 А240 | B16: кг | C16: ='1 этаж'!AI19 -> 0 | D16: ='1 этаж'!AL19 -> 0 | E16: ='1 этаж'!AO19 -> 0 | F16: ='1 этаж'!AR19 -> 0 | G16: =SUM(C16:F16) -> 0 | H16: ='Раскрой 11,7м'!F200 -> 0 | I16: ='Раскрой 11,7м'!I200 -> 0 | J16: ='Раскрой 11,7м'!L200 -> 0
... A19: Диаметр 6 А240 | B19: кг | C19: ='1 этаж'!AI22 -> 0 | D19: ='1 этаж'!AL22 -> 0 | E19: ='1 этаж'!AO22 -> 0 | F19: ='1 этаж'!AR22 -> 0 | G19: =SUM(C19:F19) -> 0 | H19: ='Раскрой 11,7м'!F203 -> 0 | I19: ='Раскрой 11,7м'!I203 -> 0 | J19: ='Раскрой 11,7м'!L203 -> 0
A20: Итого: | B20: кг | C20: =SUM(C5:C19) -> 9396.4436 | D20: =SUM(D5:D19) -> 21800.826 | E20: =SUM(E5:E19) -> 0 | F20: =SUM(F5:F19) -> 590.8392 | G20: =SUM(G5:G19) -> 31788.108 | H20: =SUM(H5:H19) -> 2573 | I20: =SUM(I5:I19) -> 34276.133 | J20: ='Раскрой 11,7м'!L204 -> 0.072587661
A21: Итого: | B21: т | C21: =C20/1000 -> 9.3964436 | D21: =D20/1000 -> 21.800826 | E21: =E20/1000 -> 0 | F21: =F20/1000 -> 0.5908392 | G21: =G20/1000 -> 31.788108 | I21: =I20/1000 -> 34.276133
A22: Контроль: итог = «1 этаж» и «Ведомость» | G22: =ROUND(G20-'1 этаж'!AF23,1) -> 0 | H22: ← должно быть 0
A24: Бетон
A25: Марка | B25: Ед. изм. | C25: 1 этаж | G25: Итого
C26: Колонны, диафрагмы | D26: Плита перекрытия, балки, ригели | E26: Лестницы (ЛВ-1) | F26: Сетки-гребёнки С-1
A27: В25 | B27: м3 | C27: ='1 этаж'!AI28 -> 43.9216 | D27: ='1 этаж'!AL28 -> 112.11321 | E27: ='1 этаж'!AO28 -> 0 | F27: ='1 этаж'!AR28 -> 0 | G27: =SUM(C27:F27) -> 156.03481
A28: Итого: | B28: м3 | C28: =SUM(C27:C27) -> 43.9216 | D28: =SUM(D27:D27) -> 112.11321 | E28: =SUM(E27:E27) -> 0 | F28: =SUM(F27:F27) -> 0 | G28: =SUM(G27:G27) -> 156.03481
A30: Прочие материалы
A31: Наименование | B31: Ед. изм. | C31: 1 этаж | G31: Итого
C32: Колонны, диафрагмы | D32: Плита перекрытия, балки, ригели | E32: Лестницы (ЛВ-1) | F32: Сетки-гребёнки С-1
A33: Анкерная шайба АШ-1 (14) | B33: шт. | C33: ='1 этаж'!AG32 -> 0 | D33: ='1 этаж'!AJ32 -> 0 | E33: ='1 этаж'!AM32 -> 0 | F33: ='1 этаж'!AP32 -> 0 | G33: =SUM(C33:F33) -> 0
A34: Анкерная шайба АШ-2 (16) | B34: шт. | C34: ='1 этаж'!AG33 -> 0 | D34: ='1 этаж'!AJ33 -> 0 | E34: ='1 этаж'!AM33 -> 0 | F34: ='1 этаж'!AP33 -> 0 | G34: =SUM(C34:F34) -> 0
A35: Анкерная шайба АШ-3 (18) | B35: шт. | C35: ='1 этаж'!AG34 -> 0 | D35: ='1 этаж'!AJ34 -> 0 | E35: ='1 этаж'!AM34 -> 0 | F35: ='1 этаж'!AP34 -> 0 | G35: =SUM(C35:F35) -> 0
A36: Анкерная шайба АШ-4 (20) | B36: шт. | C36: ='1 этаж'!AG35 -> 0 | D36: ='1 этаж'!AJ35 -> 0 | E36: ='1 этаж'!AM35 -> 0 | F36: ='1 этаж'!AP35 -> 0 | G36: =SUM(C36:F36) -> 0
A37: Анкерная шайба АШ-5 (22) | B37: шт. | C37: ='1 этаж'!AG36 -> 0 | D37: ='1 этаж'!AJ36 -> 2 | E37: ='1 этаж'!AM36 -> 0 | F37: ='1 этаж'!AP36 -> 0 | G37: =SUM(C37:F37) -> 2
A38: Анкерная шайба АШ-6 (25) | B38: шт. | C38: ='1 этаж'!AG37 -> 0 | D38: ='1 этаж'!AJ37 -> 16 | E38: ='1 этаж'!AM37 -> 0 | F38: ='1 этаж'!AP37 -> 0 | G38: =SUM(C38:F38) -> 16
A39: Анкерная шайба АШ-7 (28) | B39: шт. | C39: ='1 этаж'!AG38 -> 0 | D39: ='1 этаж'!AJ38 -> 86 | E39: ='1 этаж'!AM38 -> 0 | F39: ='1 этаж'!AP38 -> 0 | G39: =SUM(C39:F39) -> 86
A40: Анкерная шайба АШ-8 (32) | B40: шт. | C40: ='1 этаж'!AG39 -> 0 | D40: ='1 этаж'!AJ39 -> 6 | E40: ='1 этаж'!AM39 -> 0 | F40: ='1 этаж'!AP39 -> 0 | G40: =SUM(C40:F40) -> 6
A41: Ванночка d32 (стыков ванной сваркой) | B41: шт. | C41: ='1 этаж'!AG40 -> 80 | D41: ='1 этаж'!AJ40 -> 0 | E41: ='1 этаж'!AM40 -> 0 | F41: ='1 этаж'!AP40 -> 0 | G41: =SUM(C41:F41) -> 80
A42: Ванночка d28 (стыков ванной сваркой) | B42: шт. | C42: ='1 этаж'!AG41 -> 104 | D42: ='1 этаж'!AJ41 -> 52 | E42: ='1 этаж'!AM41 -> 0 | F42: ='1 этаж'!AP41 -> 0 | G42: =SUM(C42:F42) -> 156
A43: Ванночка d25 (стыков ванной сваркой) | B43: шт. | C43: ='1 этаж'!AG42 -> 36 | D43: ='1 этаж'!AJ42 -> 40 | E43: ='1 этаж'!AM42 -> 0 | F43: ='1 этаж'!AP42 -> 0 | G43: =SUM(C43:F43) -> 76
A44: Ванночка d22 (стыков ванной сваркой) | B44: шт. | C44: ='1 этаж'!AG43 -> 36 | D44: ='1 этаж'!AJ43 -> 0 | E44: ='1 этаж'!AM43 -> 0 | F44: ='1 этаж'!AP43 -> 0 | G44: =SUM(C44:F44) -> 36
...

Sheet 1 этаж
A1: Блок 14, ул. Токомбаева — 1 этаж: подсчёт арматуры по элементам (м.п. → кг)
A2: м.п. в каждой ячейке = SUMIFS из листа «Ведомость» по Ø, классу и колонке; кг/м — «Исходные»; Всего = м.п. × кг/м × К(зап) | AG2: К(зап) арматура | AH2: =Исходные!$B$13 -> 1 | AJ2: К(зап) бетон | AK2: =Исходные!$B$14 -> 1
B4: Диафрагмы | G4: Колонны | K4: Ригели +3.950 | S4: Балки плиты | V4: Перекрытие +3.950 | AB4: Лестничный марш | AC4: Сетки-гребёнки | AG4: Колонны, диафрагмы | AJ4: Ригели, балки, плита | AM4: Лестницы | AP4: Сетки С-1
A5: На отметке -0.050…+3.950 | B5: По оси А / 4 | C5: По оси А / 2 | D5: По оси Г / 2 | E5: По оси Г / 3 | F5: По оси Г / 4 | G5: По оси А | H5: По оси Б | I5: По оси В | J5: По оси Г | K5: По оси А | L5: По оси Б | M5: По оси В | N5: По оси Г | O5: По осям 1, 5 | P5: По оси 2 | Q5: По оси 3 | R5: По оси 4 | S5: Основная | T5: Хомуты | U5: Допник | V5: Основная | W5: Шпильки, фиксаторы | X5: Отверстия | Y5: Допник | AA5: Край | AB5: ЛВ-1 | AC5: С-1 | AD5: Итого: | AE5: Масса ед. кг | AF5: Всего | AG5: Итого: | AH5: Масса ед. кг | AI5: Всего | AJ5: Итого: | AK5: Масса ед. кг | AL5: Всего | AM5: Итого: | AN5: Масса ед. кг | AO5: Всего | AP5: Итого: | AQ5: Масса ед. кг | AR5: Всего
A6: (1 этаж) | B6: Дм-1 | C6: Дм-2 | D6: Дм-3 | E6: Дм-4 | F6: Дм-5 | G6: К 1-1 (3) | H6: К 1-1 (5) | I6: К 1-1 (5) | J6: К 1-1 (2) | K6: Ригель 4-4 | L6: Ригель 4-4 | M6: Ригель 4-4 | N6: Ригель 4-4 | O6: Ригель 5-5 (2) | P6: Ригель 5-5 | Q6: Ригель 5-5 | R6: Ригель 5-5 | S6: сеч.1-1…5-5 | T6: поз.10–13 | U6: Ø18 L=1200 | V6: сетка Ø10/200 низ+верх | W6: ш.800 | X6: — | Y6: Низ | Z6: Верх | AA6: сеч.6-6 | AB6: нет чертежей | AC6: 240 шт | AD6: (м.п.) | AF6: кг | AG6: (м.п.) | AI6: кг | AJ6: (м.п.) | AL6: кг | AM6: (м.п.) | AO6: кг | AP6: (м.п.) | AR6: кг
A7: Арматура, (м.п.)
A8: Диаметр 32 А500С, L=м.п. | B8: =SUMIFS(Ведомость!$N$5:$N$397,Ведомость!$H$5:$H$397,32,Ведомость!$I$5:$I$397,"А500С",Ведомость!$V$5:$V$397,"Дм-1") -> 16 | C8: =SUMIFS(Ведомость!$N$5:$N$397,Ведомость!$H$5:$H$397,32,Ведомость!$I$5:$I$397,"А500С",Ведомость!$V$5:$V$397,"Дм-2") -> 16 | D8: =SUMIFS(Ведомость!$N$5:$N$397,Ведомость!$H$5:$H$397,32,Ведомость!$I$5:$I$397,"А500С",Ведомость!$V$5:$V$397,"Дм-3") -> 16 | E8: =SUMIFS(Ведомость!$N$5:$N$397,Ведомость!$H$5:$H$397,32,Ведомость!$I$5:$I$397,"А500С",Ведомость!$V$5:$V$397,"Дм-4") -> 16 | F8: =SUMIFS(Ведомость!$N$5:$N$397,Ведомость!$H$5:$H$397,32,Ведомость!$I$5:$I$397,"А500С",Ведомость!$V$5:$V$397,"Дм-5") -> 16 | G8: =SUMIFS(Ведомость!$N$5:$N$397,Ведомость!$H$5:$H$397,32,Ведомость!$I$5:$I$397,"А500С",Ведомость!$V$5:$V$397,"К-А") -> 48 | H8: =SUMIFS(Ведомость!$N$5:$N$397,Ведомость!$H$5:$H$397,32,Ведомость!$I$5:$I$397,"А500С",Ведомость!$V$5:$V$397,"К-Б") -> 80 | I8: =SUMIFS(Ведомость!$N$5:$N$397,Ведомость!$H$5:$H$397,32,Ведомость!$I$5:$I$397,"А500С",Ведомость!$V$5:$V$397,"К-В") -> 80 | J8: =SUMIFS(Ведомость!$N$5:$N$397,Ведомость!$H$5:$H$397,32,Ведомость!$I$5:$I$397,"А500С",Ведомость!$V$5:$V$397,"К-Г") -> 32 | K8: =SUMIFS(Ведомость!$N$5:$N$397,Ведомость!$H$5:$H$397,32,Ведомость!$I$5:$I$397,"А500С",Ведомость!$V$5:$V$397,"Р-А") -> 6.6 | L8: =SUMIFS(Ведомость!$N$5:$N$397,Ведомость!$H$5:$H$397,32,Ведомость!$I$5:$I$397,"А500С",Ведомость!$V$5:$V$397,"Р-Б") -> 7.4 | M8: =SUMIFS(Ведомость!$N$5:$N$397,Ведомость!$H$5:$H$397,32,Ведомость!$I$5:$I$397,"А500С",Ведомость!$V$5:$V$397,"Р-В") -> 14.8 | N8: =SUMIFS(Ведомость!$N$5:$N$397,Ведомость!$H$5:$H$397,32,Ведомость!$I$5:$I$397,"А500С",Ведомость!$V$5:$V$397,"Р-Г") -> 8.6 | O8: =SUMIFS(Ведомость!$N$5:$N$397,Ведомость!$H$5:$H$397,32,Ведомость!$I$5:$I$397,"А500С",Ведомость!$V$5:$V$397,"Р-1, 5") -> 15.2 | P8: =SUMIFS(Ведомость!$N$5:$N$397,Ведомость!$H$5:$H$397,32,Ведомость!$I$5:$I$397,"А500С",Ведомость!$V$5:$V$397,"Р-2") -> 27.9 | Q8: =SUMIFS(Ведомость!$N$5:$N$397,Ведомость!$H$5:$H$397,32,Ведомость!$I$5:$I$397,"А500С",Ведомость!$V$5:$V$397,"Р-3") -> 4.1 | R8: =SUMIFS(Ведомость!$N$5:$N$397,Ведомость!$H$5:$H$397,32,Ведомость!$I$5:$I$397,"А500С",Ведомость!$V$5:$V$397,"Р-4") -> 17.3 | S8: =SUMIFS(Ведомость!$N$5:$N$397,Ведомость!$H$5:$H$397,32,Ведомость!$I$5:$I$397,"А500С",Ведомость!$V$5:$V$397,"Б-основная") -> 0 | T8: =SUMIFS(Ведомость!$N$5:$N$397,Ведомость!$H$5:$H$397,32,Ведомость!$I$5:$I$397,"А500С",Ведомость!$V$5:$V$397,"Б-хомуты") -> 0 | U8: =SUMIFS(Ведомость!$N$5:$N$397,Ведомость!$H$5:$H$397,32,Ведомость!$I$5:$I$397,"А500С",Ведомость!$V$5:$V$397,"Б-допник") -> 0 | V8: =SUMIFS(Ведомость!$N$5:$N$397,Ведомость!$H$5:$H$397,32,Ведомость!$I$5:$I$397,"А500С",Ведомость!$V$5:$V$397,"П-сетка") -> 0 | W8: =SUMIFS(Ведомость!$N$5:$N$397,Ведомость!$H$5:$H$397,32,Ведомость!$I$5:$I$397,"А500С",Ведомость!$V$5:$V$397,"П-фикс") -> 0 | X8: =SUMIFS(Ведомость!$N$5:$N$397,Ведомость!$H$5:$H$397,32,Ведомость!$I$5:$I$397,"А500С",Ведомость!$V$5:$V$397,"П-отв") -> 0 | Y8: =SUMIFS(Ведомость!$N$5:$N$397,Ведомость!$H$5:$H$397,32,Ведомость!$I$5:$I$397,"А500С",Ведомость!$V$5:$V$397,"П-доп-низ") -> 0 | Z8: =SUMIFS(Ведомость!$N$5:$N$397,Ведомость!$H$5:$H$397,32,Ведомость!$I$5:$I$397,"А500С",Ведомость!$V$5:$V$397,"П-доп-верх") -> 0 | AA8: =SUMIFS(Ведомость!$N$5:$N$397,Ведомость!$H$5:$H$397,32,Ведомость!$I$5:$I$397,"А500С",Ведомость!$V$5:$V$397,"П-край") -> 0 | AB8: =SUMIFS(Ведомость!$N$5:$N$397,Ведомость!$H$5:$H$397,32,Ведомость!$I$5:$I$397,"А500С",Ведомость!$V$5:$V$397,"ЛВ-1") -> 0 | AC8: =SUMIFS(Ведомость!$N$5:$N$397,Ведомость!$H$5:$H$397,32,Ведомость!$I$5:$I$397,"А500С",Ведомость!$V$5:$V$397,"С-1") -> 0 | AD8: =SUM(B8:AC8) -> 421.9 | AE8: =IFERROR(INDEX(Исходные!$B$18:$B$29,MATCH(32,Исходные!$A$18:$A$29,0)),0) -> 6.313 | AF8: =AD8*AE8*$AH$2 -> 2663.4547 | AG8: =SUM(B8:J8) -> 320 | AH8: =AE8 -> 6.313 | AI8: =AG8*AH8*$AH$2 -> 2020.16 | AJ8: =SUM(K8:AA8) -> 101.9 | AK8: =AE8 -> 6.313 | AL8: =AJ8*AK8*$AH$2 -> 643.2947 | AM8: =SUM(AB8:AB8) -> 0 | AN8: =AE8 -> 6.313 | AO8: =AM8*AN8*$AH$2 -> 0 | AP8: =SUM(AC8:AC8) -> 0 | AQ8: =AE8 -> 6.313 | AR8: =AP8*AQ8*$AH$2 -> 0
A9: Диаметр 28 А500С, L=м.п. | B9: =SUMIFS(Ведомость!$N$5:$N$397,Ведомость!$H$5:$H$397,28,Ведомость!$I$5:$I$397,"А500С",Ведомость!$V$5:$V$397,"Дм-1") -> 128 | C9: =SUMIFS(Ведомость!$N$5:$N$397,Ведомость!$H$5:$H$397,28,Ведомость!$I$5:$I$397,"А500С",Ведомость!$V$5:$V$397,"Дм-2") -> 88 | D9: =SUMIFS(Ведомость!$N$5:$N$397,Ведомость!$H$5:$H$397,28,Ведомость!$I$5:$I$397,"А500С",Ведомость!$V$5:$V$397,"Дм-3") -> 88 | E9: =SUMIFS(Ведомость!$N$5:$N$397,Ведомость!$H$5:$H$397,28,Ведомость!$I$5:$I$397,"А500С",Ведомость!$V$5:$V$397,"Дм-4") -> 56 | F9: =SUMIFS(Ведомость!$N$5:$N$397,Ведомость!$H$5:$H$397,28,Ведомость!$I$5:$I$397,"А500С",Ведомость!$V$5:$V$397,"Дм-5") -> 56 | G9: =SUMIFS(Ведомость!$N$5:$N$397,Ведомость!$H$5:$H$397,28,Ведомость!$I$5:$I$397,"А500С",Ведомость!$V$5:$V$397,"К-А") -> 0 | H9: =SUMIFS(Ведомость!$N$5:$N$397,Ведомость!$H$5:$H$397,28,Ведомость!$I$5:$I$397,"А500С",Ведомость!$V$5:$V$397,"К-Б") -> 0 | I9: =SUMIFS(Ведомость!$N$5:$N$397,Ведомость!$H$5:$H$397,28,Ведомость!$I$5:$I$397,"А500С",Ведомость!$V$5:$V$397,"К-В") -> 0 | J9: =SUMIFS(Ведомость!$N$5:$N$397,Ведомость!$H$5:$H$397,28,Ведомость!$I$5:$I$397,"А500С",Ведомость!$V$5:$V$397,"К-Г") -> 0 | K9: =SUMIFS(Ведомость!$N$5:$N$397,Ведомость!$H$5:$H$397,28,Ведомость!$I$5:$I$397,"А500С",Ведомость!$V$5:$V$397,"Р-А") -> 121.8 | L9: =SUMIFS(Ведомость!$N$5:$N$397,Ведомость!$H$5:$H$397,28,Ведомость!$I$5:$I$397,"А500С",Ведомость!$V$5:$V$397,"Р-Б") -> 116.6 | M9: =SUMIFS(Ведомость!$N$5:$N$397,Ведомость!$H$5:$H$397,28,Ведомость!$I$5:$I$397,"А500С",Ведомость!$V$5:$V$397,"Р-В") -> 113.3 | N9: =SUMIFS(Ведомость!$N$5:$N$397,Ведомость!$H$5:$H$397,28,Ведомость!$I$5:$I$397,"А500С",Ведомость!$V$5:$V$397,"Р-Г") -> 144.1 | O9: =SUMIFS(Ведомость!$N$5:$N$397,Ведомость!$H$5:$H$397,28,Ведомость!$I$5:$I$397,"А500С",Ведомость!$V$5:$V$397,"Р-1, 5") -> 187.4 | P9: =SUMIFS(Ведомость!$N$5:$N$397,Ведомость!$H$5:$H$397,28,Ведомость!$I$5:$I$397,"А500С",Ведомость!$V$5:$V$397,"Р-2") -> 82 | Q9: =SUMIFS(Ведомость!$N$5:$N$397,Ведомость!$H$5:$H$397,28,Ведомость!$I$5:$I$397,"А500С",Ведомость!$V$5:$V$397,"Р-3") -> 99.7 | R9: =SUMIFS(Ведомость!$N$5:$N$397,Ведомость!$H$5:$H$397,28,Ведомость!$I$5:$I$397,"А500С",Ведомость!$V$5:$V$397,"Р-4") -> 89.2 | S9: =SUMIFS(Ведомость!$N$5:$N$397,Ведомость!$H$5:$H$397,28,Ведомость!$I$5:$I$397,"А500С",Ведомость!$V$5:$V$397,"Б-основная") -> 0 | T9: =SUMIFS(Ведомость!$N$5:$N$397,Ведомость!$H$5:$H$397,28,Ведомость!$I$5:$I$397,"А500С",Ведомость!$V$5:$V$397,"Б-хомуты") -> 0 | U9: =SUMIFS(Ведомость!$N$5:$N$397,Ведомость!$H$5:$H$397,28,Ведомость!$I$5:$I$397,"А500С",Ведомость!$V$5:$V$397,"Б-допник") -> 0 | V9: =SUMIFS(Ведомость!$N$5:$N$397,Ведомость!$H$5:$H$397,28,Ведомость!$I$5:$I$397,"А500С",Ведомость!$V$5:$V$397,"П-сетка") -> 0 | W9: =SUMIFS(Ведомость!$N$5:$N$397,Ведомость!$H$5:$H$397,28,Ведомость!$I$5:$I$397,"А500С",Ведомость!$V$5:$V$397,"П-фикс") -> 0 | X9: =SUMIFS(Ведомость!$N$5:$N$397,Ведомость!$H$5:$H$397,28,Ведомость!$I$5:$I$397,"А500С",Ведомость!$V$5:$V$397,"П-отв") -> 0 | Y9: =SUMIFS(Ведомость!$N$5:$N$397,Ведомость!$H$5:$H$397,28,Ведомость!$I$5:$I$397,"А500С",Ведомость!$V$5:$V$397,"П-доп-низ") -> 0 | Z9: =SUMIFS(Ведомость!$N$5:$N$397,Ведомость!$H$5:$H$397,28,Ведомость!$I$5:$I$397,"А500С",Ведомость!$V$5:$V$397,"П-доп-верх") -> 0 | AA9: =SUMIFS(Ведомость!$N$5:$N$397,Ведомость!$H$5:$H$397,28,Ведомость!$I$5:$I$397,"А500С",Ведомость!$V$5:$V$397,"П-край") -> 0 | AB9: =SUMIFS(Ведомость!$N$5:$N$397,Ведомость!$H$5:$H$397,28,Ведомость!$I$5:$I$397,"А500С",Ведомость!$V$5:$V$397,"ЛВ-1") -> 0 | AC9: =SUMIFS(Ведомость!$N$5:$N$397,Ведомость!$H$5:$H$397,28,Ведомость!$I$5:$I$397,"А500С",Ведомость!$V$5:$V$397,"С-1") -> 0 | AD9: =SUM(B9:AC9) -> 1370.1 | AE9: =IFERROR(INDEX(Исходные!$B$18:$B$29,MATCH(28,Исходные!$A$18:$A$29,0)),0) -> 4.834 | AF9: =AD9*AE9*$AH$2 -> 6623.0634 | AG9: =SUM(B9:J9) -> 416 | AH9: =AE9 -> 4.834 | AI9: =AG9*AH9*$AH$2 -> 2010.944 | AJ9: =SUM(K9:AA9) -> 954.1 | AK9: =AE9 -> 4.834 | AL9: =AJ9*AK9*$AH$2 -> 4612.1194 | AM9: =SUM(AB9:AB9) -> 0 | AN9: =AE9 -> 4.834 | AO9: =AM9*AN9*$AH$2 -> 0 | AP9: =SUM(AC9:AC9) -> 0 | AQ9: =AE9 -> 4.834 | AR9: =AP9*AQ9*$AH$2 -> 0
A10: Диаметр 25 А500С, L=м.п. | B10: =SUMIFS(Ведомость!$N$5:$N$397,Ведомость!$H$5:$H$397,25,Ведомость!$I$5:$I$397,"А500С",Ведомость!$V$5:$V$397,"Дм-1") -> 32 | C10: =SUMIFS(Ведомость!$N$5:$N$397,Ведомость!$H$5:$H$397,25,Ведомость!$I$5:$I$397,"А500С",Ведомость!$V$5:$V$397,"Дм-2") -> 32 | D10: =SUMIFS(Ведомость!$N$5:$N$397,Ведомость!$H$5:$H$397,25,Ведомость!$I$5:$I$397,"А500С",Ведомость!$V$5:$V$397,"Дм-3") -> 40 | E10: =SUMIFS(Ведомость!$N$5:$N$397,Ведомость!$H$5:$H$397,25,Ведомость!$I$5:$I$397,"А500С",Ведомость!$V$5:$V$397,"Дм-4") -> 0 | F10: =SUMIFS(Ведомость!$N$5:$N$397,Ведомость!$H$5:$H$397,25,Ведомость!$I$5:$I$397,"А500С",Ведомость!$V$5:$V$397,"Дм-5") -> 40 | G10: =SUMIFS(Ведомость!$N$5:$N$397,Ведомость!$H$5:$H$397,25,Ведомость!$I$5:$I$397,"А500С",Ведомость!$V$5:$V$397,"К-А") -> 0 | H10: =SUMIFS(Ведомость!$N$5:$N$397,Ведомость!$H$5:$H$397,25,Ведомость!$I$5:$I$397,"А500С",Ведомость!$V$5:$V$397,"К-Б") -> 0 | I10: =SUMIFS(Ведомость!$N$5:$N$397,Ведомость!$H$5:$H$397,25,Ведомость!$I$5:$I$397,"А500С",Ведомость!$V$5:$V$397,"К-В") -> 0 | J10: =SUMIFS(Ведомость!$N$5:$N$397,Ведомость!$H$5:$H$397,25,Ведомость!$I$5:$I$397,"А500С",Ведомость!$V$5:$V$397,"К-Г") -> 0 | K10: =SUMIFS(Ведомость!$N$5:$N$397,Ведомость!$H$5:$H$397,25,Ведомость!$I$5:$I$397,"А500С",Ведомость!$V$5:$V$397,"Р-А") -> 40.4 | L10: =SUMIFS(Ведомость!$N$5:$N$397,Ведомость!$H$5:$H$397,25,Ведомость!$I$5:$I$397,"А500С",Ведомость!$V$5:$V$397,"Р-Б") -> 8.2 | M10: =SUMIFS(Ведомость!$N$5:$N$397,Ведомость!$H$5:$H$397,25,Ведомость!$I$5:$I$397,"А500С",Ведомость!$V$5:$V$397,"Р-В") -> 4.1 | N10: =SUMIFS(Ведомость!$N$5:$N$397,Ведомость!$H$5:$H$397,25,Ведомость!$I$5:$I$397,"А500С",Ведомость!$V$5:$V$397,"Р-Г") -> 4.1 | O10: =SUMIFS(Ведомость!$N$5:$N$397,Ведомость!$H$5:$H$397,25,Ведомость!$I$5:$I$397,"А500С",Ведомость!$V$5:$V$397,"Р-1, 5") -> 8.2 | P10: =SUMIFS(Ведомость!$N$5:$N$397,Ведомость!$H$5:$H$397,25,Ведомость!$I$5:$I$397,"А500С",Ведомость!$V$5:$V$397,"Р-2") -> 21 | Q10: =SUMIFS(Ведомость!$N$5:$N$397,Ведомость!$H$5:$H$397,25,Ведомость!$I$5:$I$397,"А500С",Ведомость!$V$5:$V$397,"Р-3") -> 22.8 | R10: =SUMIFS(Ведомость!$N$5:$N$397,Ведомость!$H$5:$H$397,25,Ведомость!$I$5:$I$397,"А500С",Ведомость!$V$5:$V$397,"Р-4") -> 12.4 | S10: =SUMIFS(Ведомость!$N$5:$N$397,Ведомость!$H$5:$H$397,25,Ведомость!$I$5:$I$397,"А500С",Ведомость!$V$5:$V$397,"Б-основная") -> 635.4 | T10: =SUMIFS(Ведомость!$N$5:$N$397,Ведомость!$H$5:$H$397,25,Ведомость!$I$5:$I$397,"А500С",Ведомость!$V$5:$V$397,"Б-хомуты") -> 0 | U10: =SUMIFS(Ведомость!$N$5:$N$397,Ведомость!$H$5:$H$397,25,Ведомость!$I$5:$I$397,"А500С",Ведомость!$V$5:$V$397,"Б-допник") -> 0 | V10: =SUMIFS(Ведомость!$N$5:$N$397,Ведомость!$H$5:$H$397,25,Ведомость!$I$5:$I$397,"А500С",Ведомость!$V$5:$V$397,"П-сетка") -> 0 | W10: =SUMIFS(Ведомость!$N$5:$N$397,Ведомость!$H$5:$H$397,25,Ведомость!$I$5:$I$397,"А500С",Ведомость!$V$5:$V$397,"П-фикс") -> 0 | X10: =SUMIFS(Ведомость!$N$5:$N$397,Ведомость!$H$5:$H$397,25,Ведомость!$I$5:$I$397,"А500С",Ведомость!$V$5:$V$397,"П-отв") -> 0 | Y10: =SUMIFS(Ведомость!$N$5:$N$397,Ведомость!$H$5:$H$397,25,Ведомость!$I$5:$I$397,"А500С",Ведомость!$V$5:$V$397,"П-доп-низ") -> 0 | Z10: =SUMIFS(Ведомость!$N$5:$N$397,Ведомость!$H$5:$H$397,25,Ведомость!$I$5:$I$397,"А500С",Ведомость!$V$5:$V$397,"П-доп-верх") -> 0 | AA10: =SUMIFS(Ведомость!$N$5:$N$397,Ведомость!$H$5:$H$397,25,Ведомость!$I$5:$I$397,"А500С",Ведомость!$V$5:$V$397,"П-край") -> 0 | AB10: =SUMIFS(Ведомость!$N$5:$N$397,Ведомость!$H$5:$H$397,25,Ведомость!$I$5:$I$397,"А500С",Ведомость!$V$5:$V$397,"ЛВ-1") -> 0 | AC10: =SUMIFS(Ведомость!$N$5:$N$397,Ведомость!$H$5:$H$397,25,Ведомость!$I$5:$I$397,"А500С",Ведомость!$V$5:$V$397,"С-1") -> 0 | AD10: =SUM(B10:AC10) -> 900.6 | AE10: =IFERROR(INDEX(Исходные!$B$18:$B$29,MATCH(25,Исходные!$A$18:$A$29,0)),0) -> 3.853 | AF10: =AD10*AE10*$AH$2 -> 3470.0118 | AG10: =SUM(B10:J10) -> 144 | AH10: =AE10 -> 3.853 | AI10: =AG10*AH10*$AH$2 -> 554.832 | AJ10: =SUM(K10:AA10) -> 756.6 | AK10: =AE10 -> 3.853 | AL10: =AJ10*AK10*$AH$2 -> 2915.1798 | AM10: =SUM(AB10:AB10) -> 0 | AN10: =AE10 -> 3.853 | AO10: =AM10*AN10*$AH$2 -> 0 | AP10: =SUM(AC10:AC10) -> 0 | AQ10: =AE10 -> 3.853 | AR10: =AP10*AQ10*$AH$2 -> 0
A11: Диаметр 22 А500С, L=м.п. | B11: =SUMIFS(Ведомость!$N$5:$N$397,Ведомость!$H$5:$H$397,22,Ведомость!$I$5:$I$397,"А500С",Ведомость!$V$5:$V$397,"Дм-1") -> 0 | C11: =SUMIFS(Ведомость!$N$5:$N$397,Ведомость!$H$5:$H$397,22,Ведомость!$I$5:$I$397,"А500С",Ведомость!$V$5:$V$397,"Дм-2") -> 64 | D11: =SUMIFS(Ведомость!$N$5:$N$397,Ведомость!$H$5:$H$397,22,Ведомость!$I$5:$I$397,"А500С",Ведомость!$V$5:$V$397,"Дм-3") -> 69 | E11: =SUMIFS(Ведомость!$N$5:$N$397,Ведомость!$H$5:$H$397,22,Ведомость!$I$5:$I$397,"А500С",Ведомость!$V$5:$V$397,"Дм-4") -> 0 | F11: =SUMIFS(Ведомость!$N$5:$N$397,Ведомость!$H$5:$H$397,22,Ведомость!$I$5:$I$397,"А500С",Ведомость!$V$5:$V$397,"Дм-5") -> 24 | G11: =SUMIFS(Ведомость!$N$5:$N$397,Ведомость!$H$5:$H$397,22,Ведомость!$I$5:$I$397,"А500С",Ведомость!$V$5:$V$397,"К-А") -> 0 | H11: =SUMIFS(Ведомость!$N$5:$N$397,Ведомость!$H$5:$H$397,22,Ведомость!$I$5:$I$397,"А500С",Ведомость!$V$5:$V$397,"К-Б") -> 0 | I11: =SUMIFS(Ведомость!$N$5:$N$397,Ведомость!$H$5:$H$397,22,Ведомость!$I$5:$I$397,"А500С",Ведомость!$V$5:$V$397,"К-В") -> 0 | J11: =SUMIFS(Ведомость!$N$5:$N$397,Ведомость!$H$5:$H$397,22,Ведомость!$I$5:$I$397,"А500С",Ведомость!$V$5:$V$397,"К-Г") -> 0 | K11: =SUMIFS(Ведомость!$N$5:$N$397,Ведомость!$H$5:$H$397,22,Ведомость!$I$5:$I$397,"А500С",Ведомость!$V$5:$V$397,"Р-А") -> 9 | L11: =SUMIFS(Ведомость!$N$5:$N$397,Ведомость!$H$5:$H$397,22,Ведомость!$I$5:$I$397,"А500С",Ведомость!$V$5:$V$397,"Р-Б") -> 6.4 | M11: =SUMIFS(Ведомость!$N$5:$N$397,Ведомость!$H$5:$H$397,22,Ведомость!$I$5:$I$397,"А500С",Ведомость!$V$5:$V$397,"Р-В") -> 6.4 | N11: =SUMIFS(Ведомость!$N$5:$N$397,Ведомость!$H$5:$H$397,22,Ведомость!$I$5:$I$397,"А500С",Ведомость!$V$5:$V$397,"Р-Г") -> 35.5 | O11: =SUMIFS(Ведомость!$N$5:$N$397,Ведомость!$H$5:$H$397,22,Ведомость!$I$5:$I$397,"А500С",Ведомость!$V$5:$V$397,"Р-1, 5") -> 0 | P11: =SUMIFS(Ведомость!$N$5:$N$397,Ведомость!$H$5:$H$397,22,Ведомость!$I$5:$I$397,"А500С",Ведомость!$V$5:$V$397,"Р-2") -> 0 | Q11: =SUMIFS(Ведомость!$N$5:$N$397,Ведомость!$H$5:$H$397,22,Ведомость!$I$5:$I$397,"А500С",Ведомость!$V$5:$V$397,"Р-3") -> 0 | R11: =SUMIFS(Ведомость!$N$5:$N$397,Ведомость!$H$5:$H$397,22,Ведомость!$I$5:$I$397,"А500С",Ведомость!$V$5:$V$397,"Р-4") -> 0 | S11: =SUMIFS(Ведомость!$N$5:$N$397,Ведомость!$H$5:$H$397,22,Ведомость!$I$5:$I$397,"А500С",Ведомость!$V$5:$V$397,"Б-основная") -> 158.8 | T11: =SUMIFS(Ведомость!$N$5:$N$397,Ведомость!$H$5:$H$397,22,Ведомость!$I$5:$I$397,"А500С",Ведомость!$V$5:$V$397,"Б-хомуты") -> 0 | U11: =SUMIFS(Ведомость!$N$5:$N$397,Ведомость!$H$5:$H$397,22,Ведомость!$I$5:$I$397,"А500С",Ведомость!$V$5:$V$397,"Б-допник") -> 0 | V11: =SUMIFS(Ведомость!$N$5:$N$397,Ведомость!$H$5:$H$397,22,Ведомость!$I$5:$I$397,"А500С",Ведомость!$V$5:$V$397,"П-сетка") -> 0 | W11: =SUMIFS(Ведомость!$N$5:$N$397,Ведомость!$H$5:$H$397,22,Ведомость!$I$5:$I$397,"А500С",Ведомость!$V$5:$V$397,"П-фикс") -> 0 | X11: =SUMIFS(Ведомость!$N$5:$N$397,Ведомость!$H$5:$H$397,22,Ведомость!$I$5:$I$397,"А500С",Ведомость!$V$5:$V$397,"П-отв") -> 0 | Y11: =SUMIFS(Ведомость!$N$5:$N$397,Ведомость!$H$5:$H$397,22,Ведомость!$I$5:$I$397,"А500С",Ведомость!$V$5:$V$397,"П-доп-низ") -> 0 | Z11: =SUMIFS(Ведомость!$N$5:$N$397,Ведомость!$H$5:$H$397,22,Ведомость!$I$5:$I$397,"А500С",Ведомость!$V$5:$V$397,"П-доп-верх") -> 0 | AA11: =SUMIFS(Ведомость!$N$5:$N$397,Ведомость!$H$5:$H$397,22,Ведомость!$I$5:$I$397,"А500С",Ведомость!$V$5:$V$397,"П-край") -> 0 | AB11: =SUMIFS(Ведомость!$N$5:$N$397,Ведомость!$H$5:$H$397,22,Ведомость!$I$5:$I$397,"А500С",Ведомость!$V$5:$V$397,"ЛВ-1") -> 0 | AC11: =SUMIFS(Ведомость!$N$5:$N$397,Ведомость!$H$5:$H$397,22,Ведомость!$I$5:$I$397,"А500С",Ведомость!$V$5:$V$397,"С-1") -> 0 | AD11: =SUM(B11:AC11) -> 373.1 | AE11: =IFERROR(INDEX(Исходные!$B$18:$B$29,MATCH(22,Исходные!$A$18:$A$29,0)),0) -> 2.984 | AF11: =AD11*AE11*$AH$2 -> 1113.3304 | AG11: =SUM(B11:J11) -> 157 | AH11: =AE11 -> 2.984 | AI11: =AG11*AH11*$AH$2 -> 468.488 | AJ11: =SUM(K11:AA11) -> 216.1 | AK11: =AE11 -> 2.984 | AL11: =AJ11*AK11*$AH$2 -> 644.8424 | AM11: =SUM(AB11:AB11) -> 0 | AN11: =AE11 -> 2.984 | AO11: =AM11*AN11*$AH$2 -> 0 | AP11: =SUM(AC11:AC11) -> 0 | AQ11: =AE11 -> 2.984 | AR11: =AP11*AQ11*$AH$2 -> 0
A12: Диаметр 20 А500С, L=м.п. | B12: =SUMIFS(Ведомость!$N$5:$N$397,Ведомость!$H$5:$H$397,20,Ведомость!$I$5:$I$397,"А500С",Ведомость!$V$5:$V$397,"Дм-1") -> 90.7 | C12: =SUMIFS(Ведомость!$N$5:$N$397,Ведомость!$H$5:$H$397,20,Ведомость!$I$5:$I$397,"А500С",Ведомость!$V$5:$V$397,"Дм-2") -> 28 | D12: =SUMIFS(Ведомость!$N$5:$N$397,Ведомость!$H$5:$H$397,20,Ведомость!$I$5:$I$397,"А500С",Ведомость!$V$5:$V$397,"Дм-3") -> 32 | E12: =SUMIFS(Ведомость!$N$5:$N$397,Ведомость!$H$5:$H$397,20,Ведомость!$I$5:$I$397,"А500С",Ведомость!$V$5:$V$397,"Дм-4") -> 40 | F12: =SUMIFS(Ведомость!$N$5:$N$397,Ведомость!$H$5:$H$397,20,Ведомость!$I$5:$I$397,"А500С",Ведомость!$V$5:$V$397,"Дм-5") -> 32 | G12: =SUMIFS(Ведомость!$N$5:$N$397,Ведомость!$H$5:$H$397,20,Ведомость!$I$5:$I$397,"А500С",Ведомость!$V$5:$V$397,"К-А") -> 96 | H12: =SUMIFS(Ведомость!$N$5:$N$397,Ведомость!$H$5:$H$397,20,Ведомость!$I$5:$I$397,"А500С",Ведомость!$V$5:$V$397,"К-Б") -> 160 | I12: =SUMIFS(Ведомость!$N$5:$N$397,Ведомость!$H$5:$H$397,20,Ведомость!$I$5:$I$397,"А500С",Ведомость!$V$5:$V$397,"К-В") -> 160 | J12: =SUMIFS(Ведомость!$N$5:$N$397,Ведомость!$H$5:$H$397,20,Ведомость!$I$5:$I$397,"А500С",Ведомость!$V$5:$V$397,"К-Г") -> 64 | K12: =SUMIFS(Ведомость!$N$5:$N$397,Ведомость!$H$5:$H$397,20,Ведомость!$I$5:$I$397,"А500С",Ведомость!$V$5:$V$397,"Р-А") -> 0 | L12: =SUMIFS(Ведомость!$N$5:$N$397,Ведомость!$H$5:$H$397,20,Ведомость!$I$5:$I$397,"А500С",Ведомость!$V$5:$V$397,"Р-Б") -> 0 | M12: =SUMIFS(Ведомость!$N$5:$N$397,Ведомость!$H$5:$H$397,20,Ведомость!$I$5:$I$397,"А500С",Ведомость!$V$5:$V$397,"Р-В") -> 0 | N12: =SUMIFS(Ведомость!$N$5:$N$397,Ведомость!$H$5:$H$397,20,Ведомость!$I$5:$I$397,"А500С",Ведомость!$V$5:$V$397,"Р-Г") -> 0 | O12: =SUMIFS(Ведомость!$N$5:$N$397,Ведомость!$H$5:$H$397,20,Ведомость!$I$5:$I$397,"А500С",Ведомость!$V$5:$V$397,"Р-1, 5") -> 0 | P12: =SUMIFS(Ведомость!$N$5:$N$397,Ведомость!$H$5:$H$397,20,Ведомость!$I$5:$I$397,"А500С",Ведомость!$V$5:$V$397,"Р-2") -> 8.1 | Q12: =SUMIFS(Ведомость!$N$5:$N$397,Ведомость!$H$5:$H$397,20,Ведомость!$I$5:$I$397,"А500С",Ведомость!$V$5:$V$397,"Р-3") -> 0 | R12: =SUMIFS(Ведомость!$N$5:$N$397,Ведомость!$H$5:$H$397,20,Ведомость!$I$5:$I$397,"А500С",Ведомость!$V$5:$V$397,"Р-4") -> 6 | S12: =SUMIFS(Ведомость!$N$5:$N$397,Ведомость!$H$5:$H$397,20,Ведомость!$I$5:$I$397,"А500С",Ведомость!$V$5:$V$397,"Б-основная") -> 57.04 | T12: =SUMIFS(Ведомость!$N$5:$N$397,Ведомость!$H$5:$H$397,20,Ведомость!$I$5:$I$397,"А500С",Ведомость!$V$5:$V$397,"Б-хомуты") -> 0 | U12: =SUMIFS(Ведомость!$N$5:$N$397,Ведомость!$H$5:$H$397,20,Ведомость!$I$5:$I$397,"А500С",Ведомость!$V$5:$V$397,"Б-допник") -> 0 | V12: =SUMIFS(Ведомость!$N$5:$N$397,Ведомость!$H$5:$H$397,20,Ведомость!$I$5:$I$397,"А500С",Ведомость!$V$5:$V$397,"П-сетка") -> 0 | W12: =SUMIFS(Ведомость!$N$5:$N$397,Ведомость!$H$5:$H$397,20,Ведомость!$I$5:$I$397,"А500С",Ведомость!$V$5:$V$397,"П-фикс") -> 0 | X12: =SUMIFS(Ведомость!$N$5:$N$397,Ведомость!$H$5:$H$397,20,Ведомость!$I$5:$I$397,"А500С",Ведомость!$V$5:$V$397,"П-отв") -> 0 | Y12: =SUMIFS(Ведомость!$N$5:$N$397,Ведомость!$H$5:$H$397,20,Ведомость!$I$5:$I$397,"А500С",Ведомость!$V$5:$V$397,"П-доп-низ") -> 0 | Z12: =SUMIFS(Ведомость!$N$5:$N$397,Ведомость!$H$5:$H$397,20,Ведомость!$I$5:$I$397,"А500С",Ведомость!$V$5:$V$397,"П-доп-верх") -> 12 | AA12: =SUMIFS(Ведомость!$N$5:$N$397,Ведомость!$H$5:$H$397,20,Ведомость!$I$5:$I$397,"А500С",Ведомость!$V$5:$V$397,"П-край") -> 0 | AB12: =SUMIFS(Ведомость!$N$5:$N$397,Ведомость!$H$5:$H$397,20,Ведомость!$I$5:$I$397,"А500С",Ведомость!$V$5:$V$397,"ЛВ-1") -> 0 | AC12: =SUMIFS(Ведомость!$N$5:$N$397,Ведомость!$H$5:$H$397,20,Ведомость!$I$5:$I$397,"А500С",Ведомость!$V$5:$V$397,"С-1") -> 0 | AD12: =SUM(B12:AC12) -> 785.84 | AE12: =IFERROR(INDEX(Исходные!$B$18:$B$29,MATCH(20,Исходные!$A$18:$A$29,0)),0) -> 2.466 | AF12: =AD12*AE12*$AH$2 -> 1937.8814 | AG12: =SUM(B12:J12) -> 702.7 | AH12: =AE12 -> 2.466 | AI12: =AG12*AH12*$AH$2 -> 1732.8582 | AJ12: =SUM(K12:AA12) -> 83.14 | AK12: =AE12 -> 2.466 | AL12: =AJ12*AK12*$AH$2 -> 205.02324 | AM12: =SUM(AB12:AB12) -> 0 | AN12: =AE12 -> 2.466 | AO12: =AM12*AN12*$AH$2 -> 0 | AP12: =SUM(AC12:AC12) -> 0 | AQ12: =AE12 -> 2.466 | AR12: =AP12*AQ12*$AH$2 -> 0
A13: Диаметр 18 А500С, L=м.п. | B13: =SUMIFS(Ведомость!$N$5:$N$397,Ведомость!$H$5:$H$397,18,Ведомость!$I$5:$I$397,"А500С",Ведомость!$V$5:$V$397,"Дм-1") -> 107.496 | C13: =SUMIFS(Ведомость!$N$5:$N$397,Ведомость!$H$5:$H$397,18,Ведомость!$I$5:$I$397,"А500С",Ведомость!$V$5:$V$397,"Дм-2") -> 0 | D13: =SUMIFS(Ведомость!$N$5:$N$397,Ведомость!$H$5:$H$397,18,Ведомость!$I$5:$I$397,"А500С",Ведомость!$V$5:$V$397,"Дм-3") -> 18.644 | E13: =SUMIFS(Ведомость!$N$5:$N$397,Ведомость!$H$5:$H$397,18,Ведомость!$I$5:$I$397,"А500С",Ведомость!$V$5:$V$397,"Дм-4") -> 14.5 | F13: =SUMIFS(Ведомость!$N$5:$N$397,Ведомость!$H$5:$H$397,18,Ведомость!$I$5:$I$397,"А500С",Ведомость!$V$5:$V$397,"Дм-5") -> 0 | G13: =SUMIFS(Ведомость!$N$5:$N$397,Ведомость!$H$5:$H$397,18,Ведомость!$I$5:$I$397,"А500С",Ведомость!$V$5:$V$397,"К-А") -> 0 | H13: =SUMIFS(Ведомость!$N$5:$N$397,Ведомость!$H$5:$H$397,18,Ведомость!$I$5:$I$397,"А500С",Ведомость!$V$5:$V$397,"К-Б") -> 0 | I13: =SUMIFS(Ведомость!$N$5:$N$397,Ведомость!$H$5:$H$397,18,Ведомость!$I$5:$I$397,"А500С",Ведомость!$V$5:$V$397,"К-В") -> 0 | J13: =SUMIFS(Ведомость!$N$5:$N$397,Ведомость!$H$5:$H$397,18,Ведомость!$I$5:$I$397,"А500С",Ведомость!$V$5:$V$397,"К-Г") -> 0 | K13: =SUMIFS(Ведомость!$N$5:$N$397,Ведомость!$H$5:$H$397,18,Ведомость!$I$5:$I$397,"А500С",Ведомость!$V$5:$V$397,"Р-А") -> 51.576 | L13: =SUMIFS(Ведомость!$N$5:$N$397,Ведомость!$H$5:$H$397,18,Ведомость!$I$5:$I$397,"А500С",Ведомость!$V$5:$V$397,"Р-Б") -> 51.576 | M13: =SUMIFS(Ведомость!$N$5:$N$397,Ведомость!$H$5:$H$397,18,Ведомость!$I$5:$I$397,"А500С",Ведомость!$V$5:$V$397,"Р-В") -> 51.576 | N13: =SUMIFS(Ведомость!$N$5:$N$397,Ведомость!$H$5:$H$397,18,Ведомость!$I$5:$I$397,"А500С",Ведомость!$V$5:$V$397,"Р-Г") -> 51.576 | O13: =SUMIFS(Ведомость!$N$5:$N$397,Ведомость!$H$5:$H$397,18,Ведомость!$I$5:$I$397,"А500С",Ведомость!$V$5:$V$397,"Р-1, 5") -> 82.576 | P13: =SUMIFS(Ведомость!$N$5:$N$397,Ведомость!$H$5:$H$397,18,Ведомость!$I$5:$I$397,"А500С",Ведомость!$V$5:$V$397,"Р-2") -> 41.288 | Q13: =SUMIFS(Ведомость!$N$5:$N$397,Ведомость!$H$5:$H$397,18,Ведомость!$I$5:$I$397,"А500С",Ведомость!$V$5:$V$397,"Р-3") -> 41.288 | R13: =SUMIFS(Ведомость!$N$5:$N$397,Ведомость!$H$5:$H$397,18,Ведомость!$I$5:$I$397,"А500С",Ведомость!$V$5:$V$397,"Р-4") -> 41.288 | S13: =SUMIFS(Ведомость!$N$5:$N$397,Ведомость!$H$5:$H$397,18,Ведомость!$I$5:$I$397,"А500С",Ведомость!$V$5:$V$397,"Б-основная") -> 0 | T13: =SUMIFS(Ведомость!$N$5:$N$397,Ведомость!$H$5:$H$397,18,Ведомость!$I$5:$I$397,"А500С",Ведомость!$V$5:$V$397,"Б-хомуты") -> 0 | U13: =SUMIFS(Ведомость!$N$5:$N$397,Ведомость!$H$5:$H$397,18,Ведомость!$I$5:$I$397,"А500С",Ведомость!$V$5:$V$397,"Б-допник") -> 50.4 | V13: =SUMIFS(Ведомость!$N$5:$N$397,Ведомость!$H$5:$H$397,18,Ведомость!$I$5:$I$397,"А500С",Ведомость!$V$5:$V$397,"П-сетка") -> 0 | W13: =SUMIFS(Ведомость!$N$5:$N$397,Ведомость!$H$5:$H$397,18,Ведомость!$I$5:$I$397,"А500С",Ведомость!$V$5:$V$397,"П-фикс") -> 0 | X13: =SUMIFS(Ведомость!$N$5:$N$397,Ведомость!$H$5:$H$397,18,Ведомость!$I$5:$I$397,"А500С",Ведомость!$V$5:$V$397,"П-отв") -> 0 | Y13: =SUMIFS(Ведомость!$N$5:$N$397,Ведомость!$H$5:$H$397,18,Ведомость!$I$5:$I$397,"А500С",Ведомость!$V$5:$V$397,"П-доп-низ") -> 0 | Z13: =SUMIFS(Ведомость!$N$5:$N$397,Ведомость!$H$5:$H$397,18,Ведомость!$I$5:$I$397,"А500С",Ведомость!$V$5:$V$397,"П-доп-верх") -> 0 | AA13: =SUMIFS(Ведомость!$N$5:$N$397,Ведомость!$H$5:$H$397,18,Ведомость!$I$5:$I$397,"А500С",Ведомость!$V$5:$V$397,"П-край") -> 0 | AB13: =SUMIFS(Ведомость!$N$5:$N$397,Ведомость!$H$5:$H$397,18,Ведомость!$I$5:$I$397,"А500С",Ведомость!$V$5:$V$397,"ЛВ-1") -> 0 | AC13: =SUMIFS(Ведомость!$N$5:$N$397,Ведомость!$H$5:$H$397,18,Ведомость!$I$5:$I$397,"А500С",Ведомость!$V$5:$V$397,"С-1") -> 0 | AD13: =SUM(B13:AC13) -> 603.784 | AE13: =IFERROR(INDEX(Исходные!$B$18:$B$29,MATCH(18,Исходные!$A$18:$A$29,0)),0) -> 1.998 | AF13: =AD13*AE13*$AH$2 -> 1206.3604 | AG13: =SUM(B13:J13) -> 140.64 | AH13: =AE13 -> 1.998 | AI13: =AG13*AH13*$AH$2 -> 280.99872 | AJ13: =SUM(K13:AA13) -> 463.144 | AK13: =AE13 -> 1.998 | AL13: =AJ13*AK13*$AH$2 -> 925.36171 | AM13: =SUM(AB13:AB13) -> 0 | AN13: =AE13 -> 1.998 | AO13: =AM13*AN13*$AH$2 -> 0 | AP13: =SUM(AC13:AC13) -> 0 | AQ13: =AE13 -> 1.998 | AR13: =AP13*AQ13*$AH$2 -> 0
A14: Диаметр 16 А500С, L=м.п. | B14: =SUMIFS(Ведомость!$N$5:$N$397,Ведомость!$H$5:$H$397,16,Ведомость!$I$5:$I$397,"А500С",Ведомость!$V$5:$V$397,"Дм-1") -> 81 | C14: =SUMIFS(Ведомость!$N$5:$N$397,Ведомость!$H$5:$H$397,16,Ведомость!$I$5:$I$397,"А500С",Ведомость!$V$5:$V$397,"Дм-2") -> 126 | D14: =SUMIFS(Ведомость!$N$5:$N$397,Ведомость!$H$5:$H$397,16,Ведомость!$I$5:$I$397,"А500С",Ведомость!$V$5:$V$397,"Дм-3") -> 83 | E14: =SUMIFS(Ведомость!$N$5:$N$397,Ведомость!$H$5:$H$397,16,Ведомость!$I$5:$I$397,"А500С",Ведомость!$V$5:$V$397,"Дм-4") -> 52.2 | F14: =SUMIFS(Ведомость!$N$5:$N$397,Ведомость!$H$5:$H$397,16,Ведомость!$I$5:$I$397,"А500С",Ведомость!$V$5:$V$397,"Дм-5") -> 97.2 | G14: =SUMIFS(Ведомость!$N$5:$N$397,Ведомость!$H$5:$H$397,16,Ведомость!$I$5:$I$397,"А500С",Ведомость!$V$5:$V$397,"К-А") -> 0 | H14: =SUMIFS(Ведомость!$N$5:$N$397,Ведомость!$H$5:$H$397,16,Ведомость!$I$5:$I$397,"А500С",Ведомость!$V$5:$V$397,"К-Б") -> 0 | I14: =SUMIFS(Ведомость!$N$5:$N$397,Ведомость!$H$5:$H$397,16,Ведомость!$I$5:$I$397,"А500С",Ведомость!$V$5:$V$397,"К-В") -> 0 | J14: =SUMIFS(Ведомость!$N$5:$N$397,Ведомость!$H$5:$H$397,16,Ведомость!$I$5:$I$397,"А500С",Ведомость!$V$5:$V$397,"К-Г") -> 0 | K14: =SUMIFS(Ведомость!$N$5:$N$397,Ведомость!$H$5:$H$397,16,Ведомость!$I$5:$I$397,"А500С",Ведомость!$V$5:$V$397,"Р-А") -> 77.012 | L14: =SUMIFS(Ведомость!$N$5:$N$397,Ведомость!$H$5:$H$397,16,Ведомость!$I$5:$I$397,"А500С",Ведомость!$V$5:$V$397,"Р-Б") -> 63.112 | M14: =SUMIFS(Ведомость!$N$5:$N$397,Ведомость!$H$5:$H$397,16,Ведомость!$I$5:$I$397,"А500С",Ведомость!$V$5:$V$397,"Р-В") -> 63.112 | N14: =SUMIFS(Ведомость!$N$5:$N$397,Ведомость!$H$5:$H$397,16,Ведомость!$I$5:$I$397,"А500С",Ведомость!$V$5:$V$397,"Р-Г") -> 55.212 | O14: =SUMIFS(Ведомость!$N$5:$N$397,Ведомость!$H$5:$H$397,16,Ведомость!$I$5:$I$397,"А500С",Ведомость!$V$5:$V$397,"Р-1, 5") -> 125.912 | P14: =SUMIFS(Ведомость!$N$5:$N$397,Ведомость!$H$5:$H$397,16,Ведомость!$I$5:$I$397,"А500С",Ведомость!$V$5:$V$397,"Р-2") -> 48.456 | Q14: =SUMIFS(Ведомость!$N$5:$N$397,Ведомость!$H$5:$H$397,16,Ведомость!$I$5:$I$397,"А500С",Ведомость!$V$5:$V$397,"Р-3") -> 56.956 | R14: =SUMIFS(Ведомость!$N$5:$N$397,Ведомость!$H$5:$H$397,16,Ведомость!$I$5:$I$397,"А500С",Ведомость!$V$5:$V$397,"Р-4") -> 45.856 | S14: =SUMIFS(Ведомость!$N$5:$N$397,Ведомость!$H$5:$H$397,16,Ведомость!$I$5:$I$397,"А500С",Ведомость!$V$5:$V$397,"Б-основная") -> 0 | T14: =SUMIFS(Ведомость!$N$5:$N$397,Ведомость!$H$5:$H$397,16,Ведомость!$I$5:$I$397,"А500С",Ведомость!$V$5:$V$397,"Б-хомуты") -> 0 | U14: =SUMIFS(Ведомость!$N$5:$N$397,Ведомость!$H$5:$H$397,16,Ведомость!$I$5:$I$397,"А500С",Ведомость!$V$5:$V$397,"Б-допник") -> 0 | V14: =SUMIFS(Ведомость!$N$5:$N$397,Ведомость!$H$5:$H$397,16,Ведомость!$I$5:$I$397,"А500С",Ведомость!$V$5:$V$397,"П-сетка") -> 0 | W14: =SUMIFS(Ведомость!$N$5:$N$397,Ведомость!$H$5:$H$397,16,Ведомость!$I$5:$I$397,"А500С",Ведомость!$V$5:$V$397,"П-фикс") -> 0 | X14: =SUMIFS(Ведомость!$N$5:$N$397,Ведомость!$H$5:$H$397,16,Ведомость!$I$5:$I$397,"А500С",Ведомость!$V$5:$V$397,"П-отв") -> 0 | Y14: =SUMIFS(Ведомость!$N$5:$N$397,Ведомость!$H$5:$H$397,16,Ведомость!$I$5:$I$397,"А500С",Ведомость!$V$5:$V$397,"П-доп-низ") -> 0 | Z14: =SUMIFS(Ведомость!$N$5:$N$397,Ведомость!$H$5:$H$397,16,Ведомость!$I$5:$I$397,"А500С",Ведомость!$V$5:$V$397,"П-доп-верх") -> 0 | AA14: =SUMIFS(Ведомость!$N$5:$N$397,Ведомость!$H$5:$H$397,16,Ведомость!$I$5:$I$397,"А500С",Ведомость!$V$5:$V$397,"П-край") -> 0 | AB14: =SUMIFS(Ведомость!$N$5:$N$397,Ведомость!$H$5:$H$397,16,Ведомость!$I$5:$I$397,"А500С",Ведомость!$V$5:$V$397,"ЛВ-1") -> 0 | AC14: =SUMIFS(Ведомость!$N$5:$N$397,Ведомость!$H$5:$H$397,16,Ведомость!$I$5:$I$397,"А500С",Ведомость!$V$5:$V$397,"С-1") -> 0 | AD14: =SUM(B14:AC14) -> 975.028 | AE14: =IFERROR(INDEX(Исходные!$B$18:$B$29,MATCH(16,Исходные!$A$18:$A$29,0)),0) -> 1.578 | AF14: =AD14*AE14*$AH$2 -> 1538.5942 | AG14: =SUM(B14:J14) -> 439.4 | AH14: =AE14 -> 1.578 | AI14: =AG14*AH14*$AH$2 -> 693.3732 | AJ14: =SUM(K14:AA14) -> 535.628 | AK14: =AE14 -> 1.578 | AL14: =AJ14*AK14*$AH$2 -> 845.22098 | AM14: =SUM(AB14:AB14) -> 0 | AN14: =AE14 -> 1.578 | AO14: =AM14*AN14*$AH$2 -> 0 | AP14: =SUM(AC14:AC14) -> 0 | AQ14: =AE14 -> 1.578 | AR14: =AP14*AQ14*$AH$2 -> 0
A15: Диаметр 14 А500С, L=м.п. | B15: =SUMIFS(Ведомость!$N$5:$N$397,Ведомость!$H$5:$H$397,14,Ведомость!$I$5:$I$397,"А500С",Ведомость!$V$5:$V$397,"Дм-1") -> 0 | C15: =SUMIFS(Ведомость!$N$5:$N$397,Ведомость!$H$5:$H$397,14,Ведомость!$I$5:$I$397,"А500С",Ведомость!$V$5:$V$397,"Дм-2") -> 0 | D15: =SUMIFS(Ведомость!$N$5:$N$397,Ведомость!$H$5:$H$397,14,Ведомость!$I$5:$I$397,"А500С",Ведомость!$V$5:$V$397,"Дм-3") -> 52.2 | E15: =SUMIFS(Ведомость!$N$5:$N$397,Ведомость!$H$5:$H$397,14,Ведомость!$I$5:$I$397,"А500С",Ведомость!$V$5:$V$397,"Дм-4") -> 0 | F15: =SUMIFS(Ведомость!$N$5:$N$397,Ведомость!$H$5:$H$397,14,Ведомость!$I$5:$I$397,"А500С",Ведомость!$V$5:$V$397,"Дм-5") -> 8.7 | G15: =SUMIFS(Ведомость!$N$5:$N$397,Ведомость!$H$5:$H$397,14,Ведомость!$I$5:$I$397,"А500С",Ведомость!$V$5:$V$397,"К-А") -> 0 | H15: =SUMIFS(Ведомость!$N$5:$N$397,Ведомость!$H$5:$H$397,14,Ведомость!$I$5:$I$397,"А500С",Ведомость!$V$5:$V$397,"К-Б") -> 0 | I15: =SUMIFS(Ведомость!$N$5:$N$397,Ведомость!$H$5:$H$397,14,Ведомость!$I$5:$I$397,"А500С",Ведомость!$V$5:$V$397,"К-В") -> 0 | J15: =SUMIFS(Ведомость!$N$5:$N$397,Ведомость!$H$5:$H$397,14,Ведомость!$I$5:$I$397,"А500С",Ведомость!$V$5:$V$397,"К-Г") -> 0 | K15: =SUMIFS(Ведомость!$N$5:$N$397,Ведомость!$H$5:$H$397,14,Ведомость!$I$5:$I$397,"А500С",Ведомость!$V$5:$V$397,"Р-А") -> 0 | L15: =SUMIFS(Ведомость!$N$5:$N$397,Ведомость!$H$5:$H$397,14,Ведомость!$I$5:$I$397,"А500С",Ведомость!$V$5:$V$397,"Р-Б") -> 14.8 | M15: =SUMIFS(Ведомость!$N$5:$N$397,Ведомость!$H$5:$H$397,14,Ведомость!$I$5:$I$397,"А500С",Ведомость!$V$5:$V$397,"Р-В") -> 32 | N15: =SUMIFS(Ведомость!$N$5:$N$397,Ведомость!$H$5:$H$397,14,Ведомость!$I$5:$I$397,"А500С",Ведомость!$V$5:$V$397,"Р-Г") -> 0 | O15: =SUMIFS(Ведомость!$N$5:$N$397,Ведомость!$H$5:$H$397,14,Ведомость!$I$5:$I$397,"А500С",Ведомость!$V$5:$V$397,"Р-1, 5") -> 0 | P15: =SUMIFS(Ведомость!$N$5:$N$397,Ведомость!$H$5:$H$397,14,Ведомость!$I$5:$I$397,"А500С",Ведомость!$V$5:$V$397,"Р-2") -> 36.7 | Q15: =SUMIFS(Ведомость!$N$5:$N$397,Ведомость!$H$5:$H$397,14,Ведомость!$I$5:$I$397,"А500С",Ведомость!$V$5:$V$397,"Р-3") -> 0 | R15: =SUMIFS(Ведомость!$N$5:$N$397,Ведомость!$H$5:$H$397,14,Ведомость!$I$5:$I$397,"А500С",Ведомость!$V$5:$V$397,"Р-4") -> 0 | S15: =SUMIFS(Ведомость!$N$5:$N$397,Ведомость!$H$5:$H$397,14,Ведомость!$I$5:$I$397,"А500С",Ведомость!$V$5:$V$397,"Б-основная") -> 0 | T15: =SUMIFS(Ведомость!$N$5:$N$397,Ведомость!$H$5:$H$397,14,Ведомость!$I$5:$I$397,"А500С",Ведомость!$V$5:$V$397,"Б-хомуты") -> 0 | U15: =SUMIFS(Ведомость!$N$5:$N$397,Ведомость!$H$5:$H$397,14,Ведомость!$I$5:$I$397,"А500С",Ведомость!$V$5:$V$397,"Б-допник") -> 0 | V15: =SUMIFS(Ведомость!$N$5:$N$397,Ведомость!$H$5:$H$397,14,Ведомость!$I$5:$I$397,"А500С",Ведомость!$V$5:$V$397,"П-сетка") -> 0 | W15: =SUMIFS(Ведомость!$N$5:$N$397,Ведомость!$H$5:$H$397,14,Ведомость!$I$5:$I$397,"А500С",Ведомость!$V$5:$V$397,"П-фикс") -> 0 | X15: =SUMIFS(Ведомость!$N$5:$N$397,Ведомость!$H$5:$H$397,14,Ведомость!$I$5:$I$397,"А500С",Ведомость!$V$5:$V$397,"П-отв") -> 0 | Y15: =SUMIFS(Ведомость!$N$5:$N$397,Ведомость!$H$5:$H$397,14,Ведомость!$I$5:$I$397,"А500С",Ведомость!$V$5:$V$397,"П-доп-низ") -> 0 | Z15: =SUMIFS(Ведомость!$N$5:$N$397,Ведомость!$H$5:$H$397,14,Ведомость!$I$5:$I$397,"А500С",Ведомость!$V$5:$V$397,"П-доп-верх") -> 0 | AA15: =SUMIFS(Ведомость!$N$5:$N$397,Ведомость!$H$5:$H$397,14,Ведомость!$I$5:$I$397,"А500С",Ведомость!$V$5:$V$397,"П-край") -> 96.06 | AB15: =SUMIFS(Ведомость!$N$5:$N$397,Ведомость!$H$5:$H$397,14,Ведомость!$I$5:$I$397,"А500С",Ведомость!$V$5:$V$397,"ЛВ-1") -> 0 | AC15: =SUMIFS(Ведомость!$N$5:$N$397,Ведомость!$H$5:$H$397,14,Ведомость!$I$5:$I$397,"А500С",Ведомость!$V$5:$V$397,"С-1") -> 0 | AD15: =SUM(B15:AC15) -> 240.46 | AE15: =IFERROR(INDEX(Исходные!$B$18:$B$29,MATCH(14,Исходные!$A$18:$A$29,0)),0) -> 1.208 | AF15: =AD15*AE15*$AH$2 -> 290.47568 | AG15: =SUM(B15:J15) -> 60.9 | AH15: =AE15 -> 1.208 | AI15: =AG15*AH15*$AH$2 -> 73.5672 | AJ15: =SUM(K15:AA15) -> 179.56 | AK15: =AE15 -> 1.208 | AL15: =AJ15*AK15*$AH$2 -> 216.90848 | AM15: =SUM(AB15:AB15) -> 0 | AN15: =AE15 -> 1.208 | AO15: =AM15*AN15*$AH$2 -> 0 | AP15: =SUM(AC15:AC15) -> 0 | AQ15: =AE15 -> 1.208 | AR15: =AP15*AQ15*$AH$2 -> 0
A16: Диаметр 12 А500С, L=м.п. | B16: =SUMIFS(Ведомость!$N$5:$N$397,Ведомость!$H$5:$H$397,12,Ведомость!$I$5:$I$397,"А500С",Ведомость!$V$5:$V$397,"Дм-1") -> 0 | C16: =SUMIFS(Ведомость!$N$5:$N$397,Ведомость!$H$5:$H$397,12,Ведомость!$I$5:$I$397,"А500С",Ведомость!$V$5:$V$397,"Дм-2") -> 0 | D16: =SUMIFS(Ведомость!$N$5:$N$397,Ведомость!$H$5:$H$397,12,Ведомость!$I$5:$I$397,"А500С",Ведомость!$V$5:$V$397,"Дм-3") -> 0 | E16: =SUMIFS(Ведомость!$N$5:$N$397,Ведомость!$H$5:$H$397,12,Ведомость!$I$5:$I$397,"А500С",Ведомость!$V$5:$V$397,"Дм-4") -> 0 | F16: =SUMIFS(Ведомость!$N$5:$N$397,Ведомость!$H$5:$H$397,12,Ведомость!$I$5:$I$397,"А500С",Ведомость!$V$5:$V$397,"Дм-5") -> 0 | G16: =SUMIFS(Ведомость!$N$5:$N$397,Ведомость!$H$5:$H$397,12,Ведомость!$I$5:$I$397,"А500С",Ведомость!$V$5:$V$397,"К-А") -> 0 | H16: =SUMIFS(Ведомость!$N$5:$N$397,Ведомость!$H$5:$H$397,12,Ведомость!$I$5:$I$397,"А500С",Ведомость!$V$5:$V$397,"К-Б") -> 0 | I16: =SUMIFS(Ведомость!$N$5:$N$397,Ведомость!$H$5:$H$397,12,Ведомость!$I$5:$I$397,"А500С",Ведомость!$V$5:$V$397,"К-В") -> 0 | J16: =SUMIFS(Ведомость!$N$5:$N$397,Ведомость!$H$5:$H$397,12,Ведомость!$I$5:$I$397,"А500С",Ведомость!$V$5:$V$397,"К-Г") -> 0 | K16: =SUMIFS(Ведомость!$N$5:$N$397,Ведомость!$H$5:$H$397,12,Ведомость!$I$5:$I$397,"А500С",Ведомость!$V$5:$V$397,"Р-А") -> 0 | L16: =SUMIFS(Ведомость!$N$5:$N$397,Ведомость!$H$5:$H$397,12,Ведомость!$I$5:$I$397,"А500С",Ведомость!$V$5:$V$397,"Р-Б") -> 28.4 | M16: =SUMIFS(Ведомость!$N$5:$N$397,Ведомость!$H$5:$H$397,12,Ведомость!$I$5:$I$397,"А500С",Ведомость!$V$5:$V$397,"Р-В") -> 68.784 | N16: =SUMIFS(Ведомость!$N$5:$N$397,Ведомость!$H$5:$H$397,12,Ведомость!$I$5:$I$397,"А500С",Ведомость!$V$5:$V$397,"Р-Г") -> 0 | O16: =SUMIFS(Ведомость!$N$5:$N$397,Ведомость!$H$5:$H$397,12,Ведомость!$I$5:$I$397,"А500С",Ведомость!$V$5:$V$397,"Р-1, 5") -> 16.4 | P16: =SUMIFS(Ведомость!$N$5:$N$397,Ведомость!$H$5:$H$397,12,Ведомость!$I$5:$I$397,"А500С",Ведомость!$V$5:$V$397,"Р-2") -> 0 | Q16: =SUMIFS(Ведомость!$N$5:$N$397,Ведомость!$H$5:$H$397,12,Ведомость!$I$5:$I$397,"А500С",Ведомость!$V$5:$V$397,"Р-3") -> 38.6 | R16: =SUMIFS(Ведомость!$N$5:$N$397,Ведомость!$H$5:$H$397,12,Ведомость!$I$5:$I$397,"А500С",Ведомость!$V$5:$V$397,"Р-4") -> 46.8 | S16: =SUMIFS(Ведомость!$N$5:$N$397,Ведомость!$H$5:$H$397,12,Ведомость!$I$5:$I$397,"А500С",Ведомость!$V$5:$V$397,"Б-основная") -> 0 | T16: =SUMIFS(Ведомость!$N$5:$N$397,Ведомость!$H$5:$H$397,12,Ведомость!$I$5:$I$397,"А500С",Ведомость!$V$5:$V$397,"Б-хомуты") -> 0 | U16: =SUMIFS(Ведомость!$N$5:$N$397,Ведомость!$H$5:$H$397,12,Ведомость!$I$5:$I$397,"А500С",Ведомость!$V$5:$V$397,"Б-допник") -> 0 | V16: =SUMIFS(Ведомость!$N$5:$N$397,Ведомость!$H$5:$H$397,12,Ведомость!$I$5:$I$397,"А500С",Ведомость!$V$5:$V$397,"П-сетка") -> 0 | W16: =SUMIFS(Ведомость!$N$5:$N$397,Ведомость!$H$5:$H$397,12,Ведомость!$I$5:$I$397,"А500С",Ведомость!$V$5:$V$397,"П-фикс") -> 0 | X16: =SUMIFS(Ведомость!$N$5:$N$397,Ведомость!$H$5:$H$397,12,Ведомость!$I$5:$I$397,"А500С",Ведомость!$V$5:$V$397,"П-отв") -> 0 | Y16: =SUMIFS(Ведомость!$N$5:$N$397,Ведомость!$H$5:$H$397,12,Ведомость!$I$5:$I$397,"А500С",Ведомость!$V$5:$V$397,"П-доп-низ") -> 0 | Z16: =SUMIFS(Ведомость!$N$5:$N$397,Ведомость!$H$5:$H$397,12,Ведомость!$I$5:$I$397,"А500С",Ведомость!$V$5:$V$397,"П-доп-верх") -> 43.2 | AA16: =SUMIFS(Ведомость!$N$5:$N$397,Ведомость!$H$5:$H$397,12,Ведомость!$I$5:$I$397,"А500С",Ведомость!$V$5:$V$397,"П-край") -> 0 | AB16: =SUMIFS(Ведомость!$N$5:$N$397,Ведомость!$H$5:$H$397,12,Ведомость!$I$5:$I$397,"А500С",Ведомость!$V$5:$V$397,"ЛВ-1") -> 0 | AC16: =SUMIFS(Ведомость!$N$5:$N$397,Ведомость!$H$5:$H$397,12,Ведомость!$I$5:$I$397,"А500С",Ведомость!$V$5:$V$397,"С-1") -> 0 | AD16: =SUM(B16:AC16) -> 242.184 | AE16: =IFERROR(INDEX(Исходные!$B$18:$B$29,MATCH(12,Исходные!$A$18:$A$29,0)),0) -> 0.888 | AF16: =AD16*AE16*$AH$2 -> 215.05939 | AG16: =SUM(B16:J16) -> 0 | AH16: =AE16 -> 0.888 | AI16: =AG16*AH16*$AH$2 -> 0 | AJ16: =SUM(K16:AA16) -> 242.184 | AK16: =AE16 -> 0.888 | AL16: =AJ16*AK16*$AH$2 -> 215.05939 | AM16: =SUM(AB16:AB16) -> 0 | AN16: =AE16 -> 0.888 | AO16: =AM16*AN16*$AH$2 -> 0 | AP16: =SUM(AC16:AC16) -> 0 | AQ16: =AE16 -> 0.888 | AR16: =AP16*AQ16*$AH$2 -> 0
A17: Диаметр 10 А500С, L=м.п. | B17: =SUMIFS(Ведомость!$N$5:$N$397,Ведомость!$H$5:$H$397,10,Ведомость!$I$5:$I$397,"А500С",Ведомость!$V$5:$V$397,"Дм-1") -> 4.8 | C17: =SUMIFS(Ведомость!$N$5:$N$397,Ведомость!$H$5:$H$397,10,Ведомость!$I$5:$I$397,"А500С",Ведомость!$V$5:$V$397,"Дм-2") -> 0 | D17: =SUMIFS(Ведомость!$N$5:$N$397,Ведомость!$H$5:$H$397,10,Ведомость!$I$5:$I$397,"А500С",Ведомость!$V$5:$V$397,"Дм-3") -> 0 | E17: =SUMIFS(Ведомость!$N$5:$N$397,Ведомость!$H$5:$H$397,10,Ведомость!$I$5:$I$397,"А500С",Ведомость!$V$5:$V$397,"Дм-4") -> 0 | F17: =SUMIFS(Ведомость!$N$5:$N$397,Ведомость!$H$5:$H$397,10,Ведомость!$I$5:$I$397,"А500С",Ведомость!$V$5:$V$397,"Дм-5") -> 7.5 | G17: =SUMIFS(Ведомость!$N$5:$N$397,Ведомость!$H$5:$H$397,10,Ведомость!$I$5:$I$397,"А500С",Ведомость!$V$5:$V$397,"К-А") -> 0 | H17: =SUMIFS(Ведомость!$N$5:$N$397,Ведомость!$H$5:$H$397,10,Ведомость!$I$5:$I$397,"А500С",Ведомость!$V$5:$V$397,"К-Б") -> 0 | I17: =SUMIFS(Ведомость!$N$5:$N$397,Ведомость!$H$5:$H$397,10,Ведомость!$I$5:$I$397,"А500С",Ведомость!$V$5:$V$397,"К-В") -> 0 | J17: =SUMIFS(Ведомость!$N$5:$N$397,Ведомость!$H$5:$H$397,10,Ведомость!$I$5:$I$397,"А500С",Ведомость!$V$5:$V$397,"К-Г") -> 0 | K17: =SUMIFS(Ведомость!$N$5:$N$397,Ведомость!$H$5:$H$397,10,Ведомость!$I$5:$I$397,"А500С",Ведомость!$V$5:$V$397,"Р-А") -> 0 | L17: =SUMIFS(Ведомость!$N$5:$N$397,Ведомость!$H$5:$H$397,10,Ведомость!$I$5:$I$397,"А500С",Ведомость!$V$5:$V$397,"Р-Б") -> 0 | M17: =SUMIFS(Ведомость!$N$5:$N$397,Ведомость!$H$5:$H$397,10,Ведомость!$I$5:$I$397,"А500С",Ведомость!$V$5:$V$397,"Р-В") -> 0 | N17: =SUMIFS(Ведомость!$N$5:$N$397,Ведомость!$H$5:$H$397,10,Ведомость!$I$5:$I$397,"А500С",Ведомость!$V$5:$V$397,"Р-Г") -> 0 | O17: =SUMIFS(Ведомость!$N$5:$N$397,Ведомость!$H$5:$H$397,10,Ведомость!$I$5:$I$397,"А500С",Ведомость!$V$5:$V$397,"Р-1, 5") -> 0 | P17: =SUMIFS(Ведомость!$N$5:$N$397,Ведомость!$H$5:$H$397,10,Ведомость!$I$5:$I$397,"А500С",Ведомость!$V$5:$V$397,"Р-2") -> 0 | Q17: =SUMIFS(Ведомость!$N$5:$N$397,Ведомость!$H$5:$H$397,10,Ведомость!$I$5:$I$397,"А500С",Ведомость!$V$5:$V$397,"Р-3") -> 0 | R17: =SUMIFS(Ведомость!$N$5:$N$397,Ведомость!$H$5:$H$397,10,Ведомость!$I$5:$I$397,"А500С",Ведомость!$V$5:$V$397,"Р-4") -> 0 | S17: =SUMIFS(Ведомость!$N$5:$N$397,Ведомость!$H$5:$H$397,10,Ведомость!$I$5:$I$397,"А500С",Ведомость!$V$5:$V$397,"Б-основная") -> 0 | T17: =SUMIFS(Ведомость!$N$5:$N$397,Ведомость!$H$5:$H$397,10,Ведомость!$I$5:$I$397,"А500С",Ведомость!$V$5:$V$397,"Б-хомуты") -> 0 | U17: =SUMIFS(Ведомость!$N$5:$N$397,Ведомость!$H$5:$H$397,10,Ведомость!$I$5:$I$397,"А500С",Ведомость!$V$5:$V$397,"Б-допник") -> 0 | V17: =SUMIFS(Ведомость!$N$5:$N$397,Ведомость!$H$5:$H$397,10,Ведомость!$I$5:$I$397,"А500С",Ведомость!$V$5:$V$397,"П-сетка") -> 11113.06 | W17: =SUMIFS(Ведомость!$N$5:$N$397,Ведомость!$H$5:$H$397,10,Ведомость!$I$5:$I$397,"А500С",Ведомость!$V$5:$V$397,"П-фикс") -> 0 | X17: =SUMIFS(Ведомость!$N$5:$N$397,Ведомость!$H$5:$H$397,10,Ведомость!$I$5:$I$397,"А500С",Ведомость!$V$5:$V$397,"П-отв") -> 0 | Y17: =SUMIFS(Ведомость!$N$5:$N$397,Ведомость!$H$5:$H$397,10,Ведомость!$I$5:$I$397,"А500С",Ведомость!$V$5:$V$397,"П-доп-низ") -> 393 | Z17: =SUMIFS(Ведомость!$N$5:$N$397,Ведомость!$H$5:$H$397,10,Ведомость!$I$5:$I$397,"А500С",Ведомость!$V$5:$V$397,"П-доп-верх") -> 529 | AA17: =SUMIFS(Ведомость!$N$5:$N$397,Ведомость!$H$5:$H$397,10,Ведомость!$I$5:$I$397,"А500С",Ведомость!$V$5:$V$397,"П-край") -> 0 | AB17: =SUMIFS(Ведомость!$N$5:$N$397,Ведомость!$H$5:$H$397,10,Ведомость!$I$5:$I$397,"А500С",Ведомость!$V$5:$V$397,"ЛВ-1") -> 0 | AC17: =SUMIFS(Ведомость!$N$5:$N$397,Ведомость!$H$5:$H$397,10,Ведомость!$I$5:$I$397,"А500С",Ведомость!$V$5:$V$397,"С-1") -> 957.6 | AD17: =SUM(B17:AC17) -> 13004.96 | AE17: =IFERROR(INDEX(Исходные!$B$18:$B$29,MATCH(10,Исходные!$A$18:$A$29,0)),0) -> 0.617 | AF17: =AD17*AE17*$AH$2 -> 8024.0603 | AG17: =SUM(B17:J17) -> 12.3 | AH17: =AE17 -> 0.617 | AI17: =AG17*AH17*$AH$2 -> 7.5891 | AJ17: =SUM(K17:AA17) -> 12035.06 | AK17: =AE17 -> 0.617 | AL17: =AJ17*AK17*$AH$2 -> 7425.632 | AM17: =SUM(AB17:AB17) -> 0 | AN17: =AE17 -> 0.617 | AO17: =AM17*AN17*$AH$2 -> 0 | AP17: =SUM(AC17:AC17) -> 957.6 | AQ17: =AE17 -> 0.617 | AR17: =AP17*AQ17*$AH$2 -> 590.8392
A18: Диаметр 8 А500С, L=м.п. | B18: =SUMIFS(Ведомость!$N$5:$N$397,Ведомость!$H$5:$H$397,8,Ведомость!$I$5:$I$397,"А500С",Ведомость!$V$5:$V$397,"Дм-1") -> 0 | C18: =SUMIFS(Ведомость!$N$5:$N$397,Ведомость!$H$5:$H$397,8,Ведомость!$I$5:$I$397,"А500С",Ведомость!$V$5:$V$397,"Дм-2") -> 0 | D18: =SUMIFS(Ведомость!$N$5:$N$397,Ведомость!$H$5:$H$397,8,Ведомость!$I$5:$I$397,"А500С",Ведомость!$V$5:$V$397,"Дм-3") -> 0 | E18: =SUMIFS(Ведомость!$N$5:$N$397,Ведомость!$H$5:$H$397,8,Ведомость!$I$5:$I$397,"А500С",Ведомость!$V$5:$V$397,"Дм-4") -> 0 | F18: =SUMIFS(Ведомость!$N$5:$N$397,Ведомость!$H$5:$H$397,8,Ведомость!$I$5:$I$397,"А500С",Ведомость!$V$5:$V$397,"Дм-5") -> 0 | G18: =SUMIFS(Ведомость!$N$5:$N$397,Ведомость!$H$5:$H$397,8,Ведомость!$I$5:$I$397,"А500С",Ведомость!$V$5:$V$397,"К-А") -> 0 | H18: =SUMIFS(Ведомость!$N$5:$N$397,Ведомость!$H$5:$H$397,8,Ведомость!$I$5:$I$397,"А500С",Ведомость!$V$5:$V$397,"К-Б") -> 0 | I18: =SUMIFS(Ведомость!$N$5:$N$397,Ведомость!$H$5:$H$397,8,Ведомость!$I$5:$I$397,"А500С",Ведомость!$V$5:$V$397,"К-В") -> 0 | J18: =SUMIFS(Ведомость!$N$5:$N$397,Ведомость!$H$5:$H$397,8,Ведомость!$I$5:$I$397,"А500С",Ведомость!$V$5:$V$397,"К-Г") -> 0 | K18: =SUMIFS(Ведомость!$N$5:$N$397,Ведомость!$H$5:$H$397,8,Ведомость!$I$5:$I$397,"А500С",Ведомость!$V$5:$V$397,"Р-А") -> 0 | L18: =SUMIFS(Ведомость!$N$5:$N$397,Ведомость!$H$5:$H$397,8,Ведомость!$I$5:$I$397,"А500С",Ведомость!$V$5:$V$397,"Р-Б") -> 0 | M18: =SUMIFS(Ведомость!$N$5:$N$397,Ведомость!$H$5:$H$397,8,Ведомость!$I$5:$I$397,"А500С",Ведомость!$V$5:$V$397,"Р-В") -> 0 | N18: =SUMIFS(Ведомость!$N$5:$N$397,Ведомость!$H$5:$H$397,8,Ведомость!$I$5:$I$397,"А500С",Ведомость!$V$5:$V$397,"Р-Г") -> 0 | O18: =SUMIFS(Ведомость!$N$5:$N$397,Ведомость!$H$5:$H$397,8,Ведомость!$I$5:$I$397,"А500С",Ведомость!$V$5:$V$397,"Р-1, 5") -> 0 | P18: =SUMIFS(Ведомость!$N$5:$N$397,Ведомость!$H$5:$H$397,8,Ведомость!$I$5:$I$397,"А500С",Ведомость!$V$5:$V$397,"Р-2") -> 0 | Q18: =SUMIFS(Ведомость!$N$5:$N$397,Ведомость!$H$5:$H$397,8,Ведомость!$I$5:$I$397,"А500С",Ведомость!$V$5:$V$397,"Р-3") -> 0 | R18: =SUMIFS(Ведомость!$N$5:$N$397,Ведомость!$H$5:$H$397,8,Ведомость!$I$5:$I$397,"А500С",Ведомость!$V$5:$V$397,"Р-4") -> 0 | S18: =SUMIFS(Ведомость!$N$5:$N$397,Ведомость!$H$5:$H$397,8,Ведомость!$I$5:$I$397,"А500С",Ведомость!$V$5:$V$397,"Б-основная") -> 0 | T18: =SUMIFS(Ведомость!$N$5:$N$397,Ведомость!$H$5:$H$397,8,Ведомость!$I$5:$I$397,"А500С",Ведомость!$V$5:$V$397,"Б-хомуты") -> 0 | U18: =SUMIFS(Ведомость!$N$5:$N$397,Ведомость!$H$5:$H$397,8,Ведомость!$I$5:$I$397,"А500С",Ведомость!$V$5:$V$397,"Б-допник") -> 0 | V18: =SUMIFS(Ведомость!$N$5:$N$397,Ведомость!$H$5:$H$397,8,Ведомость!$I$5:$I$397,"А500С",Ведомость!$V$5:$V$397,"П-сетка") -> 0 | W18: =SUMIFS(Ведомость!$N$5:$N$397,Ведомость!$H$5:$H$397,8,Ведомость!$I$5:$I$397,"А500С",Ведомость!$V$5:$V$397,"П-фикс") -> 0 | X18: =SUMIFS(Ведомость!$N$5:$N$397,Ведомость!$H$5:$H$397,8,Ведомость!$I$5:$I$397,"А500С",Ведомость!$V$5:$V$397,"П-отв") -> 0 | Y18: =SUMIFS(Ведомость!$N$5:$N$397,Ведомость!$H$5:$H$397,8,Ведомость!$I$5:$I$397,"А500С",Ведомость!$V$5:$V$397,"П-доп-низ") -> 0 | Z18: =SUMIFS(Ведомость!$N$5:$N$397,Ведомость!$H$5:$H$397,8,Ведомость!$I$5:$I$397,"А500С",Ведомость!$V$5:$V$397,"П-доп-верх") -> 0 | AA18: =SUMIFS(Ведомость!$N$5:$N$397,Ведомость!$H$5:$H$397,8,Ведомость!$I$5:$I$397,"А500С",Ведомость!$V$5:$V$397,"П-край") -> 0 | AB18: =SUMIFS(Ведомость!$N$5:$N$397,Ведомость!$H$5:$H$397,8,Ведомость!$I$5:$I$397,"А500С",Ведомость!$V$5:$V$397,"ЛВ-1") -> 0 | AC18: =SUMIFS(Ведомость!$N$5:$N$397,Ведомость!$H$5:$H$397,8,Ведомость!$I$5:$I$397,"А500С",Ведомость!$V$5:$V$397,"С-1") -> 0 | AD18: =SUM(B18:AC18) -> 0 | AE18: =IFERROR(INDEX(Исходные!$B$18:$B$29,MATCH(8,Исходные!$A$18:$A$29,0)),0) -> 0.395 | AF18: =AD18*AE18*$AH$2 -> 0 | AG18: =SUM(B18:J18) -> 0 | AH18: =AE18 -> 0.395 | AI18: =AG18*AH18*$AH$2 -> 0 | AJ18: =SUM(K18:AA18) -> 0 | AK18: =AE18 -> 0.395 | AL18: =AJ18*AK18*$AH$2 -> 0 | AM18: =SUM(AB18:AB18) -> 0 | AN18: =AE18 -> 0.395 | AO18: =AM18*AN18*$AH$2 -> 0 | AP18: =SUM(AC18:AC18) -> 0 | AQ18: =AE18 -> 0.395 | AR18: =AP18*AQ18*$AH$2 -> 0
A19: Диаметр 12 А240, L=м.п. | B19: =SUMIFS(Ведомость!$N$5:$N$397,Ведомость!$H$5:$H$397,12,Ведомость!$I$5:$I$397,"А240",Ведомость!$V$5:$V$397,"Дм-1") -> 0 | C19: =SUMIFS(Ведомость!$N$5:$N$397,Ведомость!$H$5:$H$397,12,Ведомость!$I$5:$I$397,"А240",Ведомость!$V$5:$V$397,"Дм-2") -> 0 | D19: =SUMIFS(Ведомость!$N$5:$N$397,Ведомость!$H$5:$H$397,12,Ведомость!$I$5:$I$397,"А240",Ведомость!$V$5:$V$397,"Дм-3") -> 0 | E19: =SUMIFS(Ведомость!$N$5:$N$397,Ведомость!$H$5:$H$397,12,Ведомость!$I$5:$I$397,"А240",Ведомость!$V$5:$V$397,"Дм-4") -> 0 | F19: =SUMIFS(Ведомость!$N$5:$N$397,Ведомость!$H$5:$H$397,12,Ведомость!$I$5:$I$397,"А240",Ведомость!$V$5:$V$397,"Дм-5") -> 0 | G19: =SUMIFS(Ведомость!$N$5:$N$397,Ведомость!$H$5:$H$397,12,Ведомость!$I$5:$I$397,"А240",Ведомость!$V$5:$V$397,"К-А") -> 0 | H19: =SUMIFS(Ведомость!$N$5:$N$397,Ведомость!$H$5:$H$397,12,Ведомость!$I$5:$I$397,"А240",Ведомость!$V$5:$V$397,"К-Б") -> 0 | I19: =SUMIFS(Ведомость!$N$5:$N$397,Ведомость!$H$5:$H$397,12,Ведомость!$I$5:$I$397,"А240",Ведомость!$V$5:$V$397,"К-В") -> 0 | J19: =SUMIFS(Ведомость!$N$5:$N$397,Ведомость!$H$5:$H$397,12,Ведомость!$I$5:$I$397,"А240",Ведомость!$V$5:$V$397,"К-Г") -> 0 | K19: =SUMIFS(Ведомость!$N$5:$N$397,Ведомость!$H$5:$H$397,12,Ведомость!$I$5:$I$397,"А240",Ведомость!$V$5:$V$397,"Р-А") -> 0 | L19: =SUMIFS(Ведомость!$N$5:$N$397,Ведомость!$H$5:$H$397,12,Ведомость!$I$5:$I$397,"А240",Ведомость!$V$5:$V$397,"Р-Б") -> 0 | M19: =SUMIFS(Ведомость!$N$5:$N$397,Ведомость!$H$5:$H$397,12,Ведомость!$I$5:$I$397,"А240",Ведомость!$V$5:$V$397,"Р-В") -> 0 | N19: =SUMIFS(Ведомость!$N$5:$N$397,Ведомость!$H$5:$H$397,12,Ведомость!$I$5:$I$397,"А240",Ведомость!$V$5:$V$397,"Р-Г") -> 0 | O19: =SUMIFS(Ведомость!$N$5:$N$397,Ведомость!$H$5:$H$397,12,Ведомость!$I$5:$I$397,"А240",Ведомость!$V$5:$V$397,"Р-1, 5") -> 0 | P19: =SUMIFS(Ведомость!$N$5:$N$397,Ведомость!$H$5:$H$397,12,Ведомость!$I$5:$I$397,"А240",Ведомость!$V$5:$V$397,"Р-2") -> 0 | Q19: =SUMIFS(Ведомость!$N$5:$N$397,Ведомость!$H$5:$H$397,12,Ведомость!$I$5:$I$397,"А240",Ведомость!$V$5:$V$397,"Р-3") -> 0 | R19: =SUMIFS(Ведомость!$N$5:$N$397,Ведомость!$H$5:$H$397,12,Ведомость!$I$5:$I$397,"А240",Ведомость!$V$5:$V$397,"Р-4") -> 0 | S19: =SUMIFS(Ведомость!$N$5:$N$397,Ведомость!$H$5:$H$397,12,Ведомость!$I$5:$I$397,"А240",Ведомость!$V$5:$V$397,"Б-основная") -> 0 | T19: =SUMIFS(Ведомость!$N$5:$N$397,Ведомость!$H$5:$H$397,12,Ведомость!$I$5:$I$397,"А240",Ведомость!$V$5:$V$397,"Б-хомуты") -> 0 | U19: =SUMIFS(Ведомость!$N$5:$N$397,Ведомость!$H$5:$H$397,12,Ведомость!$I$5:$I$397,"А240",Ведомость!$V$5:$V$397,"Б-допник") -> 0 | V19: =SUMIFS(Ведомость!$N$5:$N$397,Ведомость!$H$5:$H$397,12,Ведомость!$I$5:$I$397,"А240",Ведомость!$V$5:$V$397,"П-сетка") -> 0 | W19: =SUMIFS(Ведомость!$N$5:$N$397,Ведомость!$H$5:$H$397,12,Ведомость!$I$5:$I$397,"А240",Ведомость!$V$5:$V$397,"П-фикс") -> 0 | X19: =SUMIFS(Ведомость!$N$5:$N$397,Ведомость!$H$5:$H$397,12,Ведомость!$I$5:$I$397,"А240",Ведомость!$V$5:$V$397,"П-отв") -> 0 | Y19: =SUMIFS(Ведомость!$N$5:$N$397,Ведомость!$H$5:$H$397,12,Ведомость!$I$5:$I$397,"А240",Ведомость!$V$5:$V$397,"П-доп-низ") -> 0 | Z19: =SUMIFS(Ведомость!$N$5:$N$397,Ведомость!$H$5:$H$397,12,Ведомость!$I$5:$I$397,"А240",Ведомость!$V$5:$V$397,"П-доп-верх") -> 0 | AA19: =SUMIFS(Ведомость!$N$5:$N$397,Ведомость!$H$5:$H$397,12,Ведомость!$I$5:$I$397,"А240",Ведомость!$V$5:$V$397,"П-край") -> 0 | AB19: =SUMIFS(Ведомость!$N$5:$N$397,Ведомость!$H$5:$H$397,12,Ведомость!$I$5:$I$397,"А240",Ведомость!$V$5:$V$397,"ЛВ-1") -> 0 | AC19: =SUMIFS(Ведомость!$N$5:$N$397,Ведомость!$H$5:$H$397,12,Ведомость!$I$5:$I$397,"А240",Ведомость!$V$5:$V$397,"С-1") -> 0 | AD19: =SUM(B19:AC19) -> 0 | AE19: =IFERROR(INDEX(Исходные!$B$18:$B$29,MATCH(12,Исходные!$A$18:$A$29,0)),0) -> 0.888 | AF19: =AD19*AE19*$AH$2 -> 0 | AG19: =SUM(B19:J19) -> 0 | AH19: =AE19 -> 0.888 | AI19: =AG19*AH19*$AH$2 -> 0 | AJ19: =SUM(K19:AA19) -> 0 | AK19: =AE19 -> 0.888 | AL19: =AJ19*AK19*$AH$2 -> 0 | AM19: =SUM(AB19:AB19) -> 0 | AN19: =AE19 -> 0.888 | AO19: =AM19*AN19*$AH$2 -> 0 | AP19: =SUM(AC19:AC19) -> 0 | AQ19: =AE19 -> 0.888 | AR19: =AP19*AQ19*$AH$2 -> 0
