Workbook

Sheet потребность
A1: Блок 14, ул. Токомбаева — потребность по этажам
A2: Арматура (чистая проектная масса, без запаса)
A3: Диаметр | B3: Ед. изм. | C3: 1 этаж (-0.050…+3.950) | F3: 2 этаж (+3.950…+7.550) | I3: Итого 1+2 этаж | J3: Итого × К зап | K3: Заказ (раскрой поэтажно под прутки 11,7 м)
C4: Колонны, диафрагмы | D4: Плита перекрытия, балки, ригели, С-1 | E4: Лестницы и лест. рамы | F4: Колонны, диафрагмы | G4: Плита перекрытия, балки, ригели, С-1 | H4: Лестницы и лест. рамы | K4: Прутков 11,7 м, шт | L4: Масса заказа, кг | M4: Отход, %
A5: Диаметр 32 А500С | B5: кг | C5: ='По осям'!AJ8*'По осям'!AK8 -> 2020.16 | D5: ='По осям'!AM8*'По осям'!AN8 -> 643.2947 | E5: ='По осям'!AP8*'По осям'!AQ8 -> 0 | F5: ='По осям'!AJ54*'По осям'!AK54 -> 0 | G5: ='По осям'!AM54*'По осям'!AN54 -> 707.056 | H5: ='По осям'!AP54*'По осям'!AQ54 -> 0 | I5: =SUM(C5:H5) -> 3370.5107 | J5: =I5*Исходные!$B$13 -> 3606.4464 | K5: ='Раскрой 11,7м'!D447 -> 55 | L5: ='Раскрой 11,7м'!E447 -> 4062.4155 | M5: ='Раскрой 11,7м'!H447 -> 0.17031857
A6: Диаметр 28 А500С | B6: кг | C6: ='По осям'!AJ9*'По осям'!AK9 -> 2010.944 | D6: ='По осям'!AM9*'По осям'!AN9 -> 4612.1194 | E6: ='По осям'!AP9*'По осям'!AQ9 -> 0 | F6: ='По осям'!AJ55*'По осям'!AK55 -> 1392.192 | G6: ='По осям'!AM55*'По осям'!AN55 -> 4718.4674 | H6: ='По осям'!AP55*'По осям'!AQ55 -> 0 | I6: =SUM(C6:H6) -> 12733.723 | J6: =I6*Исходные!$B$13 -> 13625.083 | K6: ='Раскрой 11,7м'!D448 -> 244 | L6: ='Раскрой 11,7м'!E448 -> 13800.103 | M6: ='Раскрой 11,7м'!H448 -> 0.077273364
A7: Диаметр 25 А500С | B7: кг | C7: ='По осям'!AJ10*'По осям'!AK10 -> 554.832 | D7: ='По осям'!AM10*'По осям'!AN10 -> 2915.1798 | E7: ='По осям'!AP10*'По осям'!AQ10 -> 82.37714 | F7: ='По осям'!AJ56*'По осям'!AK56 -> 832.248 | G7: ='По осям'!AM56*'По осям'!AN56 -> 2930.9771 | H7: ='По осям'!AP56*'По осям'!AQ56 -> 81.2983 | I7: =SUM(C7:H7) -> 7396.9123 | J7: =I7*Исходные!$B$13 -> 7914.6962 | K7: ='Раскрой 11,7м'!D449 -> 171 | L7: ='Раскрой 11,7м'!E449 -> 7708.6971 | M7: ='Раскрой 11,7м'!H449 -> 0.040445844
A8: Диаметр 22 А500С | B8: кг | C8: ='По осям'!AJ11*'По осям'!AK11 -> 468.488 | D8: ='По осям'!AM11*'По осям'!AN11 -> 644.8424 | E8: ='По осям'!AP11*'По осям'!AQ11 -> 0 | F8: ='По осям'!AJ57*'По осям'!AK57 -> 64.4544 | G8: ='По осям'!AM57*'По осям'!AN57 -> 631.116 | H8: ='По осям'!AP57*'По осям'!AQ57 -> 0 | I8: =SUM(C8:H8) -> 1808.9008 | J8: =I8*Исходные!$B$13 -> 1935.5239 | K8: ='Раскрой 11,7м'!D450 -> 56 | L8: ='Раскрой 11,7м'!E450 -> 1955.1168 | M8: ='Раскрой 11,7м'!H450 -> 0.074786325
A9: Диаметр 20 А500С | B9: кг | C9: ='По осям'!AJ12*'По осям'!AK12 -> 1732.8582 | D9: ='По осям'!AM12*'По осям'!AN12 -> 205.02324 | E9: ='По осям'!AP12*'По осям'!AQ12 -> 0 | F9: ='По осям'!AJ58*'По осям'!AK58 -> 1455.9264 | G9: ='По осям'!AM58*'По осям'!AN58 -> 305.19216 | H9: ='По осям'!AP58*'По осям'!AQ58 -> 0 | I9: =SUM(C9:H9) -> 3699 | J9: =I9*Исходные!$B$13 -> 3957.93 | K9: ='Раскрой 11,7м'!D451 -> 154 | L9: ='Раскрой 11,7м'!E451 -> 4443.2388 | M9: ='Раскрой 11,7м'!H451 -> 0.16749917
A10: Диаметр 18 А500С | B10: кг | C10: ='По осям'!AJ13*'По осям'!AK13 -> 280.99872 | D10: ='По осям'!AM13*'По осям'!AN13 -> 925.36171 | E10: ='По осям'!AP13*'По осям'!AQ13 -> 447.32023 | F10: ='По осям'!AJ59*'По осям'!AK59 -> 239.37638 | G10: ='По осям'!AM59*'По осям'!AN59 -> 964.12291 | H10: ='По осям'!AP59*'По осям'!AQ59 -> 439.40815 | I10: =SUM(C10:H10) -> 3296.5881 | J10: =I10*Исходные!$B$13 -> 3527.3493 | K10: ='Раскрой 11,7м'!D452 -> 146 | L10: ='Раскрой 11,7м'!E452 -> 3412.9836 | M10: ='Раскрой 11,7м'!H452 -> 0.034103735
A11: Диаметр 16 А500С | B11: кг | C11: ='По осям'!AJ14*'По осям'!AK14 -> 693.3732 | D11: ='По осям'!AM14*'По осям'!AN14 -> 845.22098 | E11: ='По осям'!AP14*'По осям'!AQ14 -> 0 | F11: ='По осям'!AJ60*'По осям'!AK60 -> 404.15105 | G11: ='По осям'!AM60*'По осям'!AN60 -> 823.60238 | H11: ='По осям'!AP60*'По осям'!AQ60 -> 0 | I11: =SUM(C11:H11) -> 2766.3476 | J11: =I11*Исходные!$B$13 -> 2959.9919 | K11: ='Раскрой 11,7м'!D453 -> 153 | L11: ='Раскрой 11,7м'!E453 -> 2824.7778 | M11: ='Раскрой 11,7м'!H453 -> 0.020684878
A12: Диаметр 14 А500С | B12: кг | C12: ='По осям'!AJ15*'По осям'!AK15 -> 73.5672 | D12: ='По осям'!AM15*'По осям'!AN15 -> 216.90848 | E12: ='По осям'!AP15*'По осям'!AQ15 -> 0 | F12: ='По осям'!AJ61*'По осям'!AK61 -> 494.79197 | G12: ='По осям'!AM61*'По осям'!AN61 -> 243.33952 | H12: ='По осям'!AP61*'По осям'!AQ61 -> 0 | I12: =SUM(C12:H12) -> 1028.6072 | J12: =I12*Исходные!$B$13 -> 1100.6097 | K12: ='Раскрой 11,7м'!D454 -> 75 | L12: ='Раскрой 11,7м'!E454 -> 1060.02 | M12: ='Раскрой 11,7м'!H454 -> 0.029634188
A13: Диаметр 12 А500С | B13: кг | C13: ='По осям'!AJ16*'По осям'!AK16 -> 0 | D13: ='По осям'!AM16*'По осям'!AN16 -> 215.05939 | E13: ='По осям'!AP16*'По осям'!AQ16 -> 0 | F13: ='По осям'!AJ62*'По осям'!AK62 -> 95.016 | G13: ='По осям'!AM62*'По осям'!AN62 -> 260.68838 | H13: ='По осям'!AP62*'По осям'!AQ62 -> 0 | I13: =SUM(C13:H13) -> 570.76378 | J13: =I13*Исходные!$B$13 -> 610.71724 | K13: ='Раскрой 11,7м'!D455 -> 58 | L13: ='Раскрой 11,7м'!E455 -> 602.5968 | M13: ='Раскрой 11,7м'!H455 -> 0.052826407
A14: Диаметр 10 А500С | B14: кг | C14: ='По осям'!AJ17*'По осям'!AK17 -> 7.5891 | D14: ='По осям'!AM17*'По осям'!AN17 -> 8016.4712 | E14: ='По осям'!AP17*'По осям'!AQ17 -> 146.36474 | F14: ='По осям'!AJ63*'По осям'!AK63 -> 12.5868 | G14: ='По осям'!AM63*'По осям'!AN63 -> 8021.7527 | H14: ='По осям'!AP63*'По осям'!AQ63 -> 141.95936 | I14: =SUM(C14:H14) -> 16346.724 | J14: =I14*Исходные!$B$13 -> 17490.995 | K14: ='Раскрой 11,7м'!D456 -> 2284 | L14: ='Раскрой 11,7м'!E456 -> 16487.968 | M14: ='Раскрой 11,7м'!H456 -> 0.0085664676
A15: Диаметр 8 А500С | B15: кг | C15: ='По осям'!AJ18*'По осям'!AK18 -> 0 | D15: ='По осям'!AM18*'По осям'!AN18 -> 0 | E15: ='По осям'!AP18*'По осям'!AQ18 -> 0 | F15: ='По осям'!AJ64*'По осям'!AK64 -> 0 | G15: ='По осям'!AM64*'По осям'!AN64 -> 0 | H15: ='По осям'!AP64*'По осям'!AQ64 -> 0 | I15: =SUM(C15:H15) -> 0 | J15: =I15*Исходные!$B$13 -> 0 | K15: ='Раскрой 11,7м'!D457 -> 0 | L15: ='Раскрой 11,7м'!E457 -> 0 | M15: ='Раскрой 11,7м'!H457 -> 0
A16: Диаметр 16 А240 | B16: кг | C16: ='По осям'!AJ19*'По осям'!AK19 -> 0 | D16: ='По осям'!AM19*'По осям'!AN19 -> 0 | E16: ='По осям'!AP19*'По осям'!AQ19 -> 1.32552 | F16: ='По осям'!AJ65*'По осям'!AK65 -> 0 | G16: ='По осям'!AM65*'По осям'!AN65 -> 0 | H16: ='По осям'!AP65*'По осям'!AQ65 -> 1.32552 | I16: =SUM(C16:H16) -> 2.65104 | J16: =I16*Исходные!$B$13 -> 2.8366128 | K16: ='Раскрой 11,7м'!D458 -> 2 | L16: ='Раскрой 11,7м'!E458 -> 36.9252 | M16: ='Раскрой 11,7м'!H458 -> 0.92820513
... A21: Сетка Ø5 Вр-I 100×100 (лестница) | B21: кг | C21: ='По осям'!AJ24*'По осям'!AK24 -> 0 | D21: ='По осям'!AM24*'По осям'!AN24 -> 0 | E21: ='По осям'!AP24*'По осям'!AQ24 -> 43.12 | F21: ='По осям'!AJ70*'По осям'!AK70 -> 0 | G21: ='По осям'!AM70*'По осям'!AN70 -> 0 | H21: ='По осям'!AP70*'По осям'!AQ70 -> 39.3008 | I21: =SUM(C21:H21) -> 82.4208 | J21: =I21*Исходные!$B$13 -> 88.190256 | K21: ='Раскрой 11,7м'!D463 -> 0 | L21: ='Раскрой 11,7м'!E463 -> 82.4208 | M21: ='Раскрой 11,7м'!H463 -> 0
A22: Итого: | B22: кг | C22: =SUM(C5:C21) -> 9396.4436 | D22: =SUM(D5:D21) -> 22391.665 | E22: =SUM(E5:E21) -> 803.46467 | F22: =SUM(F5:F21) -> 6335.4016 | G22: =SUM(G5:G21) -> 22836.257 | H22: =SUM(H5:H21) -> 783.38341 | I22: =SUM(I5:I21) -> 62546.615 | J22: =SUM(J5:J21) -> 66924.879 | ... L22: =SUM(L5:L21) -> 66025.341 | M22: ='Раскрой 11,7м'!H464 -> 0.052687728
A23: Итого: | B23: т | C23: =C22/1000 -> 9.3964436 | D23: =D22/1000 -> 22.391665 | E23: =E22/1000 -> 0.80346467 | F23: =F22/1000 -> 6.3354016 | G23: =G22/1000 -> 22.836257 | H23: =H22/1000 -> 0.78338341 | I23: =I22/1000 -> 62.546615 | J23: =J22/1000 -> 66.924879 | L23: =L22/1000 -> 66.025341
A24: Итого по этажу, кг | B24: кг | C24: =SUM(C22:E22) -> 32591.573 | F24: =SUM(F22:H22) -> 29955.042 | I24: =I22 -> 62546.615
A25: Контроль: = «Ведомость» и «По осям» | I25: =ROUND(I22-Ведомость!P849,1)+ROUND(I22-'По осям'!AI25-'По осям'!AI71,1) -> 0 | J25: ← должно быть 0
A27: Бетон
A28: Марка | B28: Ед. изм. | C28: 1 этаж (-0.050…+3.950) | F28: 2 этаж (+3.950…+7.550) | I28: Итого 1+2 этаж
C29: Колонны, диафрагмы | D29: Плита перекрытия, балки, ригели, С-1 | E29: Лестницы и лест. рамы | F29: Колонны, диафрагмы | G29: Плита перекрытия, балки, ригели, С-1 | H29: Лестницы и лест. рамы
A30: В25 | B30: м3 | C30: ='По осям'!AL31 -> 43.9216 | D30: ='По осям'!AO31 -> 112.11321 | E30: ='По осям'!AR31 -> 3.2907172 | F30: ='По осям'!AL77 -> 39.3936 | G30: ='По осям'!AO77 -> 112.16529 | H30: ='По осям'!AR77 -> 3.069971 | I30: =SUM(C30:H30) -> 313.95439
A32: Прочие материалы
A33: Наименование | B33: Ед. изм. | C33: 1 этаж (-0.050…+3.950) | F33: 2 этаж (+3.950…+7.550) | I33: Итого 1+2 этаж
C34: Колонны, диафрагмы | D34: Плита перекрытия, балки, ригели, С-1 | E34: Лестницы и лест. рамы | F34: Колонны, диафрагмы | G34: Плита перекрытия, балки, ригели, С-1 | H34: Лестницы и лест. рамы
A35: Анкерная шайба АШ-1 (14) | B35: шт. | C35: ='По осям'!AJ35 -> 0 | D35: ='По осям'!AM35 -> 0 | E35: ='По осям'!AP35 -> 0 | F35: ='По осям'!AJ81 -> 0 | G35: ='По осям'!AM81 -> 0 | H35: ='По осям'!AP81 -> 0 | I35: =SUM(C35:H35) -> 0
A36: Анкерная шайба АШ-2 (16) | B36: шт. | C36: ='По осям'!AJ36 -> 0 | D36: ='По осям'!AM36 -> 0 | E36: ='По осям'!AP36 -> 0 | F36: ='По осям'!AJ82 -> 0 | G36: ='По осям'!AM82 -> 0 | H36: ='По осям'!AP82 -> 0 | I36: =SUM(C36:H36) -> 0
A37: Анкерная шайба АШ-3 (18) | B37: шт. | C37: ='По осям'!AJ37 -> 0 | D37: ='По осям'!AM37 -> 0 | E37: ='По осям'!AP37 -> 0 | F37: ='По осям'!AJ83 -> 0 | G37: ='По осям'!AM83 -> 0 | H37: ='По осям'!AP83 -> 0 | I37: =SUM(C37:H37) -> 0
A38: Анкерная шайба АШ-4 (20) | B38: шт. | C38: ='По осям'!AJ38 -> 0 | D38: ='По осям'!AM38 -> 0 | E38: ='По осям'!AP38 -> 0 | F38: ='По осям'!AJ84 -> 0 | G38: ='По осям'!AM84 -> 0 | H38: ='По осям'!AP84 -> 0 | I38: =SUM(C38:H38) -> 0
A39: Анкерная шайба АШ-5 (22) | B39: шт. | C39: ='По осям'!AJ39 -> 0 | D39: ='По осям'!AM39 -> 2 | E39: ='По осям'!AP39 -> 0 | F39: ='По осям'!AJ85 -> 0 | G39: ='По осям'!AM85 -> 2 | H39: ='По осям'!AP85 -> 0 | I39: =SUM(C39:H39) -> 4
A40: Анкерная шайба АШ-6 (25) | B40: шт. | C40: ='По осям'!AJ40 -> 0 | D40: ='По осям'!AM40 -> 16 | E40: ='По осям'!AP40 -> 34 | F40: ='По осям'!AJ86 -> 0 | G40: ='По осям'!AM86 -> 14 | H40: ='По осям'!AP86 -> 16 | I40: =SUM(C40:H40) -> 80
A41: Анкерная шайба АШ-7 (28) | B41: шт. | C41: ='По осям'!AJ41 -> 0 | D41: ='По осям'!AM41 -> 86 | E41: ='По осям'!AP41 -> 0 | F41: ='По осям'!AJ87 -> 0 | G41: ='По осям'!AM87 -> 82 | H41: ='По осям'!AP87 -> 0 | I41: =SUM(C41:H41) -> 168
A42: Анкерная шайба АШ-8 (32) | B42: шт. | C42: ='По осям'!AJ42 -> 0 | D42: ='По осям'!AM42 -> 6 | E42: ='По осям'!AP42 -> 0 | F42: ='По осям'!AJ88 -> 0 | G42: ='По осям'!AM88 -> 12 | H42: ='По осям'!AP88 -> 0 | I42: =SUM(C42:H42) -> 18
A43: Ванночка d32 (стыков ванной сваркой) | B43: шт. | C43: ='По осям'!AJ43 -> 80 | D43: ='По осям'!AM43 -> 0 | E43: ='По осям'!AP43 -> 0 | F43: ='По осям'!AJ89 -> 0 | G43: ='По осям'!AM89 -> 0 | H43: ='По осям'!AP89 -> 0 | I43: =SUM(C43:H43) -> 80
A44: Ванночка d28 (стыков ванной сваркой) | B44: шт. | C44: ='По осям'!AJ44 -> 104 | D44: ='По осям'!AM44 -> 52 | E44: ='По осям'!AP44 -> 0 | F44: ='По осям'!AJ90 -> 80 | G44: ='По осям'!AM90 -> 52 | H44: ='По осям'!AP90 -> 0 | I44: =SUM(C44:H44) -> 288
A45: Ванночка d25 (стыков ванной сваркой) | B45: шт. | C45: ='По осям'!AJ45 -> 36 | D45: ='По осям'!AM45 -> 40 | E45: ='По осям'!AP45 -> 0 | F45: ='По осям'!AJ91 -> 60 | G45: ='По осям'!AM91 -> 40 | H45: ='По осям'!AP91 -> 0 | I45: =SUM(C45:H45) -> 176
A46: Ванночка d22 (стыков ванной сваркой) | B46: шт. | C46: ='По осям'!AJ46 -> 36 | D46: ='По осям'!AM46 -> 0 | E46: ='По осям'!AP46 -> 0 | F46: ='По осям'!AJ92 -> 6 | G46: ='По осям'!AM92 -> 0 | H46: ='По осям'!AP92 -> 0 | I46: =SUM(C46:H46) -> 42
...

Sheet По осям
A1: Блок 14, ул. Токомбаева — подсчёт арматуры по осям: 1 этаж и 2 этаж (м.п. → кг) | AJ1: К зап | AK1: К зап бетон
A2: м.п. = SUMIFS из «Ведомости» (этаж, Ø, класс, колонка); Всего = м.п. × кг/м × К зап (как в шаблоне); чистая масса без запаса — отдельной строкой | AJ2: =Исходные!$B$13 -> 1.07 | AK2: =Исходные!$B$14 -> 1
A4: 1 ЭТАЖ | B4: Рамы | S4: Балки | V4: Перекрытие | AB4: Сетки С-1 | AC4: Лестничный марш | AJ4: Колонны, диафрагмы | AM4: Ригели, балки, плита, С-1 | AP4: Лестницы
A5: На отметке -0.050…+3.950 | B5: По оси А | C5: По оси А | D5: По оси А | E5: По оси А | F5: По оси Б | G5: По оси Б | H5: По оси В | I5: По оси В | J5: По оси Г | K5: По оси Г | L5: По оси Г | M5: По оси Г | N5: По оси Г | O5: По оси 1/5 | P5: По оси 2 | Q5: По оси 3 | R5: По оси 4 | S5: Основная | T5: Хомуты | U5: Допник | V5: Основная | W5: Хомуты | X5: Отверстия | Y5: Допник | AA5: Край | AB5: С-1 | AC5: Л1 | AD5: Л2 | AE5: Площадка | AF5: Рама | AG5: Итого: | AH5: Масса ед. кг | AI5: Всего | AJ5: Итого: | AK5: Масса ед. кг | AL5: Всего | AM5: Итого: | AN5: Масса ед. кг | AO5: Всего | AP5: Итого: | AQ5: Масса ед. кг | AR5: Всего
A6: (1 этаж) | B6: Дм-1 | C6: Дм-2 | D6: К 1-1 (3) | E6: Ригель 4-4 | F6: К 1-1 (5) | G6: Ригель 4-4 | H6: К 1-1 (5) | I6: Ригель 4-4 | J6: К 1-1 (2) | K6: Дм-3 | L6: Дм-4 | M6: Дм-5 | N6: Ригель 4-4 | O6: Ригель 5-5 (×2) | P6: Ригель 5-5 | Q6: Ригель 5-5 | R6: Ригель 5-5 | U6: Ø18 L=1200 | W6: Ф-1, шп. | Y6: Низ | Z6: Верх | AA6: сеч.6-6 | AB6: 240 шт | AC6: марш 1 | AD6: марш 2 | AE6: отм. 1.920 | AF6: Лрм-1 | AG6: (м.п.) | AI6: кг | AJ6: (м.п.) | AL6: кг | AM6: (м.п.) | AO6: кг | AP6: (м.п.) | AR6: кг
A7: Арматура, (м.п.)
A8: Диаметр 32 А500С, L=м.п. | B8: =SUMIFS(Ведомость!$N$5:$N$846,Ведомость!$H$5:$H$846,32,Ведомость!$I$5:$I$846,"А500С",Ведомость!$V$5:$V$846,"Дм-1",Ведомость!$W$5:$W$846,1) -> 16 | C8: =SUMIFS(Ведомость!$N$5:$N$846,Ведомость!$H$5:$H$846,32,Ведомость!$I$5:$I$846,"А500С",Ведомость!$V$5:$V$846,"Дм-2",Ведомость!$W$5:$W$846,1) -> 16 | D8: =SUMIFS(Ведомость!$N$5:$N$846,Ведомость!$H$5:$H$846,32,Ведомость!$I$5:$I$846,"А500С",Ведомость!$V$5:$V$846,"К-А",Ведомость!$W$5:$W$846,1) -> 48 | E8: =SUMIFS(Ведомость!$N$5:$N$846,Ведомость!$H$5:$H$846,32,Ведомость!$I$5:$I$846,"А500С",Ведомость!$V$5:$V$846,"Р-А",Ведомость!$W$5:$W$846,1) -> 6.6 | F8: =SUMIFS(Ведомость!$N$5:$N$846,Ведомость!$H$5:$H$846,32,Ведомость!$I$5:$I$846,"А500С",Ведомость!$V$5:$V$846,"К-Б",Ведомость!$W$5:$W$846,1) -> 80 | G8: =SUMIFS(Ведомость!$N$5:$N$846,Ведомость!$H$5:$H$846,32,Ведомость!$I$5:$I$846,"А500С",Ведомость!$V$5:$V$846,"Р-Б",Ведомость!$W$5:$W$846,1) -> 7.4 | H8: =SUMIFS(Ведомость!$N$5:$N$846,Ведомость!$H$5:$H$846,32,Ведомость!$I$5:$I$846,"А500С",Ведомость!$V$5:$V$846,"К-В",Ведомость!$W$5:$W$846,1) -> 80 | I8: =SUMIFS(Ведомость!$N$5:$N$846,Ведомость!$H$5:$H$846,32,Ведомость!$I$5:$I$846,"А500С",Ведомость!$V$5:$V$846,"Р-В",Ведомость!$W$5:$W$846,1) -> 14.8 | J8: =SUMIFS(Ведомость!$N$5:$N$846,Ведомость!$H$5:$H$846,32,Ведомость!$I$5:$I$846,"А500С",Ведомость!$V$5:$V$846,"К-Г",Ведомость!$W$5:$W$846,1) -> 32 | K8: =SUMIFS(Ведомость!$N$5:$N$846,Ведомость!$H$5:$H$846,32,Ведомость!$I$5:$I$846,"А500С",Ведомость!$V$5:$V$846,"Дм-3",Ведомость!$W$5:$W$846,1) -> 16 | L8: =SUMIFS(Ведомость!$N$5:$N$846,Ведомость!$H$5:$H$846,32,Ведомость!$I$5:$I$846,"А500С",Ведомость!$V$5:$V$846,"Дм-4",Ведомость!$W$5:$W$846,1) -> 16 | M8: =SUMIFS(Ведомость!$N$5:$N$846,Ведомость!$H$5:$H$846,32,Ведомость!$I$5:$I$846,"А500С",Ведомость!$V$5:$V$846,"Дм-5",Ведомость!$W$5:$W$846,1) -> 16 | N8: =SUMIFS(Ведомость!$N$5:$N$846,Ведомость!$H$5:$H$846,32,Ведомость!$I$5:$I$846,"А500С",Ведомость!$V$5:$V$846,"Р-Г",Ведомость!$W$5:$W$846,1) -> 8.6 | O8: =SUMIFS(Ведомость!$N$5:$N$846,Ведомость!$H$5:$H$846,32,Ведомость!$I$5:$I$846,"А500С",Ведомость!$V$5:$V$846,"Р-1, 5",Ведомость!$W$5:$W$846,1) -> 15.2 | P8: =SUMIFS(Ведомость!$N$5:$N$846,Ведомость!$H$5:$H$846,32,Ведомость!$I$5:$I$846,"А500С",Ведомость!$V$5:$V$846,"Р-2",Ведомость!$W$5:$W$846,1) -> 27.9 | Q8: =SUMIFS(Ведомость!$N$5:$N$846,Ведомость!$H$5:$H$846,32,Ведомость!$I$5:$I$846,"А500С",Ведомость!$V$5:$V$846,"Р-3",Ведомость!$W$5:$W$846,1) -> 4.1 | R8: =SUMIFS(Ведомость!$N$5:$N$846,Ведомость!$H$5:$H$846,32,Ведомость!$I$5:$I$846,"А500С",Ведомость!$V$5:$V$846,"Р-4",Ведомость!$W$5:$W$846,1) -> 17.3 | S8: =SUMIFS(Ведомость!$N$5:$N$846,Ведомость!$H$5:$H$846,32,Ведомость!$I$5:$I$846,"А500С",Ведомость!$V$5:$V$846,"Б-основная",Ведомость!$W$5:$W$846,1) -> 0 | T8: =SUMIFS(Ведомость!$N$5:$N$846,Ведомость!$H$5:$H$846,32,Ведомость!$I$5:$I$846,"А500С",Ведомость!$V$5:$V$846,"Б-хомуты",Ведомость!$W$5:$W$846,1) -> 0 | U8: =SUMIFS(Ведомость!$N$5:$N$846,Ведомость!$H$5:$H$846,32,Ведомость!$I$5:$I$846,"А500С",Ведомость!$V$5:$V$846,"Б-допник",Ведомость!$W$5:$W$846,1) -> 0 | V8: =SUMIFS(Ведомость!$N$5:$N$846,Ведомость!$H$5:$H$846,32,Ведомость!$I$5:$I$846,"А500С",Ведомость!$V$5:$V$846,"П-сетка",Ведомость!$W$5:$W$846,1) -> 0 | W8: =SUMIFS(Ведомость!$N$5:$N$846,Ведомость!$H$5:$H$846,32,Ведомость!$I$5:$I$846,"А500С",Ведомость!$V$5:$V$846,"П-фикс",Ведомость!$W$5:$W$846,1) -> 0 | X8: =SUMIFS(Ведомость!$N$5:$N$846,Ведомость!$H$5:$H$846,32,Ведомость!$I$5:$I$846,"А500С",Ведомость!$V$5:$V$846,"П-отв",Ведомость!$W$5:$W$846,1) -> 0 | Y8: =SUMIFS(Ведомость!$N$5:$N$846,Ведомость!$H$5:$H$846,32,Ведомость!$I$5:$I$846,"А500С",Ведомость!$V$5:$V$846,"П-доп-низ",Ведомость!$W$5:$W$846,1) -> 0 | Z8: =SUMIFS(Ведомость!$N$5:$N$846,Ведомость!$H$5:$H$846,32,Ведомость!$I$5:$I$846,"А500С",Ведомость!$V$5:$V$846,"П-доп-верх",Ведомость!$W$5:$W$846,1) -> 0 | AA8: =SUMIFS(Ведомость!$N$5:$N$846,Ведомость!$H$5:$H$846,32,Ведомость!$I$5:$I$846,"А500С",Ведомость!$V$5:$V$846,"П-край",Ведомость!$W$5:$W$846,1) -> 0 | AB8: =SUMIFS(Ведомость!$N$5:$N$846,Ведомость!$H$5:$H$846,32,Ведомость!$I$5:$I$846,"А500С",Ведомость!$V$5:$V$846,"С-1",Ведомость!$W$5:$W$846,1) -> 0 | AC8: =SUMIFS(Ведомость!$N$5:$N$846,Ведомость!$H$5:$H$846,32,Ведомость!$I$5:$I$846,"А500С",Ведомость!$V$5:$V$846,"Л1",Ведомость!$W$5:$W$846,1) -> 0 | AD8: =SUMIFS(Ведомость!$N$5:$N$846,Ведомость!$H$5:$H$846,32,Ведомость!$I$5:$I$846,"А500С",Ведомость!$V$5:$V$846,"Л2",Ведомость!$W$5:$W$846,1) -> 0 | AE8: =SUMIFS(Ведомость!$N$5:$N$846,Ведомость!$H$5:$H$846,32,Ведомость!$I$5:$I$846,"А500С",Ведомость!$V$5:$V$846,"Л-пл",Ведомость!$W$5:$W$846,1) -> 0 | AF8: =SUMIFS(Ведомость!$N$5:$N$846,Ведомость!$H$5:$H$846,32,Ведомость!$I$5:$I$846,"А500С",Ведомость!$V$5:$V$846,"Л-рама",Ведомость!$W$5:$W$846,1) -> 0 | AG8: =SUM(B8:AF8) -> 421.9 | AH8: =IFERROR(INDEX(Исходные!$B$18:$B$30,MATCH(32,Исходные!$A$18:$A$30,0)),0) -> 6.313 | AI8: =AG8*AH8*$AJ$2 -> 2849.8965 | AJ8: =SUM(B8:D8,F8,H8,J8:M8) -> 320 | AK8: =AH8 -> 6.313 | AL8: =AJ8*AK8*$AJ$2 -> 2161.5712 | AM8: =SUM(E8,G8,I8,N8:AB8) -> 101.9 | AN8: =AH8 -> 6.313 | AO8: =AM8*AN8*$AJ$2 -> 688.32533 | AP8: =SUM(AC8:AF8) -> 0 | AQ8: =AH8 -> 6.313 | AR8: =AP8*AQ8*$AJ$2 -> 0
A9: Диаметр 28 А500С, L=м.п. | B9: =SUMIFS(Ведомость!$N$5:$N$846,Ведомость!$H$5:$H$846,28,Ведомость!$I$5:$I$846,"А500С",Ведомость!$V$5:$V$846,"Дм-1",Ведомость!$W$5:$W$846,1) -> 128 | C9: =SUMIFS(Ведомость!$N$5:$N$846,Ведомость!$H$5:$H$846,28,Ведомость!$I$5:$I$846,"А500С",Ведомость!$V$5:$V$846,"Дм-2",Ведомость!$W$5:$W$846,1) -> 88 | D9: =SUMIFS(Ведомость!$N$5:$N$846,Ведомость!$H$5:$H$846,28,Ведомость!$I$5:$I$846,"А500С",Ведомость!$V$5:$V$846,"К-А",Ведомость!$W$5:$W$846,1) -> 0 | E9: =SUMIFS(Ведомость!$N$5:$N$846,Ведомость!$H$5:$H$846,28,Ведомость!$I$5:$I$846,"А500С",Ведомость!$V$5:$V$846,"Р-А",Ведомость!$W$5:$W$846,1) -> 121.8 | F9: =SUMIFS(Ведомость!$N$5:$N$846,Ведомость!$H$5:$H$846,28,Ведомость!$I$5:$I$846,"А500С",Ведомость!$V$5:$V$846,"К-Б",Ведомость!$W$5:$W$846,1) -> 0 | G9: =SUMIFS(Ведомость!$N$5:$N$846,Ведомость!$H$5:$H$846,28,Ведомость!$I$5:$I$846,"А500С",Ведомость!$V$5:$V$846,"Р-Б",Ведомость!$W$5:$W$846,1) -> 116.6 | H9: =SUMIFS(Ведомость!$N$5:$N$846,Ведомость!$H$5:$H$846,28,Ведомость!$I$5:$I$846,"А500С",Ведомость!$V$5:$V$846,"К-В",Ведомость!$W$5:$W$846,1) -> 0 | I9: =SUMIFS(Ведомость!$N$5:$N$846,Ведомость!$H$5:$H$846,28,Ведомость!$I$5:$I$846,"А500С",Ведомость!$V$5:$V$846,"Р-В",Ведомость!$W$5:$W$846,1) -> 113.3 | J9: =SUMIFS(Ведомость!$N$5:$N$846,Ведомость!$H$5:$H$846,28,Ведомость!$I$5:$I$846,"А500С",Ведомость!$V$5:$V$846,"К-Г",Ведомость!$W$5:$W$846,1) -> 0 | K9: =SUMIFS(Ведомость!$N$5:$N$846,Ведомость!$H$5:$H$846,28,Ведомость!$I$5:$I$846,"А500С",Ведомость!$V$5:$V$846,"Дм-3",Ведомость!$W$5:$W$846,1) -> 88 | L9: =SUMIFS(Ведомость!$N$5:$N$846,Ведомость!$H$5:$H$846,28,Ведомость!$I$5:$I$846,"А500С",Ведомость!$V$5:$V$846,"Дм-4",Ведомость!$W$5:$W$846,1) -> 56 | M9: =SUMIFS(Ведомость!$N$5:$N$846,Ведомость!$H$5:$H$846,28,Ведомость!$I$5:$I$846,"А500С",Ведомость!$V$5:$V$846,"Дм-5",Ведомость!$W$5:$W$846,1) -> 56 | N9: =SUMIFS(Ведомость!$N$5:$N$846,Ведомость!$H$5:$H$846,28,Ведомость!$I$5:$I$846,"А500С",Ведомость!$V$5:$V$846,"Р-Г",Ведомость!$W$5:$W$846,1) -> 144.1 | O9: =SUMIFS(Ведомость!$N$5:$N$846,Ведомость!$H$5:$H$846,28,Ведомость!$I$5:$I$846,"А500С",Ведомость!$V$5:$V$846,"Р-1, 5",Ведомость!$W$5:$W$846,1) -> 187.4 | P9: =SUMIFS(Ведомость!$N$5:$N$846,Ведомость!$H$5:$H$846,28,Ведомость!$I$5:$I$846,"А500С",Ведомость!$V$5:$V$846,"Р-2",Ведомость!$W$5:$W$846,1) -> 82 | Q9: =SUMIFS(Ведомость!$N$5:$N$846,Ведомость!$H$5:$H$846,28,Ведомость!$I$5:$I$846,"А500С",Ведомость!$V$5:$V$846,"Р-3",Ведомость!$W$5:$W$846,1) -> 99.7 | R9: =SUMIFS(Ведомость!$N$5:$N$846,Ведомость!$H$5:$H$846,28,Ведомость!$I$5:$I$846,"А500С",Ведомость!$V$5:$V$846,"Р-4",Ведомость!$W$5:$W$846,1) -> 89.2 | S9: =SUMIFS(Ведомость!$N$5:$N$846,Ведомость!$H$5:$H$846,28,Ведомость!$I$5:$I$846,"А500С",Ведомость!$V$5:$V$846,"Б-основная",Ведомость!$W$5:$W$846,1) -> 0 | T9: =SUMIFS(Ведомость!$N$5:$N$846,Ведомость!$H$5:$H$846,28,Ведомость!$I$5:$I$846,"А500С",Ведомость!$V$5:$V$846,"Б-хомуты",Ведомость!$W$5:$W$846,1) -> 0 | U9: =SUMIFS(Ведомость!$N$5:$N$846,Ведомость!$H$5:$H$846,28,Ведомость!$I$5:$I$846,"А500С",Ведомость!$V$5:$V$846,"Б-допник",Ведомость!$W$5:$W$846,1) -> 0 | V9: =SUMIFS(Ведомость!$N$5:$N$846,Ведомость!$H$5:$H$846,28,Ведомость!$I$5:$I$846,"А500С",Ведомость!$V$5:$V$846,"П-сетка",Ведомость!$W$5:$W$846,1) -> 0 | W9: =SUMIFS(Ведомость!$N$5:$N$846,Ведомость!$H$5:$H$846,28,Ведомость!$I$5:$I$846,"А500С",Ведомость!$V$5:$V$846,"П-фикс",Ведомость!$W$5:$W$846,1) -> 0 | X9: =SUMIFS(Ведомость!$N$5:$N$846,Ведомость!$H$5:$H$846,28,Ведомость!$I$5:$I$846,"А500С",Ведомость!$V$5:$V$846,"П-отв",Ведомость!$W$5:$W$846,1) -> 0 | Y9: =SUMIFS(Ведомость!$N$5:$N$846,Ведомость!$H$5:$H$846,28,Ведомость!$I$5:$I$846,"А500С",Ведомость!$V$5:$V$846,"П-доп-низ",Ведомость!$W$5:$W$846,1) -> 0 | Z9: =SUMIFS(Ведомость!$N$5:$N$846,Ведомость!$H$5:$H$846,28,Ведомость!$I$5:$I$846,"А500С",Ведомость!$V$5:$V$846,"П-доп-верх",Ведомость!$W$5:$W$846,1) -> 0 | AA9: =SUMIFS(Ведомость!$N$5:$N$846,Ведомость!$H$5:$H$846,28,Ведомость!$I$5:$I$846,"А500С",Ведомость!$V$5:$V$846,"П-край",Ведомость!$W$5:$W$846,1) -> 0 | AB9: =SUMIFS(Ведомость!$N$5:$N$846,Ведомость!$H$5:$H$846,28,Ведомость!$I$5:$I$846,"А500С",Ведомость!$V$5:$V$846,"С-1",Ведомость!$W$5:$W$846,1) -> 0 | AC9: =SUMIFS(Ведомость!$N$5:$N$846,Ведомость!$H$5:$H$846,28,Ведомость!$I$5:$I$846,"А500С",Ведомость!$V$5:$V$846,"Л1",Ведомость!$W$5:$W$846,1) -> 0 | AD9: =SUMIFS(Ведомость!$N$5:$N$846,Ведомость!$H$5:$H$846,28,Ведомость!$I$5:$I$846,"А500С",Ведомость!$V$5:$V$846,"Л2",Ведомость!$W$5:$W$846,1) -> 0 | AE9: =SUMIFS(Ведомость!$N$5:$N$846,Ведомость!$H$5:$H$846,28,Ведомость!$I$5:$I$846,"А500С",Ведомость!$V$5:$V$846,"Л-пл",Ведомость!$W$5:$W$846,1) -> 0 | AF9: =SUMIFS(Ведомость!$N$5:$N$846,Ведомость!$H$5:$H$846,28,Ведомость!$I$5:$I$846,"А500С",Ведомость!$V$5:$V$846,"Л-рама",Ведомость!$W$5:$W$846,1) -> 0 | AG9: =SUM(B9:AF9) -> 1370.1 | AH9: =IFERROR(INDEX(Исходные!$B$18:$B$30,MATCH(28,Исходные!$A$18:$A$30,0)),0) -> 4.834 | AI9: =AG9*AH9*$AJ$2 -> 7086.6778 | AJ9: =SUM(B9:D9,F9,H9,J9:M9) -> 416 | AK9: =AH9 -> 4.834 | AL9: =AJ9*AK9*$AJ$2 -> 2151.7101 | AM9: =SUM(E9,G9,I9,N9:AB9) -> 954.1 | AN9: =AH9 -> 4.834 | AO9: =AM9*AN9*$AJ$2 -> 4934.9678 | AP9: =SUM(AC9:AF9) -> 0 | AQ9: =AH9 -> 4.834 | AR9: =AP9*AQ9*$AJ$2 -> 0
A10: Диаметр 25 А500С, L=м.п. | B10: =SUMIFS(Ведомость!$N$5:$N$846,Ведомость!$H$5:$H$846,25,Ведомость!$I$5:$I$846,"А500С",Ведомость!$V$5:$V$846,"Дм-1",Ведомость!$W$5:$W$846,1) -> 32 | C10: =SUMIFS(Ведомость!$N$5:$N$846,Ведомость!$H$5:$H$846,25,Ведомость!$I$5:$I$846,"А500С",Ведомость!$V$5:$V$846,"Дм-2",Ведомость!$W$5:$W$846,1) -> 32 | D10: =SUMIFS(Ведомость!$N$5:$N$846,Ведомость!$H$5:$H$846,25,Ведомость!$I$5:$I$846,"А500С",Ведомость!$V$5:$V$846,"К-А",Ведомость!$W$5:$W$846,1) -> 0 | E10: =SUMIFS(Ведомость!$N$5:$N$846,Ведомость!$H$5:$H$846,25,Ведомость!$I$5:$I$846,"А500С",Ведомость!$V$5:$V$846,"Р-А",Ведомость!$W$5:$W$846,1) -> 40.4 | F10: =SUMIFS(Ведомость!$N$5:$N$846,Ведомость!$H$5:$H$846,25,Ведомость!$I$5:$I$846,"А500С",Ведомость!$V$5:$V$846,"К-Б",Ведомость!$W$5:$W$846,1) -> 0 | G10: =SUMIFS(Ведомость!$N$5:$N$846,Ведомость!$H$5:$H$846,25,Ведомость!$I$5:$I$846,"А500С",Ведомость!$V$5:$V$846,"Р-Б",Ведомость!$W$5:$W$846,1) -> 8.2 | H10: =SUMIFS(Ведомость!$N$5:$N$846,Ведомость!$H$5:$H$846,25,Ведомость!$I$5:$I$846,"А500С",Ведомость!$V$5:$V$846,"К-В",Ведомость!$W$5:$W$846,1) -> 0 | I10: =SUMIFS(Ведомость!$N$5:$N$846,Ведомость!$H$5:$H$846,25,Ведомость!$I$5:$I$846,"А500С",Ведомость!$V$5:$V$846,"Р-В",Ведомость!$W$5:$W$846,1) -> 4.1 | J10: =SUMIFS(Ведомость!$N$5:$N$846,Ведомость!$H$5:$H$846,25,Ведомость!$I$5:$I$846,"А500С",Ведомость!$V$5:$V$846,"К-Г",Ведомость!$W$5:$W$846,1) -> 0 | K10: =SUMIFS(Ведомость!$N$5:$N$846,Ведомость!$H$5:$H$846,25,Ведомость!$I$5:$I$846,"А500С",Ведомость!$V$5:$V$846,"Дм-3",Ведомость!$W$5:$W$846,1) -> 40 | L10: =SUMIFS(Ведомость!$N$5:$N$846,Ведомость!$H$5:$H$846,25,Ведомость!$I$5:$I$846,"А500С",Ведомость!$V$5:$V$846,"Дм-4",Ведомость!$W$5:$W$846,1) -> 0 | M10: =SUMIFS(Ведомость!$N$5:$N$846,Ведомость!$H$5:$H$846,25,Ведомость!$I$5:$I$846,"А500С",Ведомость!$V$5:$V$846,"Дм-5",Ведомость!$W$5:$W$846,1) -> 40 | N10: =SUMIFS(Ведомость!$N$5:$N$846,Ведомость!$H$5:$H$846,25,Ведомость!$I$5:$I$846,"А500С",Ведомость!$V$5:$V$846,"Р-Г",Ведомость!$W$5:$W$846,1) -> 4.1 | O10: =SUMIFS(Ведомость!$N$5:$N$846,Ведомость!$H$5:$H$846,25,Ведомость!$I$5:$I$846,"А500С",Ведомость!$V$5:$V$846,"Р-1, 5",Ведомость!$W$5:$W$846,1) -> 8.2 | P10: =SUMIFS(Ведомость!$N$5:$N$846,Ведомость!$H$5:$H$846,25,Ведомость!$I$5:$I$846,"А500С",Ведомость!$V$5:$V$846,"Р-2",Ведомость!$W$5:$W$846,1) -> 21 | Q10: =SUMIFS(Ведомость!$N$5:$N$846,Ведомость!$H$5:$H$846,25,Ведомость!$I$5:$I$846,"А500С",Ведомость!$V$5:$V$846,"Р-3",Ведомость!$W$5:$W$846,1) -> 22.8 | R10: =SUMIFS(Ведомость!$N$5:$N$846,Ведомость!$H$5:$H$846,25,Ведомость!$I$5:$I$846,"А500С",Ведомость!$V$5:$V$846,"Р-4",Ведомость!$W$5:$W$846,1) -> 12.4 | S10: =SUMIFS(Ведомость!$N$5:$N$846,Ведомость!$H$5:$H$846,25,Ведомость!$I$5:$I$846,"А500С",Ведомость!$V$5:$V$846,"Б-основная",Ведомость!$W$5:$W$846,1) -> 635.4 | T10: =SUMIFS(Ведомость!$N$5:$N$846,Ведомость!$H$5:$H$846,25,Ведомость!$I$5:$I$846,"А500С",Ведомость!$V$5:$V$846,"Б-хомуты",Ведомость!$W$5:$W$846,1) -> 0 | U10: =SUMIFS(Ведомость!$N$5:$N$846,Ведомость!$H$5:$H$846,25,Ведомость!$I$5:$I$846,"А500С",Ведомость!$V$5:$V$846,"Б-допник",Ведомость!$W$5:$W$846,1) -> 0 | V10: =SUMIFS(Ведомость!$N$5:$N$846,Ведомость!$H$5:$H$846,25,Ведомость!$I$5:$I$846,"А500С",Ведомость!$V$5:$V$846,"П-сетка",Ведомость!$W$5:$W$846,1) -> 0 | W10: =SUMIFS(Ведомость!$N$5:$N$846,Ведомость!$H$5:$H$846,25,Ведомость!$I$5:$I$846,"А500С",Ведомость!$V$5:$V$846,"П-фикс",Ведомость!$W$5:$W$846,1) -> 0 | X10: =SUMIFS(Ведомость!$N$5:$N$846,Ведомость!$H$5:$H$846,25,Ведомость!$I$5:$I$846,"А500С",Ведомость!$V$5:$V$846,"П-отв",Ведомость!$W$5:$W$846,1) -> 0 | Y10: =SUMIFS(Ведомость!$N$5:$N$846,Ведомость!$H$5:$H$846,25,Ведомость!$I$5:$I$846,"А500С",Ведомость!$V$5:$V$846,"П-доп-низ",Ведомость!$W$5:$W$846,1) -> 0 | Z10: =SUMIFS(Ведомость!$N$5:$N$846,Ведомость!$H$5:$H$846,25,Ведомость!$I$5:$I$846,"А500С",Ведомость!$V$5:$V$846,"П-доп-верх",Ведомость!$W$5:$W$846,1) -> 0 | AA10: =SUMIFS(Ведомость!$N$5:$N$846,Ведомость!$H$5:$H$846,25,Ведомость!$I$5:$I$846,"А500С",Ведомость!$V$5:$V$846,"П-край",Ведомость!$W$5:$W$846,1) -> 0 | AB10: =SUMIFS(Ведомость!$N$5:$N$846,Ведомость!$H$5:$H$846,25,Ведомость!$I$5:$I$846,"А500С",Ведомость!$V$5:$V$846,"С-1",Ведомость!$W$5:$W$846,1) -> 0 | AC10: =SUMIFS(Ведомость!$N$5:$N$846,Ведомость!$H$5:$H$846,25,Ведомость!$I$5:$I$846,"А500С",Ведомость!$V$5:$V$846,"Л1",Ведомость!$W$5:$W$846,1) -> 0 | AD10: =SUMIFS(Ведомость!$N$5:$N$846,Ведомость!$H$5:$H$846,25,Ведомость!$I$5:$I$846,"А500С",Ведомость!$V$5:$V$846,"Л2",Ведомость!$W$5:$W$846,1) -> 0 | AE10: =SUMIFS(Ведомость!$N$5:$N$846,Ведомость!$H$5:$H$846,25,Ведомость!$I$5:$I$846,"А500С",Ведомость!$V$5:$V$846,"Л-пл",Ведомость!$W$5:$W$846,1) -> 0 | AF10: =SUMIFS(Ведомость!$N$5:$N$846,Ведомость!$H$5:$H$846,25,Ведомость!$I$5:$I$846,"А500С",Ведомость!$V$5:$V$846,"Л-рама",Ведомость!$W$5:$W$846,1) -> 21.38 | AG10: =SUM(B10:AF10) -> 921.98 | AH10: =IFERROR(INDEX(Исходные!$B$18:$B$30,MATCH(25,Исходные!$A$18:$A$30,0)),0) -> 3.853 | AI10: =AG10*AH10*$AJ$2 -> 3801.0562 | AJ10: =SUM(B10:D10,F10,H10,J10:M10) -> 144 | AK10: =AH10 -> 3.853 | AL10: =AJ10*AK10*$AJ$2 -> 593.67024 | AM10: =SUM(E10,G10,I10,N10:AB10) -> 756.6 | AN10: =AH10 -> 3.853 | AO10: =AM10*AN10*$AJ$2 -> 3119.2424 | AP10: =SUM(AC10:AF10) -> 21.38 | AQ10: =AH10 -> 3.853 | AR10: =AP10*AQ10*$AJ$2 -> 88.14354
A11: Диаметр 22 А500С, L=м.п. | B11: =SUMIFS(Ведомость!$N$5:$N$846,Ведомость!$H$5:$H$846,22,Ведомость!$I$5:$I$846,"А500С",Ведомость!$V$5:$V$846,"Дм-1",Ведомость!$W$5:$W$846,1) -> 0 | C11: =SUMIFS(Ведомость!$N$5:$N$846,Ведомость!$H$5:$H$846,22,Ведомость!$I$5:$I$846,"А500С",Ведомость!$V$5:$V$846,"Дм-2",Ведомость!$W$5:$W$846,1) -> 64 | D11: =SUMIFS(Ведомость!$N$5:$N$846,Ведомость!$H$5:$H$846,22,Ведомость!$I$5:$I$846,"А500С",Ведомость!$V$5:$V$846,"К-А",Ведомость!$W$5:$W$846,1) -> 0 | E11: =SUMIFS(Ведомость!$N$5:$N$846,Ведомость!$H$5:$H$846,22,Ведомость!$I$5:$I$846,"А500С",Ведомость!$V$5:$V$846,"Р-А",Ведомость!$W$5:$W$846,1) -> 9 | F11: =SUMIFS(Ведомость!$N$5:$N$846,Ведомость!$H$5:$H$846,22,Ведомость!$I$5:$I$846,"А500С",Ведомость!$V$5:$V$846,"К-Б",Ведомость!$W$5:$W$846,1) -> 0 | G11: =SUMIFS(Ведомость!$N$5:$N$846,Ведомость!$H$5:$H$846,22,Ведомость!$I$5:$I$846,"А500С",Ведомость!$V$5:$V$846,"Р-Б",Ведомость!$W$5:$W$846,1) -> 6.4 | H11: =SUMIFS(Ведомость!$N$5:$N$846,Ведомость!$H$5:$H$846,22,Ведомость!$I$5:$I$846,"А500С",Ведомость!$V$5:$V$846,"К-В",Ведомость!$W$5:$W$846,1) -> 0 | I11: =SUMIFS(Ведомость!$N$5:$N$846,Ведомость!$H$5:$H$846,22,Ведомость!$I$5:$I$846,"А500С",Ведомость!$V$5:$V$846,"Р-В",Ведомость!$W$5:$W$846,1) -> 6.4 | J11: =SUMIFS(Ведомость!$N$5:$N$846,Ведомость!$H$5:$H$846,22,Ведомость!$I$5:$I$846,"А500С",Ведомость!$V$5:$V$846,"К-Г",Ведомость!$W$5:$W$846,1) -> 0 | K11: =SUMIFS(Ведомость!$N$5:$N$846,Ведомость!$H$5:$H$846,22,Ведомость!$I$5:$I$846,"А500С",Ведомость!$V$5:$V$846,"Дм-3",Ведомость!$W$5:$W$846,1) -> 69 | L11: =SUMIFS(Ведомость!$N$5:$N$846,Ведомость!$H$5:$H$846,22,Ведомость!$I$5:$I$846,"А500С",Ведомость!$V$5:$V$846,"Дм-4",Ведомость!$W$5:$W$846,1) -> 0 | M11: =SUMIFS(Ведомость!$N$5:$N$846,Ведомость!$H$5:$H$846,22,Ведомость!$I$5:$I$846,"А500С",Ведомость!$V$5:$V$846,"Дм-5",Ведомость!$W$5:$W$846,1) -> 24 | N11: =SUMIFS(Ведомость!$N$5:$N$846,Ведомость!$H$5:$H$846,22,Ведомость!$I$5:$I$846,"А500С",Ведомость!$V$5:$V$846,"Р-Г",Ведомость!$W$5:$W$846,1) -> 35.5 | O11: =SUMIFS(Ведомость!$N$5:$N$846,Ведомость!$H$5:$H$846,22,Ведомость!$I$5:$I$846,"А500С",Ведомость!$V$5:$V$846,"Р-1, 5",Ведомость!$W$5:$W$846,1) -> 0 | P11: =SUMIFS(Ведомость!$N$5:$N$846,Ведомость!$H$5:$H$846,22,Ведомость!$I$5:$I$846,"А500С",Ведомость!$V$5:$V$846,"Р-2",Ведомость!$W$5:$W$846,1) -> 0 | Q11: =SUMIFS(Ведомость!$N$5:$N$846,Ведомость!$H$5:$H$846,22,Ведомость!$I$5:$I$846,"А500С",Ведомость!$V$5:$V$846,"Р-3",Ведомость!$W$5:$W$846,1) -> 0 | R11: =SUMIFS(Ведомость!$N$5:$N$846,Ведомость!$H$5:$H$846,22,Ведомость!$I$5:$I$846,"А500С",Ведомость!$V$5:$V$846,"Р-4",Ведомость!$W$5:$W$846,1) -> 0 | S11: =SUMIFS(Ведомость!$N$5:$N$846,Ведомость!$H$5:$H$846,22,Ведомость!$I$5:$I$846,"А500С",Ведомость!$V$5:$V$846,"Б-основная",Ведомость!$W$5:$W$846,1) -> 158.8 | T11: =SUMIFS(Ведомость!$N$5:$N$846,Ведомость!$H$5:$H$846,22,Ведомость!$I$5:$I$846,"А500С",Ведомость!$V$5:$V$846,"Б-хомуты",Ведомость!$W$5:$W$846,1) -> 0 | U11: =SUMIFS(Ведомость!$N$5:$N$846,Ведомость!$H$5:$H$846,22,Ведомость!$I$5:$I$846,"А500С",Ведомость!$V$5:$V$846,"Б-допник",Ведомость!$W$5:$W$846,1) -> 0 | V11: =SUMIFS(Ведомость!$N$5:$N$846,Ведомость!$H$5:$H$846,22,Ведомость!$I$5:$I$846,"А500С",Ведомость!$V$5:$V$846,"П-сетка",Ведомость!$W$5:$W$846,1) -> 0 | W11: =SUMIFS(Ведомость!$N$5:$N$846,Ведомость!$H$5:$H$846,22,Ведомость!$I$5:$I$846,"А500С",Ведомость!$V$5:$V$846,"П-фикс",Ведомость!$W$5:$W$846,1) -> 0 | X11: =SUMIFS(Ведомость!$N$5:$N$846,Ведомость!$H$5:$H$846,22,Ведомость!$I$5:$I$846,"А500С",Ведомость!$V$5:$V$846,"П-отв",Ведомость!$W$5:$W$846,1) -> 0 | Y11: =SUMIFS(Ведомость!$N$5:$N$846,Ведомость!$H$5:$H$846,22,Ведомость!$I$5:$I$846,"А500С",Ведомость!$V$5:$V$846,"П-доп-низ",Ведомость!$W$5:$W$846,1) -> 0 | Z11: =SUMIFS(Ведомость!$N$5:$N$846,Ведомость!$H$5:$H$846,22,Ведомость!$I$5:$I$846,"А500С",Ведомость!$V$5:$V$846,"П-доп-верх",Ведомость!$W$5:$W$846,1) -> 0 | AA11: =SUMIFS(Ведомость!$N$5:$N$846,Ведомость!$H$5:$H$846,22,Ведомость!$I$5:$I$846,"А500С",Ведомость!$V$5:$V$846,"П-край",Ведомость!$W$5:$W$846,1) -> 0 | AB11: =SUMIFS(Ведомость!$N$5:$N$846,Ведомость!$H$5:$H$846,22,Ведомость!$I$5:$I$846,"А500С",Ведомость!$V$5:$V$846,"С-1",Ведомость!$W$5:$W$846,1) -> 0 | AC11: =SUMIFS(Ведомость!$N$5:$N$846,Ведомость!$H$5:$H$846,22,Ведомость!$I$5:$I$846,"А500С",Ведомость!$V$5:$V$846,"Л1",Ведомость!$W$5:$W$846,1) -> 0 | AD11: =SUMIFS(Ведомость!$N$5:$N$846,Ведомость!$H$5:$H$846,22,Ведомость!$I$5:$I$846,"А500С",Ведомость!$V$5:$V$846,"Л2",Ведомость!$W$5:$W$846,1) -> 0 | AE11: =SUMIFS(Ведомость!$N$5:$N$846,Ведомость!$H$5:$H$846,22,Ведомость!$I$5:$I$846,"А500С",Ведомость!$V$5:$V$846,"Л-пл",Ведомость!$W$5:$W$846,1) -> 0 | AF11: =SUMIFS(Ведомость!$N$5:$N$846,Ведомость!$H$5:$H$846,22,Ведомость!$I$5:$I$846,"А500С",Ведомость!$V$5:$V$846,"Л-рама",Ведомость!$W$5:$W$846,1) -> 0 | AG11: =SUM(B11:AF11) -> 373.1 | AH11: =IFERROR(INDEX(Исходные!$B$18:$B$30,MATCH(22,Исходные!$A$18:$A$30,0)),0) -> 2.984 | AI11: =AG11*AH11*$AJ$2 -> 1191.2635 | AJ11: =SUM(B11:D11,F11,H11,J11:M11) -> 157 | AK11: =AH11 -> 2.984 | AL11: =AJ11*AK11*$AJ$2 -> 501.28216 | AM11: =SUM(E11,G11,I11,N11:AB11) -> 216.1 | AN11: =AH11 -> 2.984 | AO11: =AM11*AN11*$AJ$2 -> 689.98137 | AP11: =SUM(AC11:AF11) -> 0 | AQ11: =AH11 -> 2.984 | AR11: =AP11*AQ11*$AJ$2 -> 0
A12: Диаметр 20 А500С, L=м.п. | B12: =SUMIFS(Ведомость!$N$5:$N$846,Ведомость!$H$5:$H$846,20,Ведомость!$I$5:$I$846,"А500С",Ведомость!$V$5:$V$846,"Дм-1",Ведомость!$W$5:$W$846,1) -> 90.7 | C12: =SUMIFS(Ведомость!$N$5:$N$846,Ведомость!$H$5:$H$846,20,Ведомость!$I$5:$I$846,"А500С",Ведомость!$V$5:$V$846,"Дм-2",Ведомость!$W$5:$W$846,1) -> 28 | D12: =SUMIFS(Ведомость!$N$5:$N$846,Ведомость!$H$5:$H$846,20,Ведомость!$I$5:$I$846,"А500С",Ведомость!$V$5:$V$846,"К-А",Ведомость!$W$5:$W$846,1) -> 96 | E12: =SUMIFS(Ведомость!$N$5:$N$846,Ведомость!$H$5:$H$846,20,Ведомость!$I$5:$I$846,"А500С",Ведомость!$V$5:$V$846,"Р-А",Ведомость!$W$5:$W$846,1) -> 0 | F12: =SUMIFS(Ведомость!$N$5:$N$846,Ведомость!$H$5:$H$846,20,Ведомость!$I$5:$I$846,"А500С",Ведомость!$V$5:$V$846,"К-Б",Ведомость!$W$5:$W$846,1) -> 160 | G12: =SUMIFS(Ведомость!$N$5:$N$846,Ведомость!$H$5:$H$846,20,Ведомость!$I$5:$I$846,"А500С",Ведомость!$V$5:$V$846,"Р-Б",Ведомость!$W$5:$W$846,1) -> 0 | H12: =SUMIFS(Ведомость!$N$5:$N$846,Ведомость!$H$5:$H$846,20,Ведомость!$I$5:$I$846,"А500С",Ведомость!$V$5:$V$846,"К-В",Ведомость!$W$5:$W$846,1) -> 160 | I12: =SUMIFS(Ведомость!$N$5:$N$846,Ведомость!$H$5:$H$846,20,Ведомость!$I$5:$I$846,"А500С",Ведомость!$V$5:$V$846,"Р-В",Ведомость!$W$5:$W$846,1) -> 0 | J12: =SUMIFS(Ведомость!$N$5:$N$846,Ведомость!$H$5:$H$846,20,Ведомость!$I$5:$I$846,"А500С",Ведомость!$V$5:$V$846,"К-Г",Ведомость!$W$5:$W$846,1) -> 64 | K12: =SUMIFS(Ведомость!$N$5:$N$846,Ведомость!$H$5:$H$846,20,Ведомость!$I$5:$I$846,"А500С",Ведомость!$V$5:$V$846,"Дм-3",Ведомость!$W$5:$W$846,1) -> 32 | L12: =SUMIFS(Ведомость!$N$5:$N$846,Ведомость!$H$5:$H$846,20,Ведомость!$I$5:$I$846,"А500С",Ведомость!$V$5:$V$846,"Дм-4",Ведомость!$W$5:$W$846,1) -> 40 | M12: =SUMIFS(Ведомость!$N$5:$N$846,Ведомость!$H$5:$H$846,20,Ведомость!$I$5:$I$846,"А500С",Ведомость!$V$5:$V$846,"Дм-5",Ведомость!$W$5:$W$846,1) -> 32 | N12: =SUMIFS(Ведомость!$N$5:$N$846,Ведомость!$H$5:$H$846,20,Ведомость!$I$5:$I$846,"А500С",Ведомость!$V$5:$V$846,"Р-Г",Ведомость!$W$5:$W$846,1) -> 0 | O12: =SUMIFS(Ведомость!$N$5:$N$846,Ведомость!$H$5:$H$846,20,Ведомость!$I$5:$I$846,"А500С",Ведомость!$V$5:$V$846,"Р-1, 5",Ведомость!$W$5:$W$846,1) -> 0 | P12: =SUMIFS(Ведомость!$N$5:$N$846,Ведомость!$H$5:$H$846,20,Ведомость!$I$5:$I$846,"А500С",Ведомость!$V$5:$V$846,"Р-2",Ведомость!$W$5:$W$846,1) -> 8.1 | Q12: =SUMIFS(Ведомость!$N$5:$N$846,Ведомость!$H$5:$H$846,20,Ведомость!$I$5:$I$846,"А500С",Ведомость!$V$5:$V$846,"Р-3",Ведомость!$W$5:$W$846,1) -> 0 | R12: =SUMIFS(Ведомость!$N$5:$N$846,Ведомость!$H$5:$H$846,20,Ведомость!$I$5:$I$846,"А500С",Ведомость!$V$5:$V$846,"Р-4",Ведомость!$W$5:$W$846,1) -> 6 | S12: =SUMIFS(Ведомость!$N$5:$N$846,Ведомость!$H$5:$H$846,20,Ведомость!$I$5:$I$846,"А500С",Ведомость!$V$5:$V$846,"Б-основная",Ведомость!$W$5:$W$846,1) -> 57.04 | T12: =SUMIFS(Ведомость!$N$5:$N$846,Ведомость!$H$5:$H$846,20,Ведомость!$I$5:$I$846,"А500С",Ведомость!$V$5:$V$846,"Б-хомуты",Ведомость!$W$5:$W$846,1) -> 0 | U12: =SUMIFS(Ведомость!$N$5:$N$846,Ведомость!$H$5:$H$846,20,Ведомость!$I$5:$I$846,"А500С",Ведомость!$V$5:$V$846,"Б-допник",Ведомость!$W$5:$W$846,1) -> 0 | V12: =SUMIFS(Ведомость!$N$5:$N$846,Ведомость!$H$5:$H$846,20,Ведомость!$I$5:$I$846,"А500С",Ведомость!$V$5:$V$846,"П-сетка",Ведомость!$W$5:$W$846,1) -> 0 | W12: =SUMIFS(Ведомость!$N$5:$N$846,Ведомость!$H$5:$H$846,20,Ведомость!$I$5:$I$846,"А500С",Ведомость!$V$5:$V$846,"П-фикс",Ведомость!$W$5:$W$846,1) -> 0 | X12: =SUMIFS(Ведомость!$N$5:$N$846,Ведомость!$H$5:$H$846,20,Ведомость!$I$5:$I$846,"А500С",Ведомость!$V$5:$V$846,"П-отв",Ведомость!$W$5:$W$846,1) -> 0 | Y12: =SUMIFS(Ведомость!$N$5:$N$846,Ведомость!$H$5:$H$846,20,Ведомость!$I$5:$I$846,"А500С",Ведомость!$V$5:$V$846,"П-доп-низ",Ведомость!$W$5:$W$846,1) -> 0 | Z12: =SUMIFS(Ведомость!$N$5:$N$846,Ведомость!$H$5:$H$846,20,Ведомость!$I$5:$I$846,"А500С",Ведомость!$V$5:$V$846,"П-доп-верх",Ведомость!$W$5:$W$846,1) -> 12 | AA12: =SUMIFS(Ведомость!$N$5:$N$846,Ведомость!$H$5:$H$846,20,Ведомость!$I$5:$I$846,"А500С",Ведомость!$V$5:$V$846,"П-край",Ведомость!$W$5:$W$846,1) -> 0 | AB12: =SUMIFS(Ведомость!$N$5:$N$846,Ведомость!$H$5:$H$846,20,Ведомость!$I$5:$I$846,"А500С",Ведомость!$V$5:$V$846,"С-1",Ведомость!$W$5:$W$846,1) -> 0 | AC12: =SUMIFS(Ведомость!$N$5:$N$846,Ведомость!$H$5:$H$846,20,Ведомость!$I$5:$I$846,"А500С",Ведомость!$V$5:$V$846,"Л1",Ведомость!$W$5:$W$846,1) -> 0 | AD12: =SUMIFS(Ведомость!$N$5:$N$846,Ведомость!$H$5:$H$846,20,Ведомость!$I$5:$I$846,"А500С",Ведомость!$V$5:$V$846,"Л2",Ведомость!$W$5:$W$846,1) -> 0 | AE12: =SUMIFS(Ведомость!$N$5:$N$846,Ведомость!$H$5:$H$846,20,Ведомость!$I$5:$I$846,"А500С",Ведомость!$V$5:$V$846,"Л-пл",Ведомость!$W$5:$W$846,1) -> 0 | AF12: =SUMIFS(Ведомость!$N$5:$N$846,Ведомость!$H$5:$H$846,20,Ведомость!$I$5:$I$846,"А500С",Ведомость!$V$5:$V$846,"Л-рама",Ведомость!$W$5:$W$846,1) -> 0 | AG12: =SUM(B12:AF12) -> 785.84 | AH12: =IFERROR(INDEX(Исходные!$B$18:$B$30,MATCH(20,Исходные!$A$18:$A$30,0)),0) -> 2.466 | AI12: =AG12*AH12*$AJ$2 -> 2073.5331 | AJ12: =SUM(B12:D12,F12,H12,J12:M12) -> 702.7 | AK12: =AH12 -> 2.466 | AL12: =AJ12*AK12*$AJ$2 -> 1854.1583 | AM12: =SUM(E12,G12,I12,N12:AB12) -> 83.14 | AN12: =AH12 -> 2.466 | AO12: =AM12*AN12*$AJ$2 -> 219.37487 | AP12: =SUM(AC12:AF12) -> 0 | AQ12: =AH12 -> 2.466 | AR12: =AP12*AQ12*$AJ$2 -> 0
A13: Диаметр 18 А500С, L=м.п. | B13: =SUMIFS(Ведомость!$N$5:$N$846,Ведомость!$H$5:$H$846,18,Ведомость!$I$5:$I$846,"А500С",Ведомость!$V$5:$V$846,"Дм-1",Ведомость!$W$5:$W$846,1) -> 107.496 | C13: =SUMIFS(Ведомость!$N$5:$N$846,Ведомость!$H$5:$H$846,18,Ведомость!$I$5:$I$846,"А500С",Ведомость!$V$5:$V$846,"Дм-2",Ведомость!$W$5:$W$846,1) -> 0 | D13: =SUMIFS(Ведомость!$N$5:$N$846,Ведомость!$H$5:$H$846,18,Ведомость!$I$5:$I$846,"А500С",Ведомость!$V$5:$V$846,"К-А",Ведомость!$W$5:$W$846,1) -> 0 | E13: =SUMIFS(Ведомость!$N$5:$N$846,Ведомость!$H$5:$H$846,18,Ведомость!$I$5:$I$846,"А500С",Ведомость!$V$5:$V$846,"Р-А",Ведомость!$W$5:$W$846,1) -> 51.576 | F13: =SUMIFS(Ведомость!$N$5:$N$846,Ведомость!$H$5:$H$846,18,Ведомость!$I$5:$I$846,"А500С",Ведомость!$V$5:$V$846,"К-Б",Ведомость!$W$5:$W$846,1) -> 0 | G13: =SUMIFS(Ведомость!$N$5:$N$846,Ведомость!$H$5:$H$846,18,Ведомость!$I$5:$I$846,"А500С",Ведомость!$V$5:$V$846,"Р-Б",Ведомость!$W$5:$W$846,1) -> 51.576 | H13: =SUMIFS(Ведомость!$N$5:$N$846,Ведомость!$H$5:$H$846,18,Ведомость!$I$5:$I$846,"А500С",Ведомость!$V$5:$V$846,"К-В",Ведомость!$W$5:$W$846,1) -> 0 | I13: =SUMIFS(Ведомость!$N$5:$N$846,Ведомость!$H$5:$H$846,18,Ведомость!$I$5:$I$846,"А500С",Ведомость!$V$5:$V$846,"Р-В",Ведомость!$W$5:$W$846,1) -> 51.576 | J13: =SUMIFS(Ведомость!$N$5:$N$846,Ведомость!$H$5:$H$846,18,Ведомость!$I$5:$I$846,"А500С",Ведомость!$V$5:$V$846,"К-Г",Ведомость!$W$5:$W$846,1) -> 0 | K13: =SUMIFS(Ведомость!$N$5:$N$846,Ведомость!$H$5:$H$846,18,Ведомость!$I$5:$I$846,"А500С",Ведомость!$V$5:$V$846,"Дм-3",Ведомость!$W$5:$W$846,1) -> 18.644 | L13: =SUMIFS(Ведомость!$N$5:$N$846,Ведомость!$H$5:$H$846,18,Ведомость!$I$5:$I$846,"А500С",Ведомость!$V$5:$V$846,"Дм-4",Ведомость!$W$5:$W$846,1) -> 14.5 | M13: =SUMIFS(Ведомость!$N$5:$N$846,Ведомость!$H$5:$H$846,18,Ведомость!$I$5:$I$846,"А500С",Ведомость!$V$5:$V$846,"Дм-5",Ведомость!$W$5:$W$846,1) -> 0 | N13: =SUMIFS(Ведомость!$N$5:$N$846,Ведомость!$H$5:$H$846,18,Ведомость!$I$5:$I$846,"А500С",Ведомость!$V$5:$V$846,"Р-Г",Ведомость!$W$5:$W$846,1) -> 51.576 | O13: =SUMIFS(Ведомость!$N$5:$N$846,Ведомость!$H$5:$H$846,18,Ведомость!$I$5:$I$846,"А500С",Ведомость!$V$5:$V$846,"Р-1, 5",Ведомость!$W$5:$W$846,1) -> 82.576 | P13: =SUMIFS(Ведомость!$N$5:$N$846,Ведомость!$H$5:$H$846,18,Ведомость!$I$5:$I$846,"А500С",Ведомость!$V$5:$V$846,"Р-2",Ведомость!$W$5:$W$846,1) -> 41.288 | Q13: =SUMIFS(Ведомость!$N$5:$N$846,Ведомость!$H$5:$H$846,18,Ведомость!$I$5:$I$846,"А500С",Ведомость!$V$5:$V$846,"Р-3",Ведомость!$W$5:$W$846,1) -> 41.288 | R13: =SUMIFS(Ведомость!$N$5:$N$846,Ведомость!$H$5:$H$846,18,Ведомость!$I$5:$I$846,"А500С",Ведомость!$V$5:$V$846,"Р-4",Ведомость!$W$5:$W$846,1) -> 41.288 | S13: =SUMIFS(Ведомость!$N$5:$N$846,Ведомость!$H$5:$H$846,18,Ведомость!$I$5:$I$846,"А500С",Ведомость!$V$5:$V$846,"Б-основная",Ведомость!$W$5:$W$846,1) -> 0 | T13: =SUMIFS(Ведомость!$N$5:$N$846,Ведомость!$H$5:$H$846,18,Ведомость!$I$5:$I$846,"А500С",Ведомость!$V$5:$V$846,"Б-хомуты",Ведомость!$W$5:$W$846,1) -> 0 | U13: =SUMIFS(Ведомость!$N$5:$N$846,Ведомость!$H$5:$H$846,18,Ведомость!$I$5:$I$846,"А500С",Ведомость!$V$5:$V$846,"Б-допник",Ведомость!$W$5:$W$846,1) -> 50.4 | V13: =SUMIFS(Ведомость!$N$5:$N$846,Ведомость!$H$5:$H$846,18,Ведомость!$I$5:$I$846,"А500С",Ведомость!$V$5:$V$846,"П-сетка",Ведомость!$W$5:$W$846,1) -> 0 | W13: =SUMIFS(Ведомость!$N$5:$N$846,Ведомость!$H$5:$H$846,18,Ведомость!$I$5:$I$846,"А500С",Ведомость!$V$5:$V$846,"П-фикс",Ведомость!$W$5:$W$846,1) -> 0 | X13: =SUMIFS(Ведомость!$N$5:$N$846,Ведомость!$H$5:$H$846,18,Ведомость!$I$5:$I$846,"А500С",Ведомость!$V$5:$V$846,"П-отв",Ведомость!$W$5:$W$846,1) -> 0 | Y13: =SUMIFS(Ведомость!$N$5:$N$846,Ведомость!$H$5:$H$846,18,Ведомость!$I$5:$I$846,"А500С",Ведомость!$V$5:$V$846,"П-доп-низ",Ведомость!$W$5:$W$846,1) -> 0 | Z13: =SUMIFS(Ведомость!$N$5:$N$846,Ведомость!$H$5:$H$846,18,Ведомость!$I$5:$I$846,"А500С",Ведомость!$V$5:$V$846,"П-доп-верх",Ведомость!$W$5:$W$846,1) -> 0 | AA13: =SUMIFS(Ведомость!$N$5:$N$846,Ведомость!$H$5:$H$846,18,Ведомость!$I$5:$I$846,"А500С",Ведомость!$V$5:$V$846,"П-край",Ведомость!$W$5:$W$846,1) -> 0 | AB13: =SUMIFS(Ведомость!$N$5:$N$846,Ведомость!$H$5:$H$846,18,Ведомость!$I$5:$I$846,"А500С",Ведомость!$V$5:$V$846,"С-1",Ведомость!$W$5:$W$846,1) -> 0 | AC13: =SUMIFS(Ведомость!$N$5:$N$846,Ведомость!$H$5:$H$846,18,Ведомость!$I$5:$I$846,"А500С",Ведомость!$V$5:$V$846,"Л1",Ведомость!$W$5:$W$846,1) -> 106.74 | AD13: =SUMIFS(Ведомость!$N$5:$N$846,Ведомость!$H$5:$H$846,18,Ведомость!$I$5:$I$846,"А500С",Ведомость!$V$5:$V$846,"Л2",Ведомость!$W$5:$W$846,1) -> 117.144 | AE13: =SUMIFS(Ведомость!$N$5:$N$846,Ведомость!$H$5:$H$846,18,Ведомость!$I$5:$I$846,"А500С",Ведомость!$V$5:$V$846,"Л-пл",Ведомость!$W$5:$W$846,1) -> 0 | AF13: =SUMIFS(Ведомость!$N$5:$N$846,Ведомость!$H$5:$H$846,18,Ведомость!$I$5:$I$846,"А500С",Ведомость!$V$5:$V$846,"Л-рама",Ведомость!$W$5:$W$846,1) -> 0 | AG13: =SUM(B13:AF13) -> 827.668 | AH13: =IFERROR(INDEX(Исходные!$B$18:$B$30,MATCH(18,Исходные!$A$18:$A$30,0)),0) -> 1.998 | AI13: =AG13*AH13*$AJ$2 -> 1769.4383 | AJ13: =SUM(B13:D13,F13,H13,J13:M13) -> 140.64 | AK13: =AH13 -> 1.998 | AL13: =AJ13*AK13*$AJ$2 -> 300.66863 | AM13: =SUM(E13,G13,I13,N13:AB13) -> 463.144 | AN13: =AH13 -> 1.998 | AO13: =AM13*AN13*$AJ$2 -> 990.13703 | AP13: =SUM(AC13:AF13) -> 223.884 | AQ13: =AH13 -> 1.998 | AR13: =AP13*AQ13*$AJ$2 -> 478.63265
A14: Диаметр 16 А500С, L=м.п. | B14: =SUMIFS(Ведомость!$N$5:$N$846,Ведомость!$H$5:$H$846,16,Ведомость!$I$5:$I$846,"А500С",Ведомость!$V$5:$V$846,"Дм-1",Ведомость!$W$5:$W$846,1) -> 81 | C14: =SUMIFS(Ведомость!$N$5:$N$846,Ведомость!$H$5:$H$846,16,Ведомость!$I$5:$I$846,"А500С",Ведомость!$V$5:$V$846,"Дм-2",Ведомость!$W$5:$W$846,1) -> 126 | D14: =SUMIFS(Ведомость!$N$5:$N$846,Ведомость!$H$5:$H$846,16,Ведомость!$I$5:$I$846,"А500С",Ведомость!$V$5:$V$846,"К-А",Ведомость!$W$5:$W$846,1) -> 0 | E14: =SUMIFS(Ведомость!$N$5:$N$846,Ведомость!$H$5:$H$846,16,Ведомость!$I$5:$I$846,"А500С",Ведомость!$V$5:$V$846,"Р-А",Ведомость!$W$5:$W$846,1) -> 77.012 | F14: =SUMIFS(Ведомость!$N$5:$N$846,Ведомость!$H$5:$H$846,16,Ведомость!$I$5:$I$846,"А500С",Ведомость!$V$5:$V$846,"К-Б",Ведомость!$W$5:$W$846,1) -> 0 | G14: =SUMIFS(Ведомость!$N$5:$N$846,Ведомость!$H$5:$H$846,16,Ведомость!$I$5:$I$846,"А500С",Ведомость!$V$5:$V$846,"Р-Б",Ведомость!$W$5:$W$846,1) -> 63.112 | H14: =SUMIFS(Ведомость!$N$5:$N$846,Ведомость!$H$5:$H$846,16,Ведомость!$I$5:$I$846,"А500С",Ведомость!$V$5:$V$846,"К-В",Ведомость!$W$5:$W$846,1) -> 0 | I14: =SUMIFS(Ведомость!$N$5:$N$846,Ведомость!$H$5:$H$846,16,Ведомость!$I$5:$I$846,"А500С",Ведомость!$V$5:$V$846,"Р-В",Ведомость!$W$5:$W$846,1) -> 63.112 | J14: =SUMIFS(Ведомость!$N$5:$N$846,Ведомость!$H$5:$H$846,16,Ведомость!$I$5:$I$846,"А500С",Ведомость!$V$5:$V$846,"К-Г",Ведомость!$W$5:$W$846,1) -> 0 | K14: =SUMIFS(Ведомость!$N$5:$N$846,Ведомость!$H$5:$H$846,16,Ведомость!$I$5:$I$846,"А500С",Ведомость!$V$5:$V$846,"Дм-3",Ведомость!$W$5:$W$846,1) -> 83 | L14: =SUMIFS(Ведомость!$N$5:$N$846,Ведомость!$H$5:$H$846,16,Ведомость!$I$5:$I$846,"А500С",Ведомость!$V$5:$V$846,"Дм-4",Ведомость!$W$5:$W$846,1) -> 52.2 | M14: =SUMIFS(Ведомость!$N$5:$N$846,Ведомость!$H$5:$H$846,16,Ведомость!$I$5:$I$846,"А500С",Ведомость!$V$5:$V$846,"Дм-5",Ведомость!$W$5:$W$846,1) -> 97.2 | N14: =SUMIFS(Ведомость!$N$5:$N$846,Ведомость!$H$5:$H$846,16,Ведомость!$I$5:$I$846,"А500С",Ведомость!$V$5:$V$846,"Р-Г",Ведомость!$W$5:$W$846,1) -> 55.212 | O14: =SUMIFS(Ведомость!$N$5:$N$846,Ведомость!$H$5:$H$846,16,Ведомость!$I$5:$I$846,"А500С",Ведомость!$V$5:$V$846,"Р-1, 5",Ведомость!$W$5:$W$846,1) -> 125.912 | P14: =SUMIFS(Ведомость!$N$5:$N$846,Ведомость!$H$5:$H$846,16,Ведомость!$I$5:$I$846,"А500С",Ведомость!$V$5:$V$846,"Р-2",Ведомость!$W$5:$W$846,1) -> 48.456 | Q14: =SUMIFS(Ведомость!$N$5:$N$846,Ведомость!$H$5:$H$846,16,Ведомость!$I$5:$I$846,"А500С",Ведомость!$V$5:$V$846,"Р-3",Ведомость!$W$5:$W$846,1) -> 56.956 | R14: =SUMIFS(Ведомость!$N$5:$N$846,Ведомость!$H$5:$H$846,16,Ведомость!$I$5:$I$846,"А500С",Ведомость!$V$5:$V$846,"Р-4",Ведомость!$W$5:$W$846,1) -> 45.856 | S14: =SUMIFS(Ведомость!$N$5:$N$846,Ведомость!$H$5:$H$846,16,Ведомость!$I$5:$I$846,"А500С",Ведомость!$V$5:$V$846,"Б-основная",Ведомость!$W$5:$W$846,1) -> 0 | T14: =SUMIFS(Ведомость!$N$5:$N$846,Ведомость!$H$5:$H$846,16,Ведомость!$I$5:$I$846,"А500С",Ведомость!$V$5:$V$846,"Б-хомуты",Ведомость!$W$5:$W$846,1) -> 0 | U14: =SUMIFS(Ведомость!$N$5:$N$846,Ведомость!$H$5:$H$846,16,Ведомость!$I$5:$I$846,"А500С",Ведомость!$V$5:$V$846,"Б-допник",Ведомость!$W$5:$W$846,1) -> 0 | V14: =SUMIFS(Ведомость!$N$5:$N$846,Ведомость!$H$5:$H$846,16,Ведомость!$I$5:$I$846,"А500С",Ведомость!$V$5:$V$846,"П-сетка",Ведомость!$W$5:$W$846,1) -> 0 | W14: =SUMIFS(Ведомость!$N$5:$N$846,Ведомость!$H$5:$H$846,16,Ведомость!$I$5:$I$846,"А500С",Ведомость!$V$5:$V$846,"П-фикс",Ведомость!$W$5:$W$846,1) -> 0 | X14: =SUMIFS(Ведомость!$N$5:$N$846,Ведомость!$H$5:$H$846,16,Ведомость!$I$5:$I$846,"А500С",Ведомость!$V$5:$V$846,"П-отв",Ведомость!$W$5:$W$846,1) -> 0 | Y14: =SUMIFS(Ведомость!$N$5:$N$846,Ведомость!$H$5:$H$846,16,Ведомость!$I$5:$I$846,"А500С",Ведомость!$V$5:$V$846,"П-доп-низ",Ведомость!$W$5:$W$846,1) -> 0 | Z14: =SUMIFS(Ведомость!$N$5:$N$846,Ведомость!$H$5:$H$846,16,Ведомость!$I$5:$I$846,"А500С",Ведомость!$V$5:$V$846,"П-доп-верх",Ведомость!$W$5:$W$846,1) -> 0 | AA14: =SUMIFS(Ведомость!$N$5:$N$846,Ведомость!$H$5:$H$846,16,Ведомость!$I$5:$I$846,"А500С",Ведомость!$V$5:$V$846,"П-край",Ведомость!$W$5:$W$846,1) -> 0 | AB14: =SUMIFS(Ведомость!$N$5:$N$846,Ведомость!$H$5:$H$846,16,Ведомость!$I$5:$I$846,"А500С",Ведомость!$V$5:$V$846,"С-1",Ведомость!$W$5:$W$846,1) -> 0 | AC14: =SUMIFS(Ведомость!$N$5:$N$846,Ведомость!$H$5:$H$846,16,Ведомость!$I$5:$I$846,"А500С",Ведомость!$V$5:$V$846,"Л1",Ведомость!$W$5:$W$846,1) -> 0 | AD14: =SUMIFS(Ведомость!$N$5:$N$846,Ведомость!$H$5:$H$846,16,Ведомость!$I$5:$I$846,"А500С",Ведомость!$V$5:$V$846,"Л2",Ведомость!$W$5:$W$846,1) -> 0 | AE14: =SUMIFS(Ведомость!$N$5:$N$846,Ведомость!$H$5:$H$846,16,Ведомость!$I$5:$I$846,"А500С",Ведомость!$V$5:$V$846,"Л-пл",Ведомость!$W$5:$W$846,1) -> 0 | AF14: =SUMIFS(Ведомость!$N$5:$N$846,Ведомость!$H$5:$H$846,16,Ведомость!$I$5:$I$846,"А500С",Ведомость!$V$5:$V$846,"Л-рама",Ведомость!$W$5:$W$846,1) -> 0 | AG14: =SUM(B14:AF14) -> 975.028 | AH14: =IFERROR(INDEX(Исходные!$B$18:$B$30,MATCH(16,Исходные!$A$18:$A$30,0)),0) -> 1.578 | AI14: =AG14*AH14*$AJ$2 -> 1646.2958 | AJ14: =SUM(B14:D14,F14,H14,J14:M14) -> 439.4 | AK14: =AH14 -> 1.578 | AL14: =AJ14*AK14*$AJ$2 -> 741.90932 | AM14: =SUM(E14,G14,I14,N14:AB14) -> 535.628 | AN14: =AH14 -> 1.578 | AO14: =AM14*AN14*$AJ$2 -> 904.38645 | AP14: =SUM(AC14:AF14) -> 0 | AQ14: =AH14 -> 1.578 | AR14: =AP14*AQ14*$AJ$2 -> 0
A15: Диаметр 14 А500С, L=м.п. | B15: =SUMIFS(Ведомость!$N$5:$N$846,Ведомость!$H$5:$H$846,14,Ведомость!$I$5:$I$846,"А500С",Ведомость!$V$5:$V$846,"Дм-1",Ведомость!$W$5:$W$846,1) -> 0 | C15: =SUMIFS(Ведомость!$N$5:$N$846,Ведомость!$H$5:$H$846,14,Ведомость!$I$5:$I$846,"А500С",Ведомость!$V$5:$V$846,"Дм-2",Ведомость!$W$5:$W$846,1) -> 0 | D15: =SUMIFS(Ведомость!$N$5:$N$846,Ведомость!$H$5:$H$846,14,Ведомость!$I$5:$I$846,"А500С",Ведомость!$V$5:$V$846,"К-А",Ведомость!$W$5:$W$846,1) -> 0 | E15: =SUMIFS(Ведомость!$N$5:$N$846,Ведомость!$H$5:$H$846,14,Ведомость!$I$5:$I$846,"А500С",Ведомость!$V$5:$V$846,"Р-А",Ведомость!$W$5:$W$846,1) -> 0 | F15: =SUMIFS(Ведомость!$N$5:$N$846,Ведомость!$H$5:$H$846,14,Ведомость!$I$5:$I$846,"А500С",Ведомость!$V$5:$V$846,"К-Б",Ведомость!$W$5:$W$846,1) -> 0 | G15: =SUMIFS(Ведомость!$N$5:$N$846,Ведомость!$H$5:$H$846,14,Ведомость!$I$5:$I$846,"А500С",Ведомость!$V$5:$V$846,"Р-Б",Ведомость!$W$5:$W$846,1) -> 14.8 | H15: =SUMIFS(Ведомость!$N$5:$N$846,Ведомость!$H$5:$H$846,14,Ведомость!$I$5:$I$846,"А500С",Ведомость!$V$5:$V$846,"К-В",Ведомость!$W$5:$W$846,1) -> 0 | I15: =SUMIFS(Ведомость!$N$5:$N$846,Ведомость!$H$5:$H$846,14,Ведомость!$I$5:$I$846,"А500С",Ведомость!$V$5:$V$846,"Р-В",Ведомость!$W$5:$W$846,1) -> 32 | J15: =SUMIFS(Ведомость!$N$5:$N$846,Ведомость!$H$5:$H$846,14,Ведомость!$I$5:$I$846,"А500С",Ведомость!$V$5:$V$846,"К-Г",Ведомость!$W$5:$W$846,1) -> 0 | K15: =SUMIFS(Ведомость!$N$5:$N$846,Ведомость!$H$5:$H$846,14,Ведомость!$I$5:$I$846,"А500С",Ведомость!$V$5:$V$846,"Дм-3",Ведомость!$W$5:$W$846,1) -> 52.2 | L15: =SUMIFS(Ведомость!$N$5:$N$846,Ведомость!$H$5:$H$846,14,Ведомость!$I$5:$I$846,"А500С",Ведомость!$V$5:$V$846,"Дм-4",Ведомость!$W$5:$W$846,1) -> 0 | M15: =SUMIFS(Ведомость!$N$5:$N$846,Ведомость!$H$5:$H$846,14,Ведомость!$I$5:$I$846,"А500С",Ведомость!$V$5:$V$846,"Дм-5",Ведомость!$W$5:$W$846,1) -> 8.7 | N15: =SUMIFS(Ведомость!$N$5:$N$846,Ведомость!$H$5:$H$846,14,Ведомость!$I$5:$I$846,"А500С",Ведомость!$V$5:$V$846,"Р-Г",Ведомость!$W$5:$W$846,1) -> 0 | O15: =SUMIFS(Ведомость!$N$5:$N$846,Ведомость!$H$5:$H$846,14,Ведомость!$I$5:$I$846,"А500С",Ведомость!$V$5:$V$846,"Р-1, 5",Ведомость!$W$5:$W$846,1) -> 0 | P15: =SUMIFS(Ведомость!$N$5:$N$846,Ведомость!$H$5:$H$846,14,Ведомость!$I$5:$I$846,"А500С",Ведомость!$V$5:$V$846,"Р-2",Ведомость!$W$5:$W$846,1) -> 36.7 | Q15: =SUMIFS(Ведомость!$N$5:$N$846,Ведомость!$H$5:$H$846,14,Ведомость!$I$5:$I$846,"А500С",Ведомость!$V$5:$V$846,"Р-3",Ведомость!$W$5:$W$846,1) -> 0 | R15: =SUMIFS(Ведомость!$N$5:$N$846,Ведомость!$H$5:$H$846,14,Ведомость!$I$5:$I$846,"А500С",Ведомость!$V$5:$V$846,"Р-4",Ведомость!$W$5:$W$846,1) -> 0 | S15: =SUMIFS(Ведомость!$N$5:$N$846,Ведомость!$H$5:$H$846,14,Ведомость!$I$5:$I$846,"А500С",Ведомость!$V$5:$V$846,"Б-основная",Ведомость!$W$5:$W$846,1) -> 0 | T15: =SUMIFS(Ведомость!$N$5:$N$846,Ведомость!$H$5:$H$846,14,Ведомость!$I$5:$I$846,"А500С",Ведомость!$V$5:$V$846,"Б-хомуты",Ведомость!$W$5:$W$846,1) -> 0 | U15: =SUMIFS(Ведомость!$N$5:$N$846,Ведомость!$H$5:$H$846,14,Ведомость!$I$5:$I$846,"А500С",Ведомость!$V$5:$V$846,"Б-допник",Ведомость!$W$5:$W$846,1) -> 0 | V15: =SUMIFS(Ведомость!$N$5:$N$846,Ведомость!$H$5:$H$846,14,Ведомость!$I$5:$I$846,"А500С",Ведомость!$V$5:$V$846,"П-сетка",Ведомость!$W$5:$W$846,1) -> 0 | W15: =SUMIFS(Ведомость!$N$5:$N$846,Ведомость!$H$5:$H$846,14,Ведомость!$I$5:$I$846,"А500С",Ведомость!$V$5:$V$846,"П-фикс",Ведомость!$W$5:$W$846,1) -> 0 | X15: =SUMIFS(Ведомость!$N$5:$N$846,Ведомость!$H$5:$H$846,14,Ведомость!$I$5:$I$846,"А500С",Ведомость!$V$5:$V$846,"П-отв",Ведомость!$W$5:$W$846,1) -> 0 | Y15: =SUMIFS(Ведомость!$N$5:$N$846,Ведомость!$H$5:$H$846,14,Ведомость!$I$5:$I$846,"А500С",Ведомость!$V$5:$V$846,"П-доп-низ",Ведомость!$W$5:$W$846,1) -> 0 | Z15: =SUMIFS(Ведомость!$N$5:$N$846,Ведомость!$H$5:$H$846,14,Ведомость!$I$5:$I$846,"А500С",Ведомость!$V$5:$V$846,"П-доп-верх",Ведомость!$W$5:$W$846,1) -> 0 | AA15: =SUMIFS(Ведомость!$N$5:$N$846,Ведомость!$H$5:$H$846,14,Ведомость!$I$5:$I$846,"А500С",Ведомость!$V$5:$V$846,"П-край",Ведомость!$W$5:$W$846,1) -> 96.06 | AB15: =SUMIFS(Ведомость!$N$5:$N$846,Ведомость!$H$5:$H$846,14,Ведомость!$I$5:$I$846,"А500С",Ведомость!$V$5:$V$846,"С-1",Ведомость!$W$5:$W$846,1) -> 0 | AC15: =SUMIFS(Ведомость!$N$5:$N$846,Ведомость!$H$5:$H$846,14,Ведомость!$I$5:$I$846,"А500С",Ведомость!$V$5:$V$846,"Л1",Ведомость!$W$5:$W$846,1) -> 0 | AD15: =SUMIFS(Ведомость!$N$5:$N$846,Ведомость!$H$5:$H$846,14,Ведомость!$I$5:$I$846,"А500С",Ведомость!$V$5:$V$846,"Л2",Ведомость!$W$5:$W$846,1) -> 0 | AE15: =SUMIFS(Ведомость!$N$5:$N$846,Ведомость!$H$5:$H$846,14,Ведомость!$I$5:$I$846,"А500С",Ведомость!$V$5:$V$846,"Л-пл",Ведомость!$W$5:$W$846,1) -> 0 | AF15: =SUMIFS(Ведомость!$N$5:$N$846,Ведомость!$H$5:$H$846,14,Ведомость!$I$5:$I$846,"А500С",Ведомость!$V$5:$V$846,"Л-рама",Ведомость!$W$5:$W$846,1) -> 0 | AG15: =SUM(B15:AF15) -> 240.46 | AH15: =IFERROR(INDEX(Исходные!$B$18:$B$30,MATCH(14,Исходные!$A$18:$A$30,0)),0) -> 1.208 | AI15: =AG15*AH15*$AJ$2 -> 310.80898 | AJ15: =SUM(B15:D15,F15,H15,J15:M15) -> 60.9 | AK15: =AH15 -> 1.208 | AL15: =AJ15*AK15*$AJ$2 -> 78.716904 | AM15: =SUM(E15,G15,I15,N15:AB15) -> 179.56 | AN15: =AH15 -> 1.208 | AO15: =AM15*AN15*$AJ$2 -> 232.09207 | AP15: =SUM(AC15:AF15) -> 0 | AQ15: =AH15 -> 1.208 | AR15: =AP15*AQ15*$AJ$2 -> 0
