Workbook

Sheet потребность
A1: Блок 14, ул. Токомбаева — потребность по этажам
A2: Арматура (чистая проектная масса, без запаса)
A3: Диаметр | B3: Ед. изм. | C3: 1 этаж (-0.050…+3.950) | F3: 2 этаж (+3.950…+7.550) | I3: 3 этаж (+7.550…+11.150) | L3: Итого 1–3 этаж | M3: Итого × К зап | N3: Заказ (раскрой поэтажно под прутки 11,7 м)
C4: Колонны, диафрагмы | D4: Плита перекрытия, балки, ригели, С-1 | E4: Лестницы и лест. рамы | F4: Колонны, диафрагмы | G4: Плита перекрытия, балки, ригели, С-1 | H4: Лестницы и лест. рамы | I4: Колонны, диафрагмы | J4: Плита перекрытия, балки, ригели, С-1 | K4: Лестницы и лест. рамы | N4: Прутков 11,7 м, шт | O4: Масса заказа, кг | P4: Отход, %
A5: Диаметр 32 А500С | B5: кг | C5: ='По осям'!AJ8*'По осям'!AK8 | D5: ='По осям'!AM8*'По осям'!AN8 | E5: ='По осям'!AP8*'По осям'!AQ8 | F5: ='По осям'!AJ54*'По осям'!AK54 | G5: ='По осям'!AM54*'По осям'!AN54 | H5: ='По осям'!AP54*'По осям'!AQ54 | I5: ='По осям'!AJ100*'По осям'!AK100 | J5: ='По осям'!AM100*'По осям'!AN100 | K5: ='По осям'!AP100*'По осям'!AQ100 | L5: =SUM(C5:K5) | M5: =L5*Исходные!$B$14 | N5: ='Раскрой 11,7м'!D666 | O5: ='Раскрой 11,7м'!E666 | P5: ='Раскрой 11,7м'!H666
A6: Диаметр 28 А500С | B6: кг | C6: ='По осям'!AJ9*'По осям'!AK9 | D6: ='По осям'!AM9*'По осям'!AN9 | E6: ='По осям'!AP9*'По осям'!AQ9 | F6: ='По осям'!AJ55*'По осям'!AK55 | G6: ='По осям'!AM55*'По осям'!AN55 | H6: ='По осям'!AP55*'По осям'!AQ55 | I6: ='По осям'!AJ101*'По осям'!AK101 | J6: ='По осям'!AM101*'По осям'!AN101 | K6: ='По осям'!AP101*'По осям'!AQ101 | L6: =SUM(C6:K6) | M6: =L6*Исходные!$B$14 | N6: ='Раскрой 11,7м'!D667 | O6: ='Раскрой 11,7м'!E667 | P6: ='Раскрой 11,7м'!H667
A7: Диаметр 25 А500С | B7: кг | C7: ='По осям'!AJ10*'По осям'!AK10 | D7: ='По осям'!AM10*'По осям'!AN10 | E7: ='По осям'!AP10*'По осям'!AQ10 | F7: ='По осям'!AJ56*'По осям'!AK56 | G7: ='По осям'!AM56*'По осям'!AN56 | H7: ='По осям'!AP56*'По осям'!AQ56 | I7: ='По осям'!AJ102*'По осям'!AK102 | J7: ='По осям'!AM102*'По осям'!AN102 | K7: ='По осям'!AP102*'По осям'!AQ102 | L7: =SUM(C7:K7) | M7: =L7*Исходные!$B$14 | N7: ='Раскрой 11,7м'!D668 | O7: ='Раскрой 11,7м'!E668 | P7: ='Раскрой 11,7м'!H668
A8: Диаметр 22 А500С | B8: кг | C8: ='По осям'!AJ11*'По осям'!AK11 | D8: ='По осям'!AM11*'По осям'!AN11 | E8: ='По осям'!AP11*'По осям'!AQ11 | F8: ='По осям'!AJ57*'По осям'!AK57 | G8: ='По осям'!AM57*'По осям'!AN57 | H8: ='По осям'!AP57*'По осям'!AQ57 | I8: ='По осям'!AJ103*'По осям'!AK103 | J8: ='По осям'!AM103*'По осям'!AN103 | K8: ='По осям'!AP103*'По осям'!AQ103 | L8: =SUM(C8:K8) | M8: =L8*Исходные!$B$14 | N8: ='Раскрой 11,7м'!D669 | O8: ='Раскрой 11,7м'!E669 | P8: ='Раскрой 11,7м'!H669
A9: Диаметр 20 А500С | B9: кг | C9: ='По осям'!AJ12*'По осям'!AK12 | D9: ='По осям'!AM12*'По осям'!AN12 | E9: ='По осям'!AP12*'По осям'!AQ12 | F9: ='По осям'!AJ58*'По осям'!AK58 | G9: ='По осям'!AM58*'По осям'!AN58 | H9: ='По осям'!AP58*'По осям'!AQ58 | I9: ='По осям'!AJ104*'По осям'!AK104 | J9: ='По осям'!AM104*'По осям'!AN104 | K9: ='По осям'!AP104*'По осям'!AQ104 | L9: =SUM(C9:K9) | M9: =L9*Исходные!$B$14 | N9: ='Раскрой 11,7м'!D670 | O9: ='Раскрой 11,7м'!E670 | P9: ='Раскрой 11,7м'!H670
A10: Диаметр 18 А500С | B10: кг | C10: ='По осям'!AJ13*'По осям'!AK13 | D10: ='По осям'!AM13*'По осям'!AN13 | E10: ='По осям'!AP13*'По осям'!AQ13 | F10: ='По осям'!AJ59*'По осям'!AK59 | G10: ='По осям'!AM59*'По осям'!AN59 | H10: ='По осям'!AP59*'По осям'!AQ59 | I10: ='По осям'!AJ105*'По осям'!AK105 | J10: ='По осям'!AM105*'По осям'!AN105 | K10: ='По осям'!AP105*'По осям'!AQ105 | L10: =SUM(C10:K10) | M10: =L10*Исходные!$B$14 | N10: ='Раскрой 11,7м'!D671 | O10: ='Раскрой 11,7м'!E671 | P10: ='Раскрой 11,7м'!H671
A11: Диаметр 16 А500С | B11: кг | C11: ='По осям'!AJ14*'По осям'!AK14 | D11: ='По осям'!AM14*'По осям'!AN14 | E11: ='По осям'!AP14*'По осям'!AQ14 | F11: ='По осям'!AJ60*'По осям'!AK60 | G11: ='По осям'!AM60*'По осям'!AN60 | H11: ='По осям'!AP60*'По осям'!AQ60 | I11: ='По осям'!AJ106*'По осям'!AK106 | J11: ='По осям'!AM106*'По осям'!AN106 | K11: ='По осям'!AP106*'По осям'!AQ106 | L11: =SUM(C11:K11) | M11: =L11*Исходные!$B$14 | N11: ='Раскрой 11,7м'!D672 | O11: ='Раскрой 11,7м'!E672 | P11: ='Раскрой 11,7м'!H672
A12: Диаметр 14 А500С | B12: кг | C12: ='По осям'!AJ15*'По осям'!AK15 | D12: ='По осям'!AM15*'По осям'!AN15 | E12: ='По осям'!AP15*'По осям'!AQ15 | F12: ='По осям'!AJ61*'По осям'!AK61 | G12: ='По осям'!AM61*'По осям'!AN61 | H12: ='По осям'!AP61*'По осям'!AQ61 | I12: ='По осям'!AJ107*'По осям'!AK107 | J12: ='По осям'!AM107*'По осям'!AN107 | K12: ='По осям'!AP107*'По осям'!AQ107 | L12: =SUM(C12:K12) | M12: =L12*Исходные!$B$14 | N12: ='Раскрой 11,7м'!D673 | O12: ='Раскрой 11,7м'!E673 | P12: ='Раскрой 11,7м'!H673
A13: Диаметр 12 А500С | B13: кг | C13: ='По осям'!AJ16*'По осям'!AK16 | D13: ='По осям'!AM16*'По осям'!AN16 | E13: ='По осям'!AP16*'По осям'!AQ16 | F13: ='По осям'!AJ62*'По осям'!AK62 | G13: ='По осям'!AM62*'По осям'!AN62 | H13: ='По осям'!AP62*'По осям'!AQ62 | I13: ='По осям'!AJ108*'По осям'!AK108 | J13: ='По осям'!AM108*'По осям'!AN108 | K13: ='По осям'!AP108*'По осям'!AQ108 | L13: =SUM(C13:K13) | M13: =L13*Исходные!$B$14 | N13: ='Раскрой 11,7м'!D674 | O13: ='Раскрой 11,7м'!E674 | P13: ='Раскрой 11,7м'!H674
A14: Диаметр 10 А500С | B14: кг | C14: ='По осям'!AJ17*'По осям'!AK17 | D14: ='По осям'!AM17*'По осям'!AN17 | E14: ='По осям'!AP17*'По осям'!AQ17 | F14: ='По осям'!AJ63*'По осям'!AK63 | G14: ='По осям'!AM63*'По осям'!AN63 | H14: ='По осям'!AP63*'По осям'!AQ63 | I14: ='По осям'!AJ109*'По осям'!AK109 | J14: ='По осям'!AM109*'По осям'!AN109 | K14: ='По осям'!AP109*'По осям'!AQ109 | L14: =SUM(C14:K14) | M14: =L14*Исходные!$B$14 | N14: ='Раскрой 11,7м'!D675 | O14: ='Раскрой 11,7м'!E675 | P14: ='Раскрой 11,7м'!H675
A15: Диаметр 8 А500С | B15: кг | C15: ='По осям'!AJ18*'По осям'!AK18 | D15: ='По осям'!AM18*'По осям'!AN18 | E15: ='По осям'!AP18*'По осям'!AQ18 | F15: ='По осям'!AJ64*'По осям'!AK64 | G15: ='По осям'!AM64*'По осям'!AN64 | H15: ='По осям'!AP64*'По осям'!AQ64 | I15: ='По осям'!AJ110*'По осям'!AK110 | J15: ='По осям'!AM110*'По осям'!AN110 | K15: ='По осям'!AP110*'По осям'!AQ110 | L15: =SUM(C15:K15) | M15: =L15*Исходные!$B$14 | N15: ='Раскрой 11,7м'!D676 | O15: ='Раскрой 11,7м'!E676 | P15: ='Раскрой 11,7м'!H676
A16: Диаметр 16 А240 | B16: кг | C16: ='По осям'!AJ19*'По осям'!AK19 | D16: ='По осям'!AM19*'По осям'!AN19 | E16: ='По осям'!AP19*'По осям'!AQ19 | F16: ='По осям'!AJ65*'По осям'!AK65 | G16: ='По осям'!AM65*'По осям'!AN65 | H16: ='По осям'!AP65*'По осям'!AQ65 | I16: ='По осям'!AJ111*'По осям'!AK111 | J16: ='По осям'!AM111*'По осям'!AN111 | K16: ='По осям'!AP111*'По осям'!AQ111 | L16: =SUM(C16:K16) | M16: =L16*Исходные!$B$14 | N16: ='Раскрой 11,7м'!D677 | O16: ='Раскрой 11,7м'!E677 | P16: ='Раскрой 11,7м'!H677
... A21: Сетка Ø5 Вр-I 100×100 (лестница) | B21: кг | C21: ='По осям'!AJ24*'По осям'!AK24 | D21: ='По осям'!AM24*'По осям'!AN24 | E21: ='По осям'!AP24*'По осям'!AQ24 | F21: ='По осям'!AJ70*'По осям'!AK70 | G21: ='По осям'!AM70*'По осям'!AN70 | H21: ='По осям'!AP70*'По осям'!AQ70 | I21: ='По осям'!AJ116*'По осям'!AK116 | J21: ='По осям'!AM116*'По осям'!AN116 | K21: ='По осям'!AP116*'По осям'!AQ116 | L21: =SUM(C21:K21) | M21: =L21*Исходные!$B$14 | N21: ='Раскрой 11,7м'!D682 | O21: ='Раскрой 11,7м'!E682 | P21: ='Раскрой 11,7м'!H682
A22: Итого: | B22: кг | C22: =SUM(C5:C21) | D22: =SUM(D5:D21) | E22: =SUM(E5:E21) | F22: =SUM(F5:F21) | G22: =SUM(G5:G21) | H22: =SUM(H5:H21) | I22: =SUM(I5:I21) | J22: =SUM(J5:J21) | ... O22: =SUM(O5:O21) | P22: ='Раскрой 11,7м'!H683
A23: Итого: | B23: т | C23: =C22/1000 | D23: =D22/1000 | E23: =E22/1000 | F23: =F22/1000 | G23: =G22/1000 | H23: =H22/1000 | I23: =I22/1000 | J23: =J22/1000 | ... M23: =M22/1000 | O23: =O22/1000
A24: Итого по этажу, кг | B24: кг | C24: =SUM(C22:E22) | F24: =SUM(F22:H22) | I24: =SUM(I22:K22) | L24: =L22
A25: Контроль: = «Ведомость» и «По осям» | L25: =ROUND(L22-Ведомость!P1274,1)+ROUND(L22-'По осям'!AI25-'По осям'!AI71-'По осям'!AI117,1) | M25: ← должно быть 0
A27: Бетон
A28: Марка | B28: Ед. изм. | C28: 1 этаж (-0.050…+3.950) | F28: 2 этаж (+3.950…+7.550) | I28: 3 этаж (+7.550…+11.150) | L28: Итого 1–3 этаж
C29: Колонны, диафрагмы | D29: Плита перекрытия, балки, ригели, С-1 | E29: Лестницы и лест. рамы | F29: Колонны, диафрагмы | G29: Плита перекрытия, балки, ригели, С-1 | H29: Лестницы и лест. рамы | I29: Колонны, диафрагмы | J29: Плита перекрытия, балки, ригели, С-1 | K29: Лестницы и лест. рамы
A30: В25 | B30: м3 | C30: ='По осям'!AL31 | D30: ='По осям'!AO31 | E30: ='По осям'!AR31 | F30: ='По осям'!AL77 | G30: ='По осям'!AO77 | H30: ='По осям'!AR77 | I30: ='По осям'!AL123 | J30: ='По осям'!AO123 | K30: ='По осям'!AR123 | L30: =SUM(C30:K30)
A32: Прочие материалы
A33: Наименование | B33: Ед. изм. | C33: 1 этаж (-0.050…+3.950) | F33: 2 этаж (+3.950…+7.550) | I33: 3 этаж (+7.550…+11.150) | L33: Итого 1–3 этаж
C34: Колонны, диафрагмы | D34: Плита перекрытия, балки, ригели, С-1 | E34: Лестницы и лест. рамы | F34: Колонны, диафрагмы | G34: Плита перекрытия, балки, ригели, С-1 | H34: Лестницы и лест. рамы | I34: Колонны, диафрагмы | J34: Плита перекрытия, балки, ригели, С-1 | K34: Лестницы и лест. рамы
A35: Анкерная шайба АШ-1 (14) | B35: шт. | C35: ='По осям'!AJ35 | D35: ='По осям'!AM35 | E35: ='По осям'!AP35 | F35: ='По осям'!AJ81 | G35: ='По осям'!AM81 | H35: ='По осям'!AP81 | I35: ='По осям'!AJ127 | J35: ='По осям'!AM127 | K35: ='По осям'!AP127 | L35: =SUM(C35:K35)
A36: Анкерная шайба АШ-2 (16) | B36: шт. | C36: ='По осям'!AJ36 | D36: ='По осям'!AM36 | E36: ='По осям'!AP36 | F36: ='По осям'!AJ82 | G36: ='По осям'!AM82 | H36: ='По осям'!AP82 | I36: ='По осям'!AJ128 | J36: ='По осям'!AM128 | K36: ='По осям'!AP128 | L36: =SUM(C36:K36)
A37: Анкерная шайба АШ-3 (18) | B37: шт. | C37: ='По осям'!AJ37 | D37: ='По осям'!AM37 | E37: ='По осям'!AP37 | F37: ='По осям'!AJ83 | G37: ='По осям'!AM83 | H37: ='По осям'!AP83 | I37: ='По осям'!AJ129 | J37: ='По осям'!AM129 | K37: ='По осям'!AP129 | L37: =SUM(C37:K37)
A38: Анкерная шайба АШ-4 (20) | B38: шт. | C38: ='По осям'!AJ38 | D38: ='По осям'!AM38 | E38: ='По осям'!AP38 | F38: ='По осям'!AJ84 | G38: ='По осям'!AM84 | H38: ='По осям'!AP84 | I38: ='По осям'!AJ130 | J38: ='По осям'!AM130 | K38: ='По осям'!AP130 | L38: =SUM(C38:K38)
A39: Анкерная шайба АШ-5 (22) | B39: шт. | C39: ='По осям'!AJ39 | D39: ='По осям'!AM39 | E39: ='По осям'!AP39 | F39: ='По осям'!AJ85 | G39: ='По осям'!AM85 | H39: ='По осям'!AP85 | I39: ='По осям'!AJ131 | J39: ='По осям'!AM131 | K39: ='По осям'!AP131 | L39: =SUM(C39:K39)
A40: Анкерная шайба АШ-6 (25) | B40: шт. | C40: ='По осям'!AJ40 | D40: ='По осям'!AM40 | E40: ='По осям'!AP40 | F40: ='По осям'!AJ86 | G40: ='По осям'!AM86 | H40: ='По осям'!AP86 | I40: ='По осям'!AJ132 | J40: ='По осям'!AM132 | K40: ='По осям'!AP132 | L40: =SUM(C40:K40)
A41: Анкерная шайба АШ-7 (28) | B41: шт. | C41: ='По осям'!AJ41 | D41: ='По осям'!AM41 | E41: ='По осям'!AP41 | F41: ='По осям'!AJ87 | G41: ='По осям'!AM87 | H41: ='По осям'!AP87 | I41: ='По осям'!AJ133 | J41: ='По осям'!AM133 | K41: ='По осям'!AP133 | L41: =SUM(C41:K41)
A42: Анкерная шайба АШ-8 (32) | B42: шт. | C42: ='По осям'!AJ42 | D42: ='По осям'!AM42 | E42: ='По осям'!AP42 | F42: ='По осям'!AJ88 | G42: ='По осям'!AM88 | H42: ='По осям'!AP88 | I42: ='По осям'!AJ134 | J42: ='По осям'!AM134 | K42: ='По осям'!AP134 | L42: =SUM(C42:K42)
A43: Ванночка d32 (стыков ванной сваркой) | B43: шт. | C43: ='По осям'!AJ43 | D43: ='По осям'!AM43 | E43: ='По осям'!AP43 | F43: ='По осям'!AJ89 | G43: ='По осям'!AM89 | H43: ='По осям'!AP89 | I43: ='По осям'!AJ135 | J43: ='По осям'!AM135 | K43: ='По осям'!AP135 | L43: =SUM(C43:K43)
A44: Ванночка d28 (стыков ванной сваркой) | B44: шт. | C44: ='По осям'!AJ44 | D44: ='По осям'!AM44 | E44: ='По осям'!AP44 | F44: ='По осям'!AJ90 | G44: ='По осям'!AM90 | H44: ='По осям'!AP90 | I44: ='По осям'!AJ136 | J44: ='По осям'!AM136 | K44: ='По осям'!AP136 | L44: =SUM(C44:K44)
A45: Ванночка d25 (стыков ванной сваркой) | B45: шт. | C45: ='По осям'!AJ45 | D45: ='По осям'!AM45 | E45: ='По осям'!AP45 | F45: ='По осям'!AJ91 | G45: ='По осям'!AM91 | H45: ='По осям'!AP91 | I45: ='По осям'!AJ137 | J45: ='По осям'!AM137 | K45: ='По осям'!AP137 | L45: =SUM(C45:K45)
A46: Ванночка d22 (стыков ванной сваркой) | B46: шт. | C46: ='По осям'!AJ46 | D46: ='По осям'!AM46 | E46: ='По осям'!AP46 | F46: ='По осям'!AJ92 | G46: ='По осям'!AM92 | H46: ='По осям'!AP92 | I46: ='По осям'!AJ138 | J46: ='По осям'!AM138 | K46: ='По осям'!AP138 | L46: =SUM(C46:K46)
...

Sheet По осям
A1: Блок 14, ул. Токомбаева — подсчёт арматуры по осям: 1–3 этаж (м.п. → кг) | AJ1: К зап | AK1: К зап бетон
A2: м.п. = SUMIFS из «Ведомости» (этаж, Ø, класс, колонка); Всего = м.п. × кг/м × К зап (как в шаблоне); чистая масса без запаса — отдельной строкой | AJ2: =Исходные!$B$14 | AK2: =Исходные!$B$15
A4: 1 ЭТАЖ | B4: Рамы | S4: Балки | V4: Перекрытие | AB4: Сетки С-1 | AC4: Лестничный марш | AJ4: Колонны, диафрагмы | AM4: Ригели, балки, плита, С-1 | AP4: Лестницы
A5: На отметке -0.050…+3.950 | B5: По оси А | C5: По оси А | D5: По оси А | E5: По оси А | F5: По оси Б | G5: По оси Б | H5: По оси В | I5: По оси В | J5: По оси Г | K5: По оси Г | L5: По оси Г | M5: По оси Г | N5: По оси Г | O5: По оси 1/5 | P5: По оси 2 | Q5: По оси 3 | R5: По оси 4 | S5: Основная | T5: Хомуты | U5: Допник | V5: Основная | W5: Хомуты | X5: Отверстия | Y5: Допник | AA5: Край | AB5: С-1 | AC5: Л1 | AD5: Л2 | AE5: Площадка | AF5: Рама | AG5: Итого: | AH5: Масса ед. кг | AI5: Всего | AJ5: Итого: | AK5: Масса ед. кг | AL5: Всего | AM5: Итого: | AN5: Масса ед. кг | AO5: Всего | AP5: Итого: | AQ5: Масса ед. кг | AR5: Всего
A6: (1 этаж) | B6: Дм-1 | C6: Дм-2 | D6: К 1-1 (3) | E6: Ригель 4-4 | F6: К 1-1 (5) | G6: Ригель 4-4 | H6: К 1-1 (5) | I6: Ригель 4-4 | J6: К 1-1 (2) | K6: Дм-3 | L6: Дм-4 | M6: Дм-5 | N6: Ригель 4-4 | O6: Ригель 5-5 (×2) | P6: Ригель 5-5 | Q6: Ригель 5-5 | R6: Ригель 5-5 | U6: Ø18 L=1200 | W6: Ф-1, шп. | Y6: Низ | Z6: Верх | AA6: сеч.6-6 | AB6: 200 шт | AC6: марш 1 | AD6: марш 2 | AE6: отм. 1.920 | AF6: Лрм-1 | AG6: (м.п.) | AI6: кг | AJ6: (м.п.) | AL6: кг | AM6: (м.п.) | AO6: кг | AP6: (м.п.) | AR6: кг
A7: Арматура, (м.п.)
A8: Диаметр 32 А500С, L=м.п. | B8: =SUMIFS(Ведомость!$N$5:$N$1270,Ведомость!$H$5:$H$1270,32,Ведомость!$I$5:$I$1270,"А500С",Ведомость!$V$5:$V$1270,"Дм-1",Ведомость!$W$5:$W$1270,1) | C8: =SUMIFS(Ведомость!$N$5:$N$1270,Ведомость!$H$5:$H$1270,32,Ведомость!$I$5:$I$1270,"А500С",Ведомость!$V$5:$V$1270,"Дм-2",Ведомость!$W$5:$W$1270,1) | D8: =SUMIFS(Ведомость!$N$5:$N$1270,Ведомость!$H$5:$H$1270,32,Ведомость!$I$5:$I$1270,"А500С",Ведомость!$V$5:$V$1270,"К-А",Ведомость!$W$5:$W$1270,1) | E8: =SUMIFS(Ведомость!$N$5:$N$1270,Ведомость!$H$5:$H$1270,32,Ведомость!$I$5:$I$1270,"А500С",Ведомость!$V$5:$V$1270,"Р-А",Ведомость!$W$5:$W$1270,1) | F8: =SUMIFS(Ведомость!$N$5:$N$1270,Ведомость!$H$5:$H$1270,32,Ведомость!$I$5:$I$1270,"А500С",Ведомость!$V$5:$V$1270,"К-Б",Ведомость!$W$5:$W$1270,1) | G8: =SUMIFS(Ведомость!$N$5:$N$1270,Ведомость!$H$5:$H$1270,32,Ведомость!$I$5:$I$1270,"А500С",Ведомость!$V$5:$V$1270,"Р-Б",Ведомость!$W$5:$W$1270,1) | H8: =SUMIFS(Ведомость!$N$5:$N$1270,Ведомость!$H$5:$H$1270,32,Ведомость!$I$5:$I$1270,"А500С",Ведомость!$V$5:$V$1270,"К-В",Ведомость!$W$5:$W$1270,1) | I8: =SUMIFS(Ведомость!$N$5:$N$1270,Ведомость!$H$5:$H$1270,32,Ведомость!$I$5:$I$1270,"А500С",Ведомость!$V$5:$V$1270,"Р-В",Ведомость!$W$5:$W$1270,1) | J8: =SUMIFS(Ведомость!$N$5:$N$1270,Ведомость!$H$5:$H$1270,32,Ведомость!$I$5:$I$1270,"А500С",Ведомость!$V$5:$V$1270,"К-Г",Ведомость!$W$5:$W$1270,1) | K8: =SUMIFS(Ведомость!$N$5:$N$1270,Ведомость!$H$5:$H$1270,32,Ведомость!$I$5:$I$1270,"А500С",Ведомость!$V$5:$V$1270,"Дм-3",Ведомость!$W$5:$W$1270,1) | L8: =SUMIFS(Ведомость!$N$5:$N$1270,Ведомость!$H$5:$H$1270,32,Ведомость!$I$5:$I$1270,"А500С",Ведомость!$V$5:$V$1270,"Дм-4",Ведомость!$W$5:$W$1270,1) | M8: =SUMIFS(Ведомость!$N$5:$N$1270,Ведомость!$H$5:$H$1270,32,Ведомость!$I$5:$I$1270,"А500С",Ведомость!$V$5:$V$1270,"Дм-5",Ведомость!$W$5:$W$1270,1) | N8: =SUMIFS(Ведомость!$N$5:$N$1270,Ведомость!$H$5:$H$1270,32,Ведомость!$I$5:$I$1270,"А500С",Ведомость!$V$5:$V$1270,"Р-Г",Ведомость!$W$5:$W$1270,1) | O8: =SUMIFS(Ведомость!$N$5:$N$1270,Ведомость!$H$5:$H$1270,32,Ведомость!$I$5:$I$1270,"А500С",Ведомость!$V$5:$V$1270,"Р-1, 5",Ведомость!$W$5:$W$1270,1) | P8: =SUMIFS(Ведомость!$N$5:$N$1270,Ведомость!$H$5:$H$1270,32,Ведомость!$I$5:$I$1270,"А500С",Ведомость!$V$5:$V$1270,"Р-2",Ведомость!$W$5:$W$1270,1) | Q8: =SUMIFS(Ведомость!$N$5:$N$1270,Ведомость!$H$5:$H$1270,32,Ведомость!$I$5:$I$1270,"А500С",Ведомость!$V$5:$V$1270,"Р-3",Ведомость!$W$5:$W$1270,1) | R8: =SUMIFS(Ведомость!$N$5:$N$1270,Ведомость!$H$5:$H$1270,32,Ведомость!$I$5:$I$1270,"А500С",Ведомость!$V$5:$V$1270,"Р-4",Ведомость!$W$5:$W$1270,1) | S8: =SUMIFS(Ведомость!$N$5:$N$1270,Ведомость!$H$5:$H$1270,32,Ведомость!$I$5:$I$1270,"А500С",Ведомость!$V$5:$V$1270,"Б-основная",Ведомость!$W$5:$W$1270,1) | T8: =SUMIFS(Ведомость!$N$5:$N$1270,Ведомость!$H$5:$H$1270,32,Ведомость!$I$5:$I$1270,"А500С",Ведомость!$V$5:$V$1270,"Б-хомуты",Ведомость!$W$5:$W$1270,1) | U8: =SUMIFS(Ведомость!$N$5:$N$1270,Ведомость!$H$5:$H$1270,32,Ведомость!$I$5:$I$1270,"А500С",Ведомость!$V$5:$V$1270,"Б-допник",Ведомость!$W$5:$W$1270,1) | V8: =SUMIFS(Ведомость!$N$5:$N$1270,Ведомость!$H$5:$H$1270,32,Ведомость!$I$5:$I$1270,"А500С",Ведомость!$V$5:$V$1270,"П-сетка",Ведомость!$W$5:$W$1270,1) | W8: =SUMIFS(Ведомость!$N$5:$N$1270,Ведомость!$H$5:$H$1270,32,Ведомость!$I$5:$I$1270,"А500С",Ведомость!$V$5:$V$1270,"П-фикс",Ведомость!$W$5:$W$1270,1) | X8: =SUMIFS(Ведомость!$N$5:$N$1270,Ведомость!$H$5:$H$1270,32,Ведомость!$I$5:$I$1270,"А500С",Ведомость!$V$5:$V$1270,"П-отв",Ведомость!$W$5:$W$1270,1) | Y8: =SUMIFS(Ведомость!$N$5:$N$1270,Ведомость!$H$5:$H$1270,32,Ведомость!$I$5:$I$1270,"А500С",Ведомость!$V$5:$V$1270,"П-доп-низ",Ведомость!$W$5:$W$1270,1) | Z8: =SUMIFS(Ведомость!$N$5:$N$1270,Ведомость!$H$5:$H$1270,32,Ведомость!$I$5:$I$1270,"А500С",Ведомость!$V$5:$V$1270,"П-доп-верх",Ведомость!$W$5:$W$1270,1) | AA8: =SUMIFS(Ведомость!$N$5:$N$1270,Ведомость!$H$5:$H$1270,32,Ведомость!$I$5:$I$1270,"А500С",Ведомость!$V$5:$V$1270,"П-край",Ведомость!$W$5:$W$1270,1) | AB8: =SUMIFS(Ведомость!$N$5:$N$1270,Ведомость!$H$5:$H$1270,32,Ведомость!$I$5:$I$1270,"А500С",Ведомость!$V$5:$V$1270,"С-1",Ведомость!$W$5:$W$1270,1) | AC8: =SUMIFS(Ведомость!$N$5:$N$1270,Ведомость!$H$5:$H$1270,32,Ведомость!$I$5:$I$1270,"А500С",Ведомость!$V$5:$V$1270,"Л1",Ведомость!$W$5:$W$1270,1) | AD8: =SUMIFS(Ведомость!$N$5:$N$1270,Ведомость!$H$5:$H$1270,32,Ведомость!$I$5:$I$1270,"А500С",Ведомость!$V$5:$V$1270,"Л2",Ведомость!$W$5:$W$1270,1) | AE8: =SUMIFS(Ведомость!$N$5:$N$1270,Ведомость!$H$5:$H$1270,32,Ведомость!$I$5:$I$1270,"А500С",Ведомость!$V$5:$V$1270,"Л-пл",Ведомость!$W$5:$W$1270,1) | AF8: =SUMIFS(Ведомость!$N$5:$N$1270,Ведомость!$H$5:$H$1270,32,Ведомость!$I$5:$I$1270,"А500С",Ведомость!$V$5:$V$1270,"Л-рама",Ведомость!$W$5:$W$1270,1) | AG8: =SUM(B8:AF8) | AH8: =IFERROR(INDEX(Исходные!$B$19:$B$31,MATCH(32,Исходные!$A$19:$A$31,0)),0) | AI8: =AG8*AH8*$AJ$2 | AJ8: =SUM(B8:D8,F8,H8,J8:M8) | AK8: =AH8 | AL8: =AJ8*AK8*$AJ$2 | AM8: =SUM(E8,G8,I8,N8:AB8) | AN8: =AH8 | AO8: =AM8*AN8*$AJ$2 | AP8: =SUM(AC8:AF8) | AQ8: =AH8 | AR8: =AP8*AQ8*$AJ$2
A9: Диаметр 28 А500С, L=м.п. | B9: =SUMIFS(Ведомость!$N$5:$N$1270,Ведомость!$H$5:$H$1270,28,Ведомость!$I$5:$I$1270,"А500С",Ведомость!$V$5:$V$1270,"Дм-1",Ведомость!$W$5:$W$1270,1) | C9: =SUMIFS(Ведомость!$N$5:$N$1270,Ведомость!$H$5:$H$1270,28,Ведомость!$I$5:$I$1270,"А500С",Ведомость!$V$5:$V$1270,"Дм-2",Ведомость!$W$5:$W$1270,1) | D9: =SUMIFS(Ведомость!$N$5:$N$1270,Ведомость!$H$5:$H$1270,28,Ведомость!$I$5:$I$1270,"А500С",Ведомость!$V$5:$V$1270,"К-А",Ведомость!$W$5:$W$1270,1) | E9: =SUMIFS(Ведомость!$N$5:$N$1270,Ведомость!$H$5:$H$1270,28,Ведомость!$I$5:$I$1270,"А500С",Ведомость!$V$5:$V$1270,"Р-А",Ведомость!$W$5:$W$1270,1) | F9: =SUMIFS(Ведомость!$N$5:$N$1270,Ведомость!$H$5:$H$1270,28,Ведомость!$I$5:$I$1270,"А500С",Ведомость!$V$5:$V$1270,"К-Б",Ведомость!$W$5:$W$1270,1) | G9: =SUMIFS(Ведомость!$N$5:$N$1270,Ведомость!$H$5:$H$1270,28,Ведомость!$I$5:$I$1270,"А500С",Ведомость!$V$5:$V$1270,"Р-Б",Ведомость!$W$5:$W$1270,1) | H9: =SUMIFS(Ведомость!$N$5:$N$1270,Ведомость!$H$5:$H$1270,28,Ведомость!$I$5:$I$1270,"А500С",Ведомость!$V$5:$V$1270,"К-В",Ведомость!$W$5:$W$1270,1) | I9: =SUMIFS(Ведомость!$N$5:$N$1270,Ведомость!$H$5:$H$1270,28,Ведомость!$I$5:$I$1270,"А500С",Ведомость!$V$5:$V$1270,"Р-В",Ведомость!$W$5:$W$1270,1) | J9: =SUMIFS(Ведомость!$N$5:$N$1270,Ведомость!$H$5:$H$1270,28,Ведомость!$I$5:$I$1270,"А500С",Ведомость!$V$5:$V$1270,"К-Г",Ведомость!$W$5:$W$1270,1) | K9: =SUMIFS(Ведомость!$N$5:$N$1270,Ведомость!$H$5:$H$1270,28,Ведомость!$I$5:$I$1270,"А500С",Ведомость!$V$5:$V$1270,"Дм-3",Ведомость!$W$5:$W$1270,1) | L9: =SUMIFS(Ведомость!$N$5:$N$1270,Ведомость!$H$5:$H$1270,28,Ведомость!$I$5:$I$1270,"А500С",Ведомость!$V$5:$V$1270,"Дм-4",Ведомость!$W$5:$W$1270,1) | M9: =SUMIFS(Ведомость!$N$5:$N$1270,Ведомость!$H$5:$H$1270,28,Ведомость!$I$5:$I$1270,"А500С",Ведомость!$V$5:$V$1270,"Дм-5",Ведомость!$W$5:$W$1270,1) | N9: =SUMIFS(Ведомость!$N$5:$N$1270,Ведомость!$H$5:$H$1270,28,Ведомость!$I$5:$I$1270,"А500С",Ведомость!$V$5:$V$1270,"Р-Г",Ведомость!$W$5:$W$1270,1) | O9: =SUMIFS(Ведомость!$N$5:$N$1270,Ведомость!$H$5:$H$1270,28,Ведомость!$I$5:$I$1270,"А500С",Ведомость!$V$5:$V$1270,"Р-1, 5",Ведомость!$W$5:$W$1270,1) | P9: =SUMIFS(Ведомость!$N$5:$N$1270,Ведомость!$H$5:$H$1270,28,Ведомость!$I$5:$I$1270,"А500С",Ведомость!$V$5:$V$1270,"Р-2",Ведомость!$W$5:$W$1270,1) | Q9: =SUMIFS(Ведомость!$N$5:$N$1270,Ведомость!$H$5:$H$1270,28,Ведомость!$I$5:$I$1270,"А500С",Ведомость!$V$5:$V$1270,"Р-3",Ведомость!$W$5:$W$1270,1) | R9: =SUMIFS(Ведомость!$N$5:$N$1270,Ведомость!$H$5:$H$1270,28,Ведомость!$I$5:$I$1270,"А500С",Ведомость!$V$5:$V$1270,"Р-4",Ведомость!$W$5:$W$1270,1) | S9: =SUMIFS(Ведомость!$N$5:$N$1270,Ведомость!$H$5:$H$1270,28,Ведомость!$I$5:$I$1270,"А500С",Ведомость!$V$5:$V$1270,"Б-основная",Ведомость!$W$5:$W$1270,1) | T9: =SUMIFS(Ведомость!$N$5:$N$1270,Ведомость!$H$5:$H$1270,28,Ведомость!$I$5:$I$1270,"А500С",Ведомость!$V$5:$V$1270,"Б-хомуты",Ведомость!$W$5:$W$1270,1) | U9: =SUMIFS(Ведомость!$N$5:$N$1270,Ведомость!$H$5:$H$1270,28,Ведомость!$I$5:$I$1270,"А500С",Ведомость!$V$5:$V$1270,"Б-допник",Ведомость!$W$5:$W$1270,1) | V9: =SUMIFS(Ведомость!$N$5:$N$1270,Ведомость!$H$5:$H$1270,28,Ведомость!$I$5:$I$1270,"А500С",Ведомость!$V$5:$V$1270,"П-сетка",Ведомость!$W$5:$W$1270,1) | W9: =SUMIFS(Ведомость!$N$5:$N$1270,Ведомость!$H$5:$H$1270,28,Ведомость!$I$5:$I$1270,"А500С",Ведомость!$V$5:$V$1270,"П-фикс",Ведомость!$W$5:$W$1270,1) | X9: =SUMIFS(Ведомость!$N$5:$N$1270,Ведомость!$H$5:$H$1270,28,Ведомость!$I$5:$I$1270,"А500С",Ведомость!$V$5:$V$1270,"П-отв",Ведомость!$W$5:$W$1270,1) | Y9: =SUMIFS(Ведомость!$N$5:$N$1270,Ведомость!$H$5:$H$1270,28,Ведомость!$I$5:$I$1270,"А500С",Ведомость!$V$5:$V$1270,"П-доп-низ",Ведомость!$W$5:$W$1270,1) | Z9: =SUMIFS(Ведомость!$N$5:$N$1270,Ведомость!$H$5:$H$1270,28,Ведомость!$I$5:$I$1270,"А500С",Ведомость!$V$5:$V$1270,"П-доп-верх",Ведомость!$W$5:$W$1270,1) | AA9: =SUMIFS(Ведомость!$N$5:$N$1270,Ведомость!$H$5:$H$1270,28,Ведомость!$I$5:$I$1270,"А500С",Ведомость!$V$5:$V$1270,"П-край",Ведомость!$W$5:$W$1270,1) | AB9: =SUMIFS(Ведомость!$N$5:$N$1270,Ведомость!$H$5:$H$1270,28,Ведомость!$I$5:$I$1270,"А500С",Ведомость!$V$5:$V$1270,"С-1",Ведомость!$W$5:$W$1270,1) | AC9: =SUMIFS(Ведомость!$N$5:$N$1270,Ведомость!$H$5:$H$1270,28,Ведомость!$I$5:$I$1270,"А500С",Ведомость!$V$5:$V$1270,"Л1",Ведомость!$W$5:$W$1270,1) | AD9: =SUMIFS(Ведомость!$N$5:$N$1270,Ведомость!$H$5:$H$1270,28,Ведомость!$I$5:$I$1270,"А500С",Ведомость!$V$5:$V$1270,"Л2",Ведомость!$W$5:$W$1270,1) | AE9: =SUMIFS(Ведомость!$N$5:$N$1270,Ведомость!$H$5:$H$1270,28,Ведомость!$I$5:$I$1270,"А500С",Ведомость!$V$5:$V$1270,"Л-пл",Ведомость!$W$5:$W$1270,1) | AF9: =SUMIFS(Ведомость!$N$5:$N$1270,Ведомость!$H$5:$H$1270,28,Ведомость!$I$5:$I$1270,"А500С",Ведомость!$V$5:$V$1270,"Л-рама",Ведомость!$W$5:$W$1270,1) | AG9: =SUM(B9:AF9) | AH9: =IFERROR(INDEX(Исходные!$B$19:$B$31,MATCH(28,Исходные!$A$19:$A$31,0)),0) | AI9: =AG9*AH9*$AJ$2 | AJ9: =SUM(B9:D9,F9,H9,J9:M9) | AK9: =AH9 | AL9: =AJ9*AK9*$AJ$2 | AM9: =SUM(E9,G9,I9,N9:AB9) | AN9: =AH9 | AO9: =AM9*AN9*$AJ$2 | AP9: =SUM(AC9:AF9) | AQ9: =AH9 | AR9: =AP9*AQ9*$AJ$2
A10: Диаметр 25 А500С, L=м.п. | B10: =SUMIFS(Ведомость!$N$5:$N$1270,Ведомость!$H$5:$H$1270,25,Ведомость!$I$5:$I$1270,"А500С",Ведомость!$V$5:$V$1270,"Дм-1",Ведомость!$W$5:$W$1270,1) | C10: =SUMIFS(Ведомость!$N$5:$N$1270,Ведомость!$H$5:$H$1270,25,Ведомость!$I$5:$I$1270,"А500С",Ведомость!$V$5:$V$1270,"Дм-2",Ведомость!$W$5:$W$1270,1) | D10: =SUMIFS(Ведомость!$N$5:$N$1270,Ведомость!$H$5:$H$1270,25,Ведомость!$I$5:$I$1270,"А500С",Ведомость!$V$5:$V$1270,"К-А",Ведомость!$W$5:$W$1270,1) | E10: =SUMIFS(Ведомость!$N$5:$N$1270,Ведомость!$H$5:$H$1270,25,Ведомость!$I$5:$I$1270,"А500С",Ведомость!$V$5:$V$1270,"Р-А",Ведомость!$W$5:$W$1270,1) | F10: =SUMIFS(Ведомость!$N$5:$N$1270,Ведомость!$H$5:$H$1270,25,Ведомость!$I$5:$I$1270,"А500С",Ведомость!$V$5:$V$1270,"К-Б",Ведомость!$W$5:$W$1270,1) | G10: =SUMIFS(Ведомость!$N$5:$N$1270,Ведомость!$H$5:$H$1270,25,Ведомость!$I$5:$I$1270,"А500С",Ведомость!$V$5:$V$1270,"Р-Б",Ведомость!$W$5:$W$1270,1) | H10: =SUMIFS(Ведомость!$N$5:$N$1270,Ведомость!$H$5:$H$1270,25,Ведомость!$I$5:$I$1270,"А500С",Ведомость!$V$5:$V$1270,"К-В",Ведомость!$W$5:$W$1270,1) | I10: =SUMIFS(Ведомость!$N$5:$N$1270,Ведомость!$H$5:$H$1270,25,Ведомость!$I$5:$I$1270,"А500С",Ведомость!$V$5:$V$1270,"Р-В",Ведомость!$W$5:$W$1270,1) | J10: =SUMIFS(Ведомость!$N$5:$N$1270,Ведомость!$H$5:$H$1270,25,Ведомость!$I$5:$I$1270,"А500С",Ведомость!$V$5:$V$1270,"К-Г",Ведомость!$W$5:$W$1270,1) | K10: =SUMIFS(Ведомость!$N$5:$N$1270,Ведомость!$H$5:$H$1270,25,Ведомость!$I$5:$I$1270,"А500С",Ведомость!$V$5:$V$1270,"Дм-3",Ведомость!$W$5:$W$1270,1) | L10: =SUMIFS(Ведомость!$N$5:$N$1270,Ведомость!$H$5:$H$1270,25,Ведомость!$I$5:$I$1270,"А500С",Ведомость!$V$5:$V$1270,"Дм-4",Ведомость!$W$5:$W$1270,1) | M10: =SUMIFS(Ведомость!$N$5:$N$1270,Ведомость!$H$5:$H$1270,25,Ведомость!$I$5:$I$1270,"А500С",Ведомость!$V$5:$V$1270,"Дм-5",Ведомость!$W$5:$W$1270,1) | N10: =SUMIFS(Ведомость!$N$5:$N$1270,Ведомость!$H$5:$H$1270,25,Ведомость!$I$5:$I$1270,"А500С",Ведомость!$V$5:$V$1270,"Р-Г",Ведомость!$W$5:$W$1270,1) | O10: =SUMIFS(Ведомость!$N$5:$N$1270,Ведомость!$H$5:$H$1270,25,Ведомость!$I$5:$I$1270,"А500С",Ведомость!$V$5:$V$1270,"Р-1, 5",Ведомость!$W$5:$W$1270,1) | P10: =SUMIFS(Ведомость!$N$5:$N$1270,Ведомость!$H$5:$H$1270,25,Ведомость!$I$5:$I$1270,"А500С",Ведомость!$V$5:$V$1270,"Р-2",Ведомость!$W$5:$W$1270,1) | Q10: =SUMIFS(Ведомость!$N$5:$N$1270,Ведомость!$H$5:$H$1270,25,Ведомость!$I$5:$I$1270,"А500С",Ведомость!$V$5:$V$1270,"Р-3",Ведомость!$W$5:$W$1270,1) | R10: =SUMIFS(Ведомость!$N$5:$N$1270,Ведомость!$H$5:$H$1270,25,Ведомость!$I$5:$I$1270,"А500С",Ведомость!$V$5:$V$1270,"Р-4",Ведомость!$W$5:$W$1270,1) | S10: =SUMIFS(Ведомость!$N$5:$N$1270,Ведомость!$H$5:$H$1270,25,Ведомость!$I$5:$I$1270,"А500С",Ведомость!$V$5:$V$1270,"Б-основная",Ведомость!$W$5:$W$1270,1) | T10: =SUMIFS(Ведомость!$N$5:$N$1270,Ведомость!$H$5:$H$1270,25,Ведомость!$I$5:$I$1270,"А500С",Ведомость!$V$5:$V$1270,"Б-хомуты",Ведомость!$W$5:$W$1270,1) | U10: =SUMIFS(Ведомость!$N$5:$N$1270,Ведомость!$H$5:$H$1270,25,Ведомость!$I$5:$I$1270,"А500С",Ведомость!$V$5:$V$1270,"Б-допник",Ведомость!$W$5:$W$1270,1) | V10: =SUMIFS(Ведомость!$N$5:$N$1270,Ведомость!$H$5:$H$1270,25,Ведомость!$I$5:$I$1270,"А500С",Ведомость!$V$5:$V$1270,"П-сетка",Ведомость!$W$5:$W$1270,1) | W10: =SUMIFS(Ведомость!$N$5:$N$1270,Ведомость!$H$5:$H$1270,25,Ведомость!$I$5:$I$1270,"А500С",Ведомость!$V$5:$V$1270,"П-фикс",Ведомость!$W$5:$W$1270,1) | X10: =SUMIFS(Ведомость!$N$5:$N$1270,Ведомость!$H$5:$H$1270,25,Ведомость!$I$5:$I$1270,"А500С",Ведомость!$V$5:$V$1270,"П-отв",Ведомость!$W$5:$W$1270,1) | Y10: =SUMIFS(Ведомость!$N$5:$N$1270,Ведомость!$H$5:$H$1270,25,Ведомость!$I$5:$I$1270,"А500С",Ведомость!$V$5:$V$1270,"П-доп-низ",Ведомость!$W$5:$W$1270,1) | Z10: =SUMIFS(Ведомость!$N$5:$N$1270,Ведомость!$H$5:$H$1270,25,Ведомость!$I$5:$I$1270,"А500С",Ведомость!$V$5:$V$1270,"П-доп-верх",Ведомость!$W$5:$W$1270,1) | AA10: =SUMIFS(Ведомость!$N$5:$N$1270,Ведомость!$H$5:$H$1270,25,Ведомость!$I$5:$I$1270,"А500С",Ведомость!$V$5:$V$1270,"П-край",Ведомость!$W$5:$W$1270,1) | AB10: =SUMIFS(Ведомость!$N$5:$N$1270,Ведомость!$H$5:$H$1270,25,Ведомость!$I$5:$I$1270,"А500С",Ведомость!$V$5:$V$1270,"С-1",Ведомость!$W$5:$W$1270,1) | AC10: =SUMIFS(Ведомость!$N$5:$N$1270,Ведомость!$H$5:$H$1270,25,Ведомость!$I$5:$I$1270,"А500С",Ведомость!$V$5:$V$1270,"Л1",Ведомость!$W$5:$W$1270,1) | AD10: =SUMIFS(Ведомость!$N$5:$N$1270,Ведомость!$H$5:$H$1270,25,Ведомость!$I$5:$I$1270,"А500С",Ведомость!$V$5:$V$1270,"Л2",Ведомость!$W$5:$W$1270,1) | AE10: =SUMIFS(Ведомость!$N$5:$N$1270,Ведомость!$H$5:$H$1270,25,Ведомость!$I$5:$I$1270,"А500С",Ведомость!$V$5:$V$1270,"Л-пл",Ведомость!$W$5:$W$1270,1) | AF10: =SUMIFS(Ведомость!$N$5:$N$1270,Ведомость!$H$5:$H$1270,25,Ведомость!$I$5:$I$1270,"А500С",Ведомость!$V$5:$V$1270,"Л-рама",Ведомость!$W$5:$W$1270,1) | AG10: =SUM(B10:AF10) | AH10: =IFERROR(INDEX(Исходные!$B$19:$B$31,MATCH(25,Исходные!$A$19:$A$31,0)),0) | AI10: =AG10*AH10*$AJ$2 | AJ10: =SUM(B10:D10,F10,H10,J10:M10) | AK10: =AH10 | AL10: =AJ10*AK10*$AJ$2 | AM10: =SUM(E10,G10,I10,N10:AB10) | AN10: =AH10 | AO10: =AM10*AN10*$AJ$2 | AP10: =SUM(AC10:AF10) | AQ10: =AH10 | AR10: =AP10*AQ10*$AJ$2
A11: Диаметр 22 А500С, L=м.п. | B11: =SUMIFS(Ведомость!$N$5:$N$1270,Ведомость!$H$5:$H$1270,22,Ведомость!$I$5:$I$1270,"А500С",Ведомость!$V$5:$V$1270,"Дм-1",Ведомость!$W$5:$W$1270,1) | C11: =SUMIFS(Ведомость!$N$5:$N$1270,Ведомость!$H$5:$H$1270,22,Ведомость!$I$5:$I$1270,"А500С",Ведомость!$V$5:$V$1270,"Дм-2",Ведомость!$W$5:$W$1270,1) | D11: =SUMIFS(Ведомость!$N$5:$N$1270,Ведомость!$H$5:$H$1270,22,Ведомость!$I$5:$I$1270,"А500С",Ведомость!$V$5:$V$1270,"К-А",Ведомость!$W$5:$W$1270,1) | E11: =SUMIFS(Ведомость!$N$5:$N$1270,Ведомость!$H$5:$H$1270,22,Ведомость!$I$5:$I$1270,"А500С",Ведомость!$V$5:$V$1270,"Р-А",Ведомость!$W$5:$W$1270,1) | F11: =SUMIFS(Ведомость!$N$5:$N$1270,Ведомость!$H$5:$H$1270,22,Ведомость!$I$5:$I$1270,"А500С",Ведомость!$V$5:$V$1270,"К-Б",Ведомость!$W$5:$W$1270,1) | G11: =SUMIFS(Ведомость!$N$5:$N$1270,Ведомость!$H$5:$H$1270,22,Ведомость!$I$5:$I$1270,"А500С",Ведомость!$V$5:$V$1270,"Р-Б",Ведомость!$W$5:$W$1270,1) | H11: =SUMIFS(Ведомость!$N$5:$N$1270,Ведомость!$H$5:$H$1270,22,Ведомость!$I$5:$I$1270,"А500С",Ведомость!$V$5:$V$1270,"К-В",Ведомость!$W$5:$W$1270,1) | I11: =SUMIFS(Ведомость!$N$5:$N$1270,Ведомость!$H$5:$H$1270,22,Ведомость!$I$5:$I$1270,"А500С",Ведомость!$V$5:$V$1270,"Р-В",Ведомость!$W$5:$W$1270,1) | J11: =SUMIFS(Ведомость!$N$5:$N$1270,Ведомость!$H$5:$H$1270,22,Ведомость!$I$5:$I$1270,"А500С",Ведомость!$V$5:$V$1270,"К-Г",Ведомость!$W$5:$W$1270,1) | K11: =SUMIFS(Ведомость!$N$5:$N$1270,Ведомость!$H$5:$H$1270,22,Ведомость!$I$5:$I$1270,"А500С",Ведомость!$V$5:$V$1270,"Дм-3",Ведомость!$W$5:$W$1270,1) | L11: =SUMIFS(Ведомость!$N$5:$N$1270,Ведомость!$H$5:$H$1270,22,Ведомость!$I$5:$I$1270,"А500С",Ведомость!$V$5:$V$1270,"Дм-4",Ведомость!$W$5:$W$1270,1) | M11: =SUMIFS(Ведомость!$N$5:$N$1270,Ведомость!$H$5:$H$1270,22,Ведомость!$I$5:$I$1270,"А500С",Ведомость!$V$5:$V$1270,"Дм-5",Ведомость!$W$5:$W$1270,1) | N11: =SUMIFS(Ведомость!$N$5:$N$1270,Ведомость!$H$5:$H$1270,22,Ведомость!$I$5:$I$1270,"А500С",Ведомость!$V$5:$V$1270,"Р-Г",Ведомость!$W$5:$W$1270,1) | O11: =SUMIFS(Ведомость!$N$5:$N$1270,Ведомость!$H$5:$H$1270,22,Ведомость!$I$5:$I$1270,"А500С",Ведомость!$V$5:$V$1270,"Р-1, 5",Ведомость!$W$5:$W$1270,1) | P11: =SUMIFS(Ведомость!$N$5:$N$1270,Ведомость!$H$5:$H$1270,22,Ведомость!$I$5:$I$1270,"А500С",Ведомость!$V$5:$V$1270,"Р-2",Ведомость!$W$5:$W$1270,1) | Q11: =SUMIFS(Ведомость!$N$5:$N$1270,Ведомость!$H$5:$H$1270,22,Ведомость!$I$5:$I$1270,"А500С",Ведомость!$V$5:$V$1270,"Р-3",Ведомость!$W$5:$W$1270,1) | R11: =SUMIFS(Ведомость!$N$5:$N$1270,Ведомость!$H$5:$H$1270,22,Ведомость!$I$5:$I$1270,"А500С",Ведомость!$V$5:$V$1270,"Р-4",Ведомость!$W$5:$W$1270,1) | S11: =SUMIFS(Ведомость!$N$5:$N$1270,Ведомость!$H$5:$H$1270,22,Ведомость!$I$5:$I$1270,"А500С",Ведомость!$V$5:$V$1270,"Б-основная",Ведомость!$W$5:$W$1270,1) | T11: =SUMIFS(Ведомость!$N$5:$N$1270,Ведомость!$H$5:$H$1270,22,Ведомость!$I$5:$I$1270,"А500С",Ведомость!$V$5:$V$1270,"Б-хомуты",Ведомость!$W$5:$W$1270,1) | U11: =SUMIFS(Ведомость!$N$5:$N$1270,Ведомость!$H$5:$H$1270,22,Ведомость!$I$5:$I$1270,"А500С",Ведомость!$V$5:$V$1270,"Б-допник",Ведомость!$W$5:$W$1270,1) | V11: =SUMIFS(Ведомость!$N$5:$N$1270,Ведомость!$H$5:$H$1270,22,Ведомость!$I$5:$I$1270,"А500С",Ведомость!$V$5:$V$1270,"П-сетка",Ведомость!$W$5:$W$1270,1) | W11: =SUMIFS(Ведомость!$N$5:$N$1270,Ведомость!$H$5:$H$1270,22,Ведомость!$I$5:$I$1270,"А500С",Ведомость!$V$5:$V$1270,"П-фикс",Ведомость!$W$5:$W$1270,1) | X11: =SUMIFS(Ведомость!$N$5:$N$1270,Ведомость!$H$5:$H$1270,22,Ведомость!$I$5:$I$1270,"А500С",Ведомость!$V$5:$V$1270,"П-отв",Ведомость!$W$5:$W$1270,1) | Y11: =SUMIFS(Ведомость!$N$5:$N$1270,Ведомость!$H$5:$H$1270,22,Ведомость!$I$5:$I$1270,"А500С",Ведомость!$V$5:$V$1270,"П-доп-низ",Ведомость!$W$5:$W$1270,1) | Z11: =SUMIFS(Ведомость!$N$5:$N$1270,Ведомость!$H$5:$H$1270,22,Ведомость!$I$5:$I$1270,"А500С",Ведомость!$V$5:$V$1270,"П-доп-верх",Ведомость!$W$5:$W$1270,1) | AA11: =SUMIFS(Ведомость!$N$5:$N$1270,Ведомость!$H$5:$H$1270,22,Ведомость!$I$5:$I$1270,"А500С",Ведомость!$V$5:$V$1270,"П-край",Ведомость!$W$5:$W$1270,1) | AB11: =SUMIFS(Ведомость!$N$5:$N$1270,Ведомость!$H$5:$H$1270,22,Ведомость!$I$5:$I$1270,"А500С",Ведомость!$V$5:$V$1270,"С-1",Ведомость!$W$5:$W$1270,1) | AC11: =SUMIFS(Ведомость!$N$5:$N$1270,Ведомость!$H$5:$H$1270,22,Ведомость!$I$5:$I$1270,"А500С",Ведомость!$V$5:$V$1270,"Л1",Ведомость!$W$5:$W$1270,1) | AD11: =SUMIFS(Ведомость!$N$5:$N$1270,Ведомость!$H$5:$H$1270,22,Ведомость!$I$5:$I$1270,"А500С",Ведомость!$V$5:$V$1270,"Л2",Ведомость!$W$5:$W$1270,1) | AE11: =SUMIFS(Ведомость!$N$5:$N$1270,Ведомость!$H$5:$H$1270,22,Ведомость!$I$5:$I$1270,"А500С",Ведомость!$V$5:$V$1270,"Л-пл",Ведомость!$W$5:$W$1270,1) | AF11: =SUMIFS(Ведомость!$N$5:$N$1270,Ведомость!$H$5:$H$1270,22,Ведомость!$I$5:$I$1270,"А500С",Ведомость!$V$5:$V$1270,"Л-рама",Ведомость!$W$5:$W$1270,1) | AG11: =SUM(B11:AF11) | AH11: =IFERROR(INDEX(Исходные!$B$19:$B$31,MATCH(22,Исходные!$A$19:$A$31,0)),0) | AI11: =AG11*AH11*$AJ$2 | AJ11: =SUM(B11:D11,F11,H11,J11:M11) | AK11: =AH11 | AL11: =AJ11*AK11*$AJ$2 | AM11: =SUM(E11,G11,I11,N11:AB11) | AN11: =AH11 | AO11: =AM11*AN11*$AJ$2 | AP11: =SUM(AC11:AF11) | AQ11: =AH11 | AR11: =AP11*AQ11*$AJ$2
A12: Диаметр 20 А500С, L=м.п. | B12: =SUMIFS(Ведомость!$N$5:$N$1270,Ведомость!$H$5:$H$1270,20,Ведомость!$I$5:$I$1270,"А500С",Ведомость!$V$5:$V$1270,"Дм-1",Ведомость!$W$5:$W$1270,1) | C12: =SUMIFS(Ведомость!$N$5:$N$1270,Ведомость!$H$5:$H$1270,20,Ведомость!$I$5:$I$1270,"А500С",Ведомость!$V$5:$V$1270,"Дм-2",Ведомость!$W$5:$W$1270,1) | D12: =SUMIFS(Ведомость!$N$5:$N$1270,Ведомость!$H$5:$H$1270,20,Ведомость!$I$5:$I$1270,"А500С",Ведомость!$V$5:$V$1270,"К-А",Ведомость!$W$5:$W$1270,1) | E12: =SUMIFS(Ведомость!$N$5:$N$1270,Ведомость!$H$5:$H$1270,20,Ведомость!$I$5:$I$1270,"А500С",Ведомость!$V$5:$V$1270,"Р-А",Ведомость!$W$5:$W$1270,1) | F12: =SUMIFS(Ведомость!$N$5:$N$1270,Ведомость!$H$5:$H$1270,20,Ведомость!$I$5:$I$1270,"А500С",Ведомость!$V$5:$V$1270,"К-Б",Ведомость!$W$5:$W$1270,1) | G12: =SUMIFS(Ведомость!$N$5:$N$1270,Ведомость!$H$5:$H$1270,20,Ведомость!$I$5:$I$1270,"А500С",Ведомость!$V$5:$V$1270,"Р-Б",Ведомость!$W$5:$W$1270,1) | H12: =SUMIFS(Ведомость!$N$5:$N$1270,Ведомость!$H$5:$H$1270,20,Ведомость!$I$5:$I$1270,"А500С",Ведомость!$V$5:$V$1270,"К-В",Ведомость!$W$5:$W$1270,1) | I12: =SUMIFS(Ведомость!$N$5:$N$1270,Ведомость!$H$5:$H$1270,20,Ведомость!$I$5:$I$1270,"А500С",Ведомость!$V$5:$V$1270,"Р-В",Ведомость!$W$5:$W$1270,1) | J12: =SUMIFS(Ведомость!$N$5:$N$1270,Ведомость!$H$5:$H$1270,20,Ведомость!$I$5:$I$1270,"А500С",Ведомость!$V$5:$V$1270,"К-Г",Ведомость!$W$5:$W$1270,1) | K12: =SUMIFS(Ведомость!$N$5:$N$1270,Ведомость!$H$5:$H$1270,20,Ведомость!$I$5:$I$1270,"А500С",Ведомость!$V$5:$V$1270,"Дм-3",Ведомость!$W$5:$W$1270,1) | L12: =SUMIFS(Ведомость!$N$5:$N$1270,Ведомость!$H$5:$H$1270,20,Ведомость!$I$5:$I$1270,"А500С",Ведомость!$V$5:$V$1270,"Дм-4",Ведомость!$W$5:$W$1270,1) | M12: =SUMIFS(Ведомость!$N$5:$N$1270,Ведомость!$H$5:$H$1270,20,Ведомость!$I$5:$I$1270,"А500С",Ведомость!$V$5:$V$1270,"Дм-5",Ведомость!$W$5:$W$1270,1) | N12: =SUMIFS(Ведомость!$N$5:$N$1270,Ведомость!$H$5:$H$1270,20,Ведомость!$I$5:$I$1270,"А500С",Ведомость!$V$5:$V$1270,"Р-Г",Ведомость!$W$5:$W$1270,1) | O12: =SUMIFS(Ведомость!$N$5:$N$1270,Ведомость!$H$5:$H$1270,20,Ведомость!$I$5:$I$1270,"А500С",Ведомость!$V$5:$V$1270,"Р-1, 5",Ведомость!$W$5:$W$1270,1) | P12: =SUMIFS(Ведомость!$N$5:$N$1270,Ведомость!$H$5:$H$1270,20,Ведомость!$I$5:$I$1270,"А500С",Ведомость!$V$5:$V$1270,"Р-2",Ведомость!$W$5:$W$1270,1) | Q12: =SUMIFS(Ведомость!$N$5:$N$1270,Ведомость!$H$5:$H$1270,20,Ведомость!$I$5:$I$1270,"А500С",Ведомость!$V$5:$V$1270,"Р-3",Ведомость!$W$5:$W$1270,1) | R12: =SUMIFS(Ведомость!$N$5:$N$1270,Ведомость!$H$5:$H$1270,20,Ведомость!$I$5:$I$1270,"А500С",Ведомость!$V$5:$V$1270,"Р-4",Ведомость!$W$5:$W$1270,1) | S12: =SUMIFS(Ведомость!$N$5:$N$1270,Ведомость!$H$5:$H$1270,20,Ведомость!$I$5:$I$1270,"А500С",Ведомость!$V$5:$V$1270,"Б-основная",Ведомость!$W$5:$W$1270,1) | T12: =SUMIFS(Ведомость!$N$5:$N$1270,Ведомость!$H$5:$H$1270,20,Ведомость!$I$5:$I$1270,"А500С",Ведомость!$V$5:$V$1270,"Б-хомуты",Ведомость!$W$5:$W$1270,1) | U12: =SUMIFS(Ведомость!$N$5:$N$1270,Ведомость!$H$5:$H$1270,20,Ведомость!$I$5:$I$1270,"А500С",Ведомость!$V$5:$V$1270,"Б-допник",Ведомость!$W$5:$W$1270,1) | V12: =SUMIFS(Ведомость!$N$5:$N$1270,Ведомость!$H$5:$H$1270,20,Ведомость!$I$5:$I$1270,"А500С",Ведомость!$V$5:$V$1270,"П-сетка",Ведомость!$W$5:$W$1270,1) | W12: =SUMIFS(Ведомость!$N$5:$N$1270,Ведомость!$H$5:$H$1270,20,Ведомость!$I$5:$I$1270,"А500С",Ведомость!$V$5:$V$1270,"П-фикс",Ведомость!$W$5:$W$1270,1) | X12: =SUMIFS(Ведомость!$N$5:$N$1270,Ведомость!$H$5:$H$1270,20,Ведомость!$I$5:$I$1270,"А500С",Ведомость!$V$5:$V$1270,"П-отв",Ведомость!$W$5:$W$1270,1) | Y12: =SUMIFS(Ведомость!$N$5:$N$1270,Ведомость!$H$5:$H$1270,20,Ведомость!$I$5:$I$1270,"А500С",Ведомость!$V$5:$V$1270,"П-доп-низ",Ведомость!$W$5:$W$1270,1) | Z12: =SUMIFS(Ведомость!$N$5:$N$1270,Ведомость!$H$5:$H$1270,20,Ведомость!$I$5:$I$1270,"А500С",Ведомость!$V$5:$V$1270,"П-доп-верх",Ведомость!$W$5:$W$1270,1) | AA12: =SUMIFS(Ведомость!$N$5:$N$1270,Ведомость!$H$5:$H$1270,20,Ведомость!$I$5:$I$1270,"А500С",Ведомость!$V$5:$V$1270,"П-край",Ведомость!$W$5:$W$1270,1) | AB12: =SUMIFS(Ведомость!$N$5:$N$1270,Ведомость!$H$5:$H$1270,20,Ведомость!$I$5:$I$1270,"А500С",Ведомость!$V$5:$V$1270,"С-1",Ведомость!$W$5:$W$1270,1) | AC12: =SUMIFS(Ведомость!$N$5:$N$1270,Ведомость!$H$5:$H$1270,20,Ведомость!$I$5:$I$1270,"А500С",Ведомость!$V$5:$V$1270,"Л1",Ведомость!$W$5:$W$1270,1) | AD12: =SUMIFS(Ведомость!$N$5:$N$1270,Ведомость!$H$5:$H$1270,20,Ведомость!$I$5:$I$1270,"А500С",Ведомость!$V$5:$V$1270,"Л2",Ведомость!$W$5:$W$1270,1) | AE12: =SUMIFS(Ведомость!$N$5:$N$1270,Ведомость!$H$5:$H$1270,20,Ведомость!$I$5:$I$1270,"А500С",Ведомость!$V$5:$V$1270,"Л-пл",Ведомость!$W$5:$W$1270,1) | AF12: =SUMIFS(Ведомость!$N$5:$N$1270,Ведомость!$H$5:$H$1270,20,Ведомость!$I$5:$I$1270,"А500С",Ведомость!$V$5:$V$1270,"Л-рама",Ведомость!$W$5:$W$1270,1) | AG12: =SUM(B12:AF12) | AH12: =IFERROR(INDEX(Исходные!$B$19:$B$31,MATCH(20,Исходные!$A$19:$A$31,0)),0) | AI12: =AG12*AH12*$AJ$2 | AJ12: =SUM(B12:D12,F12,H12,J12:M12) | AK12: =AH12 | AL12: =AJ12*AK12*$AJ$2 | AM12: =SUM(E12,G12,I12,N12:AB12) | AN12: =AH12 | AO12: =AM12*AN12*$AJ$2 | AP12: =SUM(AC12:AF12) | AQ12: =AH12 | AR12: =AP12*AQ12*$AJ$2
A13: Диаметр 18 А500С, L=м.п. | B13: =SUMIFS(Ведомость!$N$5:$N$1270,Ведомость!$H$5:$H$1270,18,Ведомость!$I$5:$I$1270,"А500С",Ведомость!$V$5:$V$1270,"Дм-1",Ведомость!$W$5:$W$1270,1) | C13: =SUMIFS(Ведомость!$N$5:$N$1270,Ведомость!$H$5:$H$1270,18,Ведомость!$I$5:$I$1270,"А500С",Ведомость!$V$5:$V$1270,"Дм-2",Ведомость!$W$5:$W$1270,1) | D13: =SUMIFS(Ведомость!$N$5:$N$1270,Ведомость!$H$5:$H$1270,18,Ведомость!$I$5:$I$1270,"А500С",Ведомость!$V$5:$V$1270,"К-А",Ведомость!$W$5:$W$1270,1) | E13: =SUMIFS(Ведомость!$N$5:$N$1270,Ведомость!$H$5:$H$1270,18,Ведомость!$I$5:$I$1270,"А500С",Ведомость!$V$5:$V$1270,"Р-А",Ведомость!$W$5:$W$1270,1) | F13: =SUMIFS(Ведомость!$N$5:$N$1270,Ведомость!$H$5:$H$1270,18,Ведомость!$I$5:$I$1270,"А500С",Ведомость!$V$5:$V$1270,"К-Б",Ведомость!$W$5:$W$1270,1) | G13: =SUMIFS(Ведомость!$N$5:$N$1270,Ведомость!$H$5:$H$1270,18,Ведомость!$I$5:$I$1270,"А500С",Ведомость!$V$5:$V$1270,"Р-Б",Ведомость!$W$5:$W$1270,1) | H13: =SUMIFS(Ведомость!$N$5:$N$1270,Ведомость!$H$5:$H$1270,18,Ведомость!$I$5:$I$1270,"А500С",Ведомость!$V$5:$V$1270,"К-В",Ведомость!$W$5:$W$1270,1) | I13: =SUMIFS(Ведомость!$N$5:$N$1270,Ведомость!$H$5:$H$1270,18,Ведомость!$I$5:$I$1270,"А500С",Ведомость!$V$5:$V$1270,"Р-В",Ведомость!$W$5:$W$1270,1) | J13: =SUMIFS(Ведомость!$N$5:$N$1270,Ведомость!$H$5:$H$1270,18,Ведомость!$I$5:$I$1270,"А500С",Ведомость!$V$5:$V$1270,"К-Г",Ведомость!$W$5:$W$1270,1) | K13: =SUMIFS(Ведомость!$N$5:$N$1270,Ведомость!$H$5:$H$1270,18,Ведомость!$I$5:$I$1270,"А500С",Ведомость!$V$5:$V$1270,"Дм-3",Ведомость!$W$5:$W$1270,1) | L13: =SUMIFS(Ведомость!$N$5:$N$1270,Ведомость!$H$5:$H$1270,18,Ведомость!$I$5:$I$1270,"А500С",Ведомость!$V$5:$V$1270,"Дм-4",Ведомость!$W$5:$W$1270,1) | M13: =SUMIFS(Ведомость!$N$5:$N$1270,Ведомость!$H$5:$H$1270,18,Ведомость!$I$5:$I$1270,"А500С",Ведомость!$V$5:$V$1270,"Дм-5",Ведомость!$W$5:$W$1270,1) | N13: =SUMIFS(Ведомость!$N$5:$N$1270,Ведомость!$H$5:$H$1270,18,Ведомость!$I$5:$I$1270,"А500С",Ведомость!$V$5:$V$1270,"Р-Г",Ведомость!$W$5:$W$1270,1) | O13: =SUMIFS(Ведомость!$N$5:$N$1270,Ведомость!$H$5:$H$1270,18,Ведомость!$I$5:$I$1270,"А500С",Ведомость!$V$5:$V$1270,"Р-1, 5",Ведомость!$W$5:$W$1270,1) | P13: =SUMIFS(Ведомость!$N$5:$N$1270,Ведомость!$H$5:$H$1270,18,Ведомость!$I$5:$I$1270,"А500С",Ведомость!$V$5:$V$1270,"Р-2",Ведомость!$W$5:$W$1270,1) | Q13: =SUMIFS(Ведомость!$N$5:$N$1270,Ведомость!$H$5:$H$1270,18,Ведомость!$I$5:$I$1270,"А500С",Ведомость!$V$5:$V$1270,"Р-3",Ведомость!$W$5:$W$1270,1) | R13: =SUMIFS(Ведомость!$N$5:$N$1270,Ведомость!$H$5:$H$1270,18,Ведомость!$I$5:$I$1270,"А500С",Ведомость!$V$5:$V$1270,"Р-4",Ведомость!$W$5:$W$1270,1) | S13: =SUMIFS(Ведомость!$N$5:$N$1270,Ведомость!$H$5:$H$1270,18,Ведомость!$I$5:$I$1270,"А500С",Ведомость!$V$5:$V$1270,"Б-основная",Ведомость!$W$5:$W$1270,1) | T13: =SUMIFS(Ведомость!$N$5:$N$1270,Ведомость!$H$5:$H$1270,18,Ведомость!$I$5:$I$1270,"А500С",Ведомость!$V$5:$V$1270,"Б-хомуты",Ведомость!$W$5:$W$1270,1) | U13: =SUMIFS(Ведомость!$N$5:$N$1270,Ведомость!$H$5:$H$1270,18,Ведомость!$I$5:$I$1270,"А500С",Ведомость!$V$5:$V$1270,"Б-допник",Ведомость!$W$5:$W$1270,1) | V13: =SUMIFS(Ведомость!$N$5:$N$1270,Ведомость!$H$5:$H$1270,18,Ведомость!$I$5:$I$1270,"А500С",Ведомость!$V$5:$V$1270,"П-сетка",Ведомость!$W$5:$W$1270,1) | W13: =SUMIFS(Ведомость!$N$5:$N$1270,Ведомость!$H$5:$H$1270,18,Ведомость!$I$5:$I$1270,"А500С",Ведомость!$V$5:$V$1270,"П-фикс",Ведомость!$W$5:$W$1270,1) | X13: =SUMIFS(Ведомость!$N$5:$N$1270,Ведомость!$H$5:$H$1270,18,Ведомость!$I$5:$I$1270,"А500С",Ведомость!$V$5:$V$1270,"П-отв",Ведомость!$W$5:$W$1270,1) | Y13: =SUMIFS(Ведомость!$N$5:$N$1270,Ведомость!$H$5:$H$1270,18,Ведомость!$I$5:$I$1270,"А500С",Ведомость!$V$5:$V$1270,"П-доп-низ",Ведомость!$W$5:$W$1270,1) | Z13: =SUMIFS(Ведомость!$N$5:$N$1270,Ведомость!$H$5:$H$1270,18,Ведомость!$I$5:$I$1270,"А500С",Ведомость!$V$5:$V$1270,"П-доп-верх",Ведомость!$W$5:$W$1270,1) | AA13: =SUMIFS(Ведомость!$N$5:$N$1270,Ведомость!$H$5:$H$1270,18,Ведомость!$I$5:$I$1270,"А500С",Ведомость!$V$5:$V$1270,"П-край",Ведомость!$W$5:$W$1270,1) | AB13: =SUMIFS(Ведомость!$N$5:$N$1270,Ведомость!$H$5:$H$1270,18,Ведомость!$I$5:$I$1270,"А500С",Ведомость!$V$5:$V$1270,"С-1",Ведомость!$W$5:$W$1270,1) | AC13: =SUMIFS(Ведомость!$N$5:$N$1270,Ведомость!$H$5:$H$1270,18,Ведомость!$I$5:$I$1270,"А500С",Ведомость!$V$5:$V$1270,"Л1",Ведомость!$W$5:$W$1270,1) | AD13: =SUMIFS(Ведомость!$N$5:$N$1270,Ведомость!$H$5:$H$1270,18,Ведомость!$I$5:$I$1270,"А500С",Ведомость!$V$5:$V$1270,"Л2",Ведомость!$W$5:$W$1270,1) | AE13: =SUMIFS(Ведомость!$N$5:$N$1270,Ведомость!$H$5:$H$1270,18,Ведомость!$I$5:$I$1270,"А500С",Ведомость!$V$5:$V$1270,"Л-пл",Ведомость!$W$5:$W$1270,1) | AF13: =SUMIFS(Ведомость!$N$5:$N$1270,Ведомость!$H$5:$H$1270,18,Ведомость!$I$5:$I$1270,"А500С",Ведомость!$V$5:$V$1270,"Л-рама",Ведомость!$W$5:$W$1270,1) | AG13: =SUM(B13:AF13) | AH13: =IFERROR(INDEX(Исходные!$B$19:$B$31,MATCH(18,Исходные!$A$19:$A$31,0)),0) | AI13: =AG13*AH13*$AJ$2 | AJ13: =SUM(B13:D13,F13,H13,J13:M13) | AK13: =AH13 | AL13: =AJ13*AK13*$AJ$2 | AM13: =SUM(E13,G13,I13,N13:AB13) | AN13: =AH13 | AO13: =AM13*AN13*$AJ$2 | AP13: =SUM(AC13:AF13) | AQ13: =AH13 | AR13: =AP13*AQ13*$AJ$2
A14: Диаметр 16 А500С, L=м.п. | B14: =SUMIFS(Ведомость!$N$5:$N$1270,Ведомость!$H$5:$H$1270,16,Ведомость!$I$5:$I$1270,"А500С",Ведомость!$V$5:$V$1270,"Дм-1",Ведомость!$W$5:$W$1270,1) | C14: =SUMIFS(Ведомость!$N$5:$N$1270,Ведомость!$H$5:$H$1270,16,Ведомость!$I$5:$I$1270,"А500С",Ведомость!$V$5:$V$1270,"Дм-2",Ведомость!$W$5:$W$1270,1) | D14: =SUMIFS(Ведомость!$N$5:$N$1270,Ведомость!$H$5:$H$1270,16,Ведомость!$I$5:$I$1270,"А500С",Ведомость!$V$5:$V$1270,"К-А",Ведомость!$W$5:$W$1270,1) | E14: =SUMIFS(Ведомость!$N$5:$N$1270,Ведомость!$H$5:$H$1270,16,Ведомость!$I$5:$I$1270,"А500С",Ведомость!$V$5:$V$1270,"Р-А",Ведомость!$W$5:$W$1270,1) | F14: =SUMIFS(Ведомость!$N$5:$N$1270,Ведомость!$H$5:$H$1270,16,Ведомость!$I$5:$I$1270,"А500С",Ведомость!$V$5:$V$1270,"К-Б",Ведомость!$W$5:$W$1270,1) | G14: =SUMIFS(Ведомость!$N$5:$N$1270,Ведомость!$H$5:$H$1270,16,Ведомость!$I$5:$I$1270,"А500С",Ведомость!$V$5:$V$1270,"Р-Б",Ведомость!$W$5:$W$1270,1) | H14: =SUMIFS(Ведомость!$N$5:$N$1270,Ведомость!$H$5:$H$1270,16,Ведомость!$I$5:$I$1270,"А500С",Ведомость!$V$5:$V$1270,"К-В",Ведомость!$W$5:$W$1270,1) | I14: =SUMIFS(Ведомость!$N$5:$N$1270,Ведомость!$H$5:$H$1270,16,Ведомость!$I$5:$I$1270,"А500С",Ведомость!$V$5:$V$1270,"Р-В",Ведомость!$W$5:$W$1270,1) | J14: =SUMIFS(Ведомость!$N$5:$N$1270,Ведомость!$H$5:$H$1270,16,Ведомость!$I$5:$I$1270,"А500С",Ведомость!$V$5:$V$1270,"К-Г",Ведомость!$W$5:$W$1270,1) | K14: =SUMIFS(Ведомость!$N$5:$N$1270,Ведомость!$H$5:$H$1270,16,Ведомость!$I$5:$I$1270,"А500С",Ведомость!$V$5:$V$1270,"Дм-3",Ведомость!$W$5:$W$1270,1) | L14: =SUMIFS(Ведомость!$N$5:$N$1270,Ведомость!$H$5:$H$1270,16,Ведомость!$I$5:$I$1270,"А500С",Ведомость!$V$5:$V$1270,"Дм-4",Ведомость!$W$5:$W$1270,1) | M14: =SUMIFS(Ведомость!$N$5:$N$1270,Ведомость!$H$5:$H$1270,16,Ведомость!$I$5:$I$1270,"А500С",Ведомость!$V$5:$V$1270,"Дм-5",Ведомость!$W$5:$W$1270,1) | N14: =SUMIFS(Ведомость!$N$5:$N$1270,Ведомость!$H$5:$H$1270,16,Ведомость!$I$5:$I$1270,"А500С",Ведомость!$V$5:$V$1270,"Р-Г",Ведомость!$W$5:$W$1270,1) | O14: =SUMIFS(Ведомость!$N$5:$N$1270,Ведомость!$H$5:$H$1270,16,Ведомость!$I$5:$I$1270,"А500С",Ведомость!$V$5:$V$1270,"Р-1, 5",Ведомость!$W$5:$W$1270,1) | P14: =SUMIFS(Ведомость!$N$5:$N$1270,Ведомость!$H$5:$H$1270,16,Ведомость!$I$5:$I$1270,"А500С",Ведомость!$V$5:$V$1270,"Р-2",Ведомость!$W$5:$W$1270,1) | Q14: =SUMIFS(Ведомость!$N$5:$N$1270,Ведомость!$H$5:$H$1270,16,Ведомость!$I$5:$I$1270,"А500С",Ведомость!$V$5:$V$1270,"Р-3",Ведомость!$W$5:$W$1270,1) | R14: =SUMIFS(Ведомость!$N$5:$N$1270,Ведомость!$H$5:$H$1270,16,Ведомость!$I$5:$I$1270,"А500С",Ведомость!$V$5:$V$1270,"Р-4",Ведомость!$W$5:$W$1270,1) | S14: =SUMIFS(Ведомость!$N$5:$N$1270,Ведомость!$H$5:$H$1270,16,Ведомость!$I$5:$I$1270,"А500С",Ведомость!$V$5:$V$1270,"Б-основная",Ведомость!$W$5:$W$1270,1) | T14: =SUMIFS(Ведомость!$N$5:$N$1270,Ведомость!$H$5:$H$1270,16,Ведомость!$I$5:$I$1270,"А500С",Ведомость!$V$5:$V$1270,"Б-хомуты",Ведомость!$W$5:$W$1270,1) | U14: =SUMIFS(Ведомость!$N$5:$N$1270,Ведомость!$H$5:$H$1270,16,Ведомость!$I$5:$I$1270,"А500С",Ведомость!$V$5:$V$1270,"Б-допник",Ведомость!$W$5:$W$1270,1) | V14: =SUMIFS(Ведомость!$N$5:$N$1270,Ведомость!$H$5:$H$1270,16,Ведомость!$I$5:$I$1270,"А500С",Ведомость!$V$5:$V$1270,"П-сетка",Ведомость!$W$5:$W$1270,1) | W14: =SUMIFS(Ведомость!$N$5:$N$1270,Ведомость!$H$5:$H$1270,16,Ведомость!$I$5:$I$1270,"А500С",Ведомость!$V$5:$V$1270,"П-фикс",Ведомость!$W$5:$W$1270,1) | X14: =SUMIFS(Ведомость!$N$5:$N$1270,Ведомость!$H$5:$H$1270,16,Ведомость!$I$5:$I$1270,"А500С",Ведомость!$V$5:$V$1270,"П-отв",Ведомость!$W$5:$W$1270,1) | Y14: =SUMIFS(Ведомость!$N$5:$N$1270,Ведомость!$H$5:$H$1270,16,Ведомость!$I$5:$I$1270,"А500С",Ведомость!$V$5:$V$1270,"П-доп-низ",Ведомость!$W$5:$W$1270,1) | Z14: =SUMIFS(Ведомость!$N$5:$N$1270,Ведомость!$H$5:$H$1270,16,Ведомость!$I$5:$I$1270,"А500С",Ведомость!$V$5:$V$1270,"П-доп-верх",Ведомость!$W$5:$W$1270,1) | AA14: =SUMIFS(Ведомость!$N$5:$N$1270,Ведомость!$H$5:$H$1270,16,Ведомость!$I$5:$I$1270,"А500С",Ведомость!$V$5:$V$1270,"П-край",Ведомость!$W$5:$W$1270,1) | AB14: =SUMIFS(Ведомость!$N$5:$N$1270,Ведомость!$H$5:$H$1270,16,Ведомость!$I$5:$I$1270,"А500С",Ведомость!$V$5:$V$1270,"С-1",Ведомость!$W$5:$W$1270,1) | AC14: =SUMIFS(Ведомость!$N$5:$N$1270,Ведомость!$H$5:$H$1270,16,Ведомость!$I$5:$I$1270,"А500С",Ведомость!$V$5:$V$1270,"Л1",Ведомость!$W$5:$W$1270,1) | AD14: =SUMIFS(Ведомость!$N$5:$N$1270,Ведомость!$H$5:$H$1270,16,Ведомость!$I$5:$I$1270,"А500С",Ведомость!$V$5:$V$1270,"Л2",Ведомость!$W$5:$W$1270,1) | AE14: =SUMIFS(Ведомость!$N$5:$N$1270,Ведомость!$H$5:$H$1270,16,Ведомость!$I$5:$I$1270,"А500С",Ведомость!$V$5:$V$1270,"Л-пл",Ведомость!$W$5:$W$1270,1) | AF14: =SUMIFS(Ведомость!$N$5:$N$1270,Ведомость!$H$5:$H$1270,16,Ведомость!$I$5:$I$1270,"А500С",Ведомость!$V$5:$V$1270,"Л-рама",Ведомость!$W$5:$W$1270,1) | AG14: =SUM(B14:AF14) | AH14: =IFERROR(INDEX(Исходные!$B$19:$B$31,MATCH(16,Исходные!$A$19:$A$31,0)),0) | AI14: =AG14*AH14*$AJ$2 | AJ14: =SUM(B14:D14,F14,H14,J14:M14) | AK14: =AH14 | AL14: =AJ14*AK14*$AJ$2 | AM14: =SUM(E14,G14,I14,N14:AB14) | AN14: =AH14 | AO14: =AM14*AN14*$AJ$2 | AP14: =SUM(AC14:AF14) | AQ14: =AH14 | AR14: =AP14*AQ14*$AJ$2
A15: Диаметр 14 А500С, L=м.п. | B15: =SUMIFS(Ведомость!$N$5:$N$1270,Ведомость!$H$5:$H$1270,14,Ведомость!$I$5:$I$1270,"А500С",Ведомость!$V$5:$V$1270,"Дм-1",Ведомость!$W$5:$W$1270,1) | C15: =SUMIFS(Ведомость!$N$5:$N$1270,Ведомость!$H$5:$H$1270,14,Ведомость!$I$5:$I$1270,"А500С",Ведомость!$V$5:$V$1270,"Дм-2",Ведомость!$W$5:$W$1270,1) | D15: =SUMIFS(Ведомость!$N$5:$N$1270,Ведомость!$H$5:$H$1270,14,Ведомость!$I$5:$I$1270,"А500С",Ведомость!$V$5:$V$1270,"К-А",Ведомость!$W$5:$W$1270,1) | E15: =SUMIFS(Ведомость!$N$5:$N$1270,Ведомость!$H$5:$H$1270,14,Ведомость!$I$5:$I$1270,"А500С",Ведомость!$V$5:$V$1270,"Р-А",Ведомость!$W$5:$W$1270,1) | F15: =SUMIFS(Ведомость!$N$5:$N$1270,Ведомость!$H$5:$H$1270,14,Ведомость!$I$5:$I$1270,"А500С",Ведомость!$V$5:$V$1270,"К-Б",Ведомость!$W$5:$W$1270,1) | G15: =SUMIFS(Ведомость!$N$5:$N$1270,Ведомость!$H$5:$H$1270,14,Ведомость!$I$5:$I$1270,"А500С",Ведомость!$V$5:$V$1270,"Р-Б",Ведомость!$W$5:$W$1270,1) | H15: =SUMIFS(Ведомость!$N$5:$N$1270,Ведомость!$H$5:$H$1270,14,Ведомость!$I$5:$I$1270,"А500С",Ведомость!$V$5:$V$1270,"К-В",Ведомость!$W$5:$W$1270,1) | I15: =SUMIFS(Ведомость!$N$5:$N$1270,Ведомость!$H$5:$H$1270,14,Ведомость!$I$5:$I$1270,"А500С",Ведомость!$V$5:$V$1270,"Р-В",Ведомость!$W$5:$W$1270,1) | J15: =SUMIFS(Ведомость!$N$5:$N$1270,Ведомость!$H$5:$H$1270,14,Ведомость!$I$5:$I$1270,"А500С",Ведомость!$V$5:$V$1270,"К-Г",Ведомость!$W$5:$W$1270,1) | K15: =SUMIFS(Ведомость!$N$5:$N$1270,Ведомость!$H$5:$H$1270,14,Ведомость!$I$5:$I$1270,"А500С",Ведомость!$V$5:$V$1270,"Дм-3",Ведомость!$W$5:$W$1270,1) | L15: =SUMIFS(Ведомость!$N$5:$N$1270,Ведомость!$H$5:$H$1270,14,Ведомость!$I$5:$I$1270,"А500С",Ведомость!$V$5:$V$1270,"Дм-4",Ведомость!$W$5:$W$1270,1) | M15: =SUMIFS(Ведомость!$N$5:$N$1270,Ведомость!$H$5:$H$1270,14,Ведомость!$I$5:$I$1270,"А500С",Ведомость!$V$5:$V$1270,"Дм-5",Ведомость!$W$5:$W$1270,1) | N15: =SUMIFS(Ведомость!$N$5:$N$1270,Ведомость!$H$5:$H$1270,14,Ведомость!$I$5:$I$1270,"А500С",Ведомость!$V$5:$V$1270,"Р-Г",Ведомость!$W$5:$W$1270,1) | O15: =SUMIFS(Ведомость!$N$5:$N$1270,Ведомость!$H$5:$H$1270,14,Ведомость!$I$5:$I$1270,"А500С",Ведомость!$V$5:$V$1270,"Р-1, 5",Ведомость!$W$5:$W$1270,1) | P15: =SUMIFS(Ведомость!$N$5:$N$1270,Ведомость!$H$5:$H$1270,14,Ведомость!$I$5:$I$1270,"А500С",Ведомость!$V$5:$V$1270,"Р-2",Ведомость!$W$5:$W$1270,1) | Q15: =SUMIFS(Ведомость!$N$5:$N$1270,Ведомость!$H$5:$H$1270,14,Ведомость!$I$5:$I$1270,"А500С",Ведомость!$V$5:$V$1270,"Р-3",Ведомость!$W$5:$W$1270,1) | R15: =SUMIFS(Ведомость!$N$5:$N$1270,Ведомость!$H$5:$H$1270,14,Ведомость!$I$5:$I$1270,"А500С",Ведомость!$V$5:$V$1270,"Р-4",Ведомость!$W$5:$W$1270,1) | S15: =SUMIFS(Ведомость!$N$5:$N$1270,Ведомость!$H$5:$H$1270,14,Ведомость!$I$5:$I$1270,"А500С",Ведомость!$V$5:$V$1270,"Б-основная",Ведомость!$W$5:$W$1270,1) | T15: =SUMIFS(Ведомость!$N$5:$N$1270,Ведомость!$H$5:$H$1270,14,Ведомость!$I$5:$I$1270,"А500С",Ведомость!$V$5:$V$1270,"Б-хомуты",Ведомость!$W$5:$W$1270,1) | U15: =SUMIFS(Ведомость!$N$5:$N$1270,Ведомость!$H$5:$H$1270,14,Ведомость!$I$5:$I$1270,"А500С",Ведомость!$V$5:$V$1270,"Б-допник",Ведомость!$W$5:$W$1270,1) | V15: =SUMIFS(Ведомость!$N$5:$N$1270,Ведомость!$H$5:$H$1270,14,Ведомость!$I$5:$I$1270,"А500С",Ведомость!$V$5:$V$1270,"П-сетка",Ведомость!$W$5:$W$1270,1) | W15: =SUMIFS(Ведомость!$N$5:$N$1270,Ведомость!$H$5:$H$1270,14,Ведомость!$I$5:$I$1270,"А500С",Ведомость!$V$5:$V$1270,"П-фикс",Ведомость!$W$5:$W$1270,1) | X15: =SUMIFS(Ведомость!$N$5:$N$1270,Ведомость!$H$5:$H$1270,14,Ведомость!$I$5:$I$1270,"А500С",Ведомость!$V$5:$V$1270,"П-отв",Ведомость!$W$5:$W$1270,1) | Y15: =SUMIFS(Ведомость!$N$5:$N$1270,Ведомость!$H$5:$H$1270,14,Ведомость!$I$5:$I$1270,"А500С",Ведомость!$V$5:$V$1270,"П-доп-низ",Ведомость!$W$5:$W$1270,1) | Z15: =SUMIFS(Ведомость!$N$5:$N$1270,Ведомость!$H$5:$H$1270,14,Ведомость!$I$5:$I$1270,"А500С",Ведомость!$V$5:$V$1270,"П-доп-верх",Ведомость!$W$5:$W$1270,1) | AA15: =SUMIFS(Ведомость!$N$5:$N$1270,Ведомость!$H$5:$H$1270,14,Ведомость!$I$5:$I$1270,"А500С",Ведомость!$V$5:$V$1270,"П-край",Ведомость!$W$5:$W$1270,1) | AB15: =SUMIFS(Ведомость!$N$5:$N$1270,Ведомость!$H$5:$H$1270,14,Ведомость!$I$5:$I$1270,"А500С",Ведомость!$V$5:$V$1270,"С-1",Ведомость!$W$5:$W$1270,1) | AC15: =SUMIFS(Ведомость!$N$5:$N$1270,Ведомость!$H$5:$H$1270,14,Ведомость!$I$5:$I$1270,"А500С",Ведомость!$V$5:$V$1270,"Л1",Ведомость!$W$5:$W$1270,1) | AD15: =SUMIFS(Ведомость!$N$5:$N$1270,Ведомость!$H$5:$H$1270,14,Ведомость!$I$5:$I$1270,"А500С",Ведомость!$V$5:$V$1270,"Л2",Ведомость!$W$5:$W$1270,1) | AE15: =SUMIFS(Ведомость!$N$5:$N$1270,Ведомость!$H$5:$H$1270,14,Ведомость!$I$5:$I$1270,"А500С",Ведомость!$V$5:$V$1270,"Л-пл",Ведомость!$W$5:$W$1270,1) | AF15: =SUMIFS(Ведомость!$N$5:$N$1270,Ведомость!$H$5:$H$1270,14,Ведомость!$I$5:$I$1270,"А500С",Ведомость!$V$5:$V$1270,"Л-рама",Ведомость!$W$5:$W$1270,1) | AG15: =SUM(B15:AF15) | AH15: =IFERROR(INDEX(Исходные!$B$19:$B$31,MATCH(14,Исходные!$A$19:$A$31,0)),0) | AI15: =AG15*AH15*$AJ$2 | AJ15: =SUM(B15:D15,F15,H15,J15:M15) | AK15: =AH15 | AL15: =AJ15*AK15*$AJ$2 | AM15: =SUM(E15,G15,I15,N15:AB15) | AN15: =AH15 | AO15: =AM15*AN15*$AJ$2 | AP15: =SUM(AC15:AF15) | AQ15: =AH15 | AR15: =AP15*AQ15*$AJ$2
A16: Диаметр 12 А500С, L=м.п. | B16: =SUMIFS(Ведомость!$N$5:$N$1270,Ведомость!$H$5:$H$1270,12,Ведомость!$I$5:$I$1270,"А500С",Ведомость!$V$5:$V$1270,"Дм-1",Ведомость!$W$5:$W$1270,1) | C16: =SUMIFS(Ведомость!$N$5:$N$1270,Ведомость!$H$5:$H$1270,12,Ведомость!$I$5:$I$1270,"А500С",Ведомость!$V$5:$V$1270,"Дм-2",Ведомость!$W$5:$W$1270,1) | D16: =SUMIFS(Ведомость!$N$5:$N$1270,Ведомость!$H$5:$H$1270,12,Ведомость!$I$5:$I$1270,"А500С",Ведомость!$V$5:$V$1270,"К-А",Ведомость!$W$5:$W$1270,1) | E16: =SUMIFS(Ведомость!$N$5:$N$1270,Ведомость!$H$5:$H$1270,12,Ведомость!$I$5:$I$1270,"А500С",Ведомость!$V$5:$V$1270,"Р-А",Ведомость!$W$5:$W$1270,1) | F16: =SUMIFS(Ведомость!$N$5:$N$1270,Ведомость!$H$5:$H$1270,12,Ведомость!$I$5:$I$1270,"А500С",Ведомость!$V$5:$V$1270,"К-Б",Ведомость!$W$5:$W$1270,1) | G16: =SUMIFS(Ведомость!$N$5:$N$1270,Ведомость!$H$5:$H$1270,12,Ведомость!$I$5:$I$1270,"А500С",Ведомость!$V$5:$V$1270,"Р-Б",Ведомость!$W$5:$W$1270,1) | H16: =SUMIFS(Ведомость!$N$5:$N$1270,Ведомость!$H$5:$H$1270,12,Ведомость!$I$5:$I$1270,"А500С",Ведомость!$V$5:$V$1270,"К-В",Ведомость!$W$5:$W$1270,1) | I16: =SUMIFS(Ведомость!$N$5:$N$1270,Ведомость!$H$5:$H$1270,12,Ведомость!$I$5:$I$1270,"А500С",Ведомость!$V$5:$V$1270,"Р-В",Ведомость!$W$5:$W$1270,1) | J16: =SUMIFS(Ведомость!$N$5:$N$1270,Ведомость!$H$5:$H$1270,12,Ведомость!$I$5:$I$1270,"А500С",Ведомость!$V$5:$V$1270,"К-Г",Ведомость!$W$5:$W$1270,1) | K16: =SUMIFS(Ведомость!$N$5:$N$1270,Ведомость!$H$5:$H$1270,12,Ведомость!$I$5:$I$1270,"А500С",Ведомость!$V$5:$V$1270,"Дм-3",Ведомость!$W$5:$W$1270,1) | L16: =SUMIFS(Ведомость!$N$5:$N$1270,Ведомость!$H$5:$H$1270,12,Ведомость!$I$5:$I$1270,"А500С",Ведомость!$V$5:$V$1270,"Дм-4",Ведомость!$W$5:$W$1270,1) | M16: =SUMIFS(Ведомость!$N$5:$N$1270,Ведомость!$H$5:$H$1270,12,Ведомость!$I$5:$I$1270,"А500С",Ведомость!$V$5:$V$1270,"Дм-5",Ведомость!$W$5:$W$1270,1) | N16: =SUMIFS(Ведомость!$N$5:$N$1270,Ведомость!$H$5:$H$1270,12,Ведомость!$I$5:$I$1270,"А500С",Ведомость!$V$5:$V$1270,"Р-Г",Ведомость!$W$5:$W$1270,1) | O16: =SUMIFS(Ведомость!$N$5:$N$1270,Ведомость!$H$5:$H$1270,12,Ведомость!$I$5:$I$1270,"А500С",Ведомость!$V$5:$V$1270,"Р-1, 5",Ведомость!$W$5:$W$1270,1) | P16: =SUMIFS(Ведомость!$N$5:$N$1270,Ведомость!$H$5:$H$1270,12,Ведомость!$I$5:$I$1270,"А500С",Ведомость!$V$5:$V$1270,"Р-2",Ведомость!$W$5:$W$1270,1) | Q16: =SUMIFS(Ведомость!$N$5:$N$1270,Ведомость!$H$5:$H$1270,12,Ведомость!$I$5:$I$1270,"А500С",Ведомость!$V$5:$V$1270,"Р-3",Ведомость!$W$5:$W$1270,1) | R16: =SUMIFS(Ведомость!$N$5:$N$1270,Ведомость!$H$5:$H$1270,12,Ведомость!$I$5:$I$1270,"А500С",Ведомость!$V$5:$V$1270,"Р-4",Ведомость!$W$5:$W$1270,1) | S16: =SUMIFS(Ведомость!$N$5:$N$1270,Ведомость!$H$5:$H$1270,12,Ведомость!$I$5:$I$1270,"А500С",Ведомость!$V$5:$V$1270,"Б-основная",Ведомость!$W$5:$W$1270,1) | T16: =SUMIFS(Ведомость!$N$5:$N$1270,Ведомость!$H$5:$H$1270,12,Ведомость!$I$5:$I$1270,"А500С",Ведомость!$V$5:$V$1270,"Б-хомуты",Ведомость!$W$5:$W$1270,1) | U16: =SUMIFS(Ведомость!$N$5:$N$1270,Ведомость!$H$5:$H$1270,12,Ведомость!$I$5:$I$1270,"А500С",Ведомость!$V$5:$V$1270,"Б-допник",Ведомость!$W$5:$W$1270,1) | V16: =SUMIFS(Ведомость!$N$5:$N$1270,Ведомость!$H$5:$H$1270,12,Ведомость!$I$5:$I$1270,"А500С",Ведомость!$V$5:$V$1270,"П-сетка",Ведомость!$W$5:$W$1270,1) | W16: =SUMIFS(Ведомость!$N$5:$N$1270,Ведомость!$H$5:$H$1270,12,Ведомость!$I$5:$I$1270,"А500С",Ведомость!$V$5:$V$1270,"П-фикс",Ведомость!$W$5:$W$1270,1) | X16: =SUMIFS(Ведомость!$N$5:$N$1270,Ведомость!$H$5:$H$1270,12,Ведомость!$I$5:$I$1270,"А500С",Ведомость!$V$5:$V$1270,"П-отв",Ведомость!$W$5:$W$1270,1) | Y16: =SUMIFS(Ведомость!$N$5:$N$1270,Ведомость!$H$5:$H$1270,12,Ведомость!$I$5:$I$1270,"А500С",Ведомость!$V$5:$V$1270,"П-доп-низ",Ведомость!$W$5:$W$1270,1) | Z16: =SUMIFS(Ведомость!$N$5:$N$1270,Ведомость!$H$5:$H$1270,12,Ведомость!$I$5:$I$1270,"А500С",Ведомость!$V$5:$V$1270,"П-доп-верх",Ведомость!$W$5:$W$1270,1) | AA16: =SUMIFS(Ведомость!$N$5:$N$1270,Ведомость!$H$5:$H$1270,12,Ведомость!$I$5:$I$1270,"А500С",Ведомость!$V$5:$V$1270,"П-край",Ведомость!$W$5:$W$1270,1) | AB16: =SUMIFS(Ведомость!$N$5:$N$1270,Ведомость!$H$5:$H$1270,12,Ведомость!$I$5:$I$1270,"А500С",Ведомость!$V$5:$V$1270,"С-1",Ведомость!$W$5:$W$1270,1) | AC16: =SUMIFS(Ведомость!$N$5:$N$1270,Ведомость!$H$5:$H$1270,12,Ведомость!$I$5:$I$1270,"А500С",Ведомость!$V$5:$V$1270,"Л1",Ведомость!$W$5:$W$1270,1) | AD16: =SUMIFS(Ведомость!$N$5:$N$1270,Ведомость!$H$5:$H$1270,12,Ведомость!$I$5:$I$1270,"А500С",Ведомость!$V$5:$V$1270,"Л2",Ведомость!$W$5:$W$1270,1) | AE16: =SUMIFS(Ведомость!$N$5:$N$1270,Ведомость!$H$5:$H$1270,12,Ведомость!$I$5:$I$1270,"А500С",Ведомость!$V$5:$V$1270,"Л-пл",Ведомость!$W$5:$W$1270,1) | AF16: =SUMIFS(Ведомость!$N$5:$N$1270,Ведомость!$H$5:$H$1270,12,Ведомость!$I$5:$I$1270,"А500С",Ведомость!$V$5:$V$1270,"Л-рама",Ведомость!$W$5:$W$1270,1) | AG16: =SUM(B16:AF16) | AH16: =IFERROR(INDEX(Исходные!$B$19:$B$31,MATCH(12,Исходные!$A$19:$A$31,0)),0) | AI16: =AG16*AH16*$AJ$2 | AJ16: =SUM(B16:D16,F16,H16,J16:M16) | AK16: =AH16 | AL16: =AJ16*AK16*$AJ$2 | AM16: =SUM(E16,G16,I16,N16:AB16) | AN16: =AH16 | AO16: =AM16*AN16*$AJ$2 | AP16: =SUM(AC16:AF16) | AQ16: =AH16 | AR16: =AP16*AQ16*$AJ$2
