Workbook

Sheet потребность
A1: Блок 14 — надстройка (тех. этаж +18.350…+21.750) — потребность
A3: Диаметр | B3: Ед. изм. | C3: Колонны (4 шт) | D3: Ригели, балки, плита, С-1 | E3: Итого (чистая) | F3: Итого × К зап | G3: Прутков 11,7 м | H3: Масса заказа по раскрою | I3: Отход, % | J3: К ЗАКАЗУ (большее)
A4: Диаметр 32 А500С | B4: кг | C4: ='По осям'!P8*'По осям'!Q8 -> 116.1592 | D4: ='По осям'!S8*'По осям'!T8 -> 0 | E4: =C4+D4 -> 116.1592 | F4: =E4*Исходные!$B$9 -> 124.29034 | G4: ='Раскрой 11,7м'!D4 -> 2 | H4: ='Раскрой 11,7м'!E4 -> 147.7242 | I4: ='Раскрой 11,7м'!H4 -> 0.21367521 | J4: =MAX(F4,H4) -> 147.7242
A5: Диаметр 28 А500С | B5: кг | C5: ='По осям'!P9*'По осям'!Q9 -> 88.9456 | D5: ='По осям'!S9*'По осям'!T9 -> 541.408 | E5: =C5+D5 -> 630.3536 | F5: =E5*Исходные!$B$9 -> 674.47835 | G5: ='Раскрой 11,7м'!D5 -> 16 | H5: ='Раскрой 11,7м'!E5 -> 904.9248 | I5: ='Раскрой 11,7м'!H5 -> 0.3034188 | J5: =MAX(F5,H5) -> 904.9248
A6: Диаметр 25 А500С | B6: кг | C6: ='По осям'!P10*'По осям'!Q10 -> 0 | D6: ='По осям'!S10*'По осям'!T10 -> 212.6856 | E6: =C6+D6 -> 212.6856 | F6: =E6*Исходные!$B$9 -> 227.57359 | G6: ='Раскрой 11,7м'!D6 -> 8 | H6: ='Раскрой 11,7м'!E6 -> 360.6408 | I6: ='Раскрой 11,7м'!H6 -> 0.41025641 | J6: =MAX(F6,H6) -> 360.6408
A7: Диаметр 20 А500С | B7: кг | C7: ='По осям'!P11*'По осям'!Q11 -> 181.4976 | D7: ='По осям'!S11*'По осям'!T11 -> 67.42044 | E7: =C7+D7 -> 248.91804 | F7: =E7*Исходные!$B$9 -> 266.3423 | G7: ='Раскрой 11,7м'!D7 -> 10 | H7: ='Раскрой 11,7м'!E7 -> 288.522 | I7: ='Раскрой 11,7м'!H7 -> 0.13726496 | J7: =MAX(F7,H7) -> 288.522
A8: Диаметр 18 А500С | B8: кг | C8: ='По осям'!P12*'По осям'!Q12 -> 0 | D8: ='По осям'!S12*'По осям'!T12 -> 111.888 | E8: =C8+D8 -> 111.888 | F8: =E8*Исходные!$B$9 -> 119.72016 | G8: ='Раскрой 11,7м'!D8 -> 8 | H8: ='Раскрой 11,7м'!E8 -> 187.0128 | I8: ='Раскрой 11,7м'!H8 -> 0.4017094 | J8: =MAX(F8,H8) -> 187.0128
A9: Диаметр 16 А500С | B9: кг | C9: ='По осям'!P13*'По осям'!Q13 -> 0 | D9: ='По осям'!S13*'По осям'!T13 -> 88.368 | E9: =C9+D9 -> 88.368 | F9: =E9*Исходные!$B$9 -> 94.55376 | G9: ='Раскрой 11,7м'!D9 -> 8 | H9: ='Раскрой 11,7м'!E9 -> 147.7008 | I9: ='Раскрой 11,7м'!H9 -> 0.4017094 | J9: =MAX(F9,H9) -> 147.7008
A10: Диаметр 10 А500С | B10: кг | C10: ='По осям'!P14*'По осям'!Q14 -> 0 | D10: ='По осям'!S14*'По осям'!T14 -> 661.18337 | E10: =C10+D10 -> 661.18337 | F10: =E10*Исходные!$B$9 -> 707.46621 | G10: ='Раскрой 11,7м'!D10 -> 104 | H10: ='Раскрой 11,7м'!E10 -> 750.7656 | I10: ='Раскрой 11,7м'!H10 -> 0.11932117 | J10: =MAX(F10,H10) -> 750.7656
A11: Диаметр 10 А240 | B11: кг | C11: ='По осям'!P15*'По осям'!Q15 -> 0 | D11: ='По осям'!S15*'По осям'!T15 -> 18.39894 | E11: =C11+D11 -> 18.39894 | F11: =E11*Исходные!$B$9 -> 19.686866 | G11: ='Раскрой 11,7м'!D11 -> 3 | H11: ='Раскрой 11,7м'!E11 -> 21.6567 | I11: ='Раскрой 11,7м'!H11 -> 0.15042735 | J11: =MAX(F11,H11) -> 21.6567
A12: Диаметр 8 А240 | B12: кг | C12: ='По осям'!P16*'По осям'!Q16 -> 196.9944 | D12: ='По осям'!S16*'По осям'!T16 -> 281.6982 | E12: =C12+D12 -> 478.6926 | F12: =E12*Исходные!$B$9 -> 512.20108 | G12: ='Раскрой 11,7м'!D12 -> 105 | H12: ='Раскрой 11,7м'!E12 -> 485.2575 | I12: ='Раскрой 11,7м'!H12 -> 0.013528694 | J12: =MAX(F12,H12) -> 512.20108
A13: Итого: | B13: кг | C13: =SUM(C4:C12) -> 583.5968 | D13: =SUM(D4:D12) -> 1983.0505 | E13: =SUM(E4:E12) -> 2566.6474 | F13: =SUM(F4:F12) -> 2746.3127 | G13: =SUM(G4:G12) -> 264 | H13: =SUM(H4:H12) -> 3294.2052 | J13: =SUM(J4:J12) -> 3321.1488
A14: Итого: | B14: т | C14: =C13/1000 -> 0.5835968 | D14: =D13/1000 -> 1.9830505 | E14: =E13/1000 -> 2.5666474 | F14: =F13/1000 -> 2.7463127 | H14: =H13/1000 -> 3.2942052 | J14: =J13/1000 -> 3.3211488
A15: Контроль: = «Ведомость» и «По осям» | E15: =ROUND(E13-Ведомость!O66,1)+ROUND(E13-'По осям'!O17,1) -> 0 | F15: ← должно быть 0
A17: Бетон
A18: В25 | B18: м³ | C18: ='По осям'!R22 -> 4.7232 | D18: ='По осям'!U22 -> 11.38146 | E18: =C18+D18 -> 16.10466
A20: Прочие материалы
A21: Наименование | B21: Ед. изм. | C21: Колонны (4 шт) | D21: Ригели, балки, плита, С-1 | E21: Итого | F21: Основание
A22: Анкерная шайба АШ-3 (18) | B22: шт. | C22: ='По осям'!P28 -> 0 | D22: ='По осям'!S28 -> 16 | E22: =SUM(C22:D22) -> 16 | F22: 2Ø18 ригелей × 2 конца (узел «3»: верхние и нижние стержни)
A23: Анкерная шайба АШ-4 (20) | B23: шт. | C23: ='По осям'!P29 -> 0 | D23: ='По осям'!S29 -> 4 | E23: =SUM(C23:D23) -> 4 | F23: балка 4-4 у ригеля В: 4 стержня
A24: Анкерная шайба АШ-6 (25) | B24: шт. | C24: ='По осям'!P31 -> 0 | D24: ='По осям'!S31 -> 16 | E24: =SUM(C24:D24) -> 16 | F24: балки 1-1: 2 балки × 2 конца у ригелей × 4 стержня (АС-57 узел «1»)
A25: Анкерная шайба АШ-7 (28) | B25: шт. | C25: ='По осям'!P32 -> 8 | D25: ='По осям'!S32 -> 32 | E25: =SUM(C25:D25) -> 40 | F25: верх угловых Ø28 колонн Г/3, Г/4; 4Ø28 ригелей × 2 конца (узел «3»)
A26: Анкерная шайба АШ-8 (32) | B26: шт. | C26: ='По осям'!P33 -> 8 | D26: ='По осям'!S33 -> 0 | E26: =SUM(C26:D26) -> 8 | F26: верх угловых Ø32 колонн В/3, В/4
A27: Масса анкерных шайб (справочно) | B27: кг | C27: =C22*Исходные!$B$30+C23*Исходные!$B$31+C24*Исходные!$B$33+C25*Исходные!$B$34+C26*Исходные!$B$35 -> 21.52 | D27: =D22*Исходные!$B$30+D23*Исходные!$B$31+D24*Исходные!$B$33+D25*Исходные!$B$34+D26*Исходные!$B$35 -> 53.28 | E27: =SUM(C27:D27) -> 74.8 | F27: шт × масса 1 шт по АС-33 (лист «Исходные»)
A28: Ванночка d32 (= стыков ванной сварки) | B28: шт. | C28: ='По осям'!P34 -> 8 | D28: ='По осям'!S34 -> 0 | E28: =SUM(C28:D28) -> 8 | F28: вертикали колонн — 1 стык на стержень над +18.350; АС-19 прим.1: в инвентарной медной форме
A29: Ванночка d28 (= стыков ванной сварки) | B29: шт. | C29: ='По осям'!P35 -> 8 | D29: ='По осям'!S35 -> 0 | E29: =SUM(C29:D29) -> 8 | F29: то же
A30: Ванночка d20 (= стыков ванной сварки) | B30: шт. | C30: ='По осям'!P38 -> 32 | D30: ='По осям'!S38 -> 0 | E30: =SUM(C30:D30) -> 32 | F30: то же
A31: Электроды | B31: кг | C31: =ROUND(C13*Исходные!$B$9*Исходные!$B$37/1000,1) -> 4.4 | D31: =ROUND(D13*Исходные!$B$9*Исходные!$B$37/1000,1) -> 14.9 | E31: =SUM(C31:D31) -> 19.3 | F31: масса × К зап / 1000 × норма шаблона (лист «Исходные»)
A32: Вязальная проволока | B32: кг | C32: =ROUND(C13*Исходные!$B$9*Исходные!$B$38/1000,1) -> 6.9 | D32: =ROUND(D13*Исходные!$B$9*Исходные!$B$38/1000,1) -> 23.3 | E32: =SUM(C32:D32) -> 30.2 | F32: масса × К зап / 1000 × норма шаблона (лист «Исходные»)
A33: Вулканит | B33: шт. | C33: =ROUND(C13*Исходные!$B$9*Исходные!$B$39/1000,0) -> 1 | D33: =ROUND(D13*Исходные!$B$9*Исходные!$B$39/1000,0) -> 4 | E33: =SUM(C33:D33) -> 5 | F33: масса × К зап / 1000 × норма шаблона (лист «Исходные»)
A34: Гвозди 100 мм | B34: кг | C34: =ROUND(Исходные!$B$44*Исходные!$B$43/Исходные!$B$42,1) -> 35 | E34: =SUM(C34:D34) -> 35 | F34: норма на этаж 18×18 (324 м²) × площадь плиты надстройки / 324 (≈ ×0,14)
A35: Гвозди 70 мм | B35: кг | C35: =ROUND(Исходные!$B$45*Исходные!$B$43/Исходные!$B$42,1) -> 14 | E35: =SUM(C35:D35) -> 14 | F35: норма на этаж 18×18 (324 м²) × площадь плиты надстройки / 324 (≈ ×0,14)
A36: Гвозди — справочно: сметная норма ГЭСН (не складывать) | B36: кг | C36: =ROUND('По осям'!P22*Исходные!$B$51/100,1) -> 2.1 | D36: =ROUND('По осям'!S22*Исходные!$B$52/100,1) -> 13.2 | E36: =SUM(C36:D36) -> 15.3 | F36: объём бетона × норма ГЭСН на 100 м³ (колонны 45, перекрытие ребристое 116 кг)
A37: Пена монтажная | B37: баллон | C37: =ROUNDUP(Исходные!$B$46*Исходные!$B$43/Исходные!$B$42,0) -> 2 | E37: =SUM(C37:D37) -> 2 | F37: норма на этаж 18×18 (324 м²) × площадь плиты надстройки / 324 (≈ ×0,14)
A38: Труба квадратная 25×25×0,8 | B38: м | C38: =ROUND(Исходные!$B$47*Исходные!$B$43/Исходные!$B$42,1) -> 35 | E38: =SUM(C38:D38) -> 35 | F38: норма на этаж 18×18 (324 м²) × площадь плиты надстройки / 324 (≈ ×0,14)
A39: Бур по бетону 260×12 | B39: шт. | C39: =ROUNDUP(Исходные!$B$48*Исходные!$B$43/Исходные!$B$42,0) -> 3 | E39: =SUM(C39:D39) -> 3 | F39: норма на этаж 18×18 (324 м²) × площадь плиты надстройки / 324 (≈ ×0,14)
A40: Диск по дереву 180/230 | B40: шт. | C40: =ROUNDUP(Исходные!$B$49*Исходные!$B$43/Исходные!$B$42,0) -> 3 | E40: =SUM(C40:D40) -> 3 | F40: норма на этаж 18×18 (324 м²) × площадь плиты надстройки / 324 (≈ ×0,14)
A41: Дюбель-гвоздь для бетона 4,5×50 | B41: кг | C41: =ROUND(Исходные!$B$50*Исходные!$B$43/Исходные!$B$42,1) -> 2.1 | E41: =SUM(C41:D41) -> 2.1 | F41: норма на этаж 18×18 (324 м²) × площадь плиты надстройки / 324 (≈ ×0,14)
A42: П/лес обрезной (опалубка) | B42: м³ | E42: =SUM(C42:D42) -> 0 | F42: в КЖ нет — ТРЕБУЕТСЯ УТОЧНЕНИЕ (по ППР / норме участка)

Sheet По осям
A1: Блок 14, ул. Токомбаева — надстройка (технический этаж над лестницей и лифтом), отм. +18.350…+21.750, оси 3–4 / В–Г — м.п. → кг
A2: м.п. в ячейке — формула из чисел «кол-во × длина» по позициям (расшифровка — лист «Ведомость»); Всего = м.п. × кг/м × К зап | P2: К зап | Q2: =Исходные!$B$9 -> 1.07
A4: НАДСТРОЙКА | B4: Колонны | D4: Ригели +21.750 | H4: Балки | J4: Перекрытие | L4: Сетки С-1 | P4: Колонны | S4: Ригели, балки, плита, С-1
A5: +18.350…+21.750 | B5: ось В | C5: ось Г | D5: ось В | E5: ось Г | F5: ось 3 | G5: ось 4 | H5: Основная | I5: Хомуты | J5: Основная | K5: Ф-1, шп. | L5: С-1 | M5: Итого (м.п.) | N5: Масса ед. кг | O5: Всего, кг | P5: Итого (м.п.) | Q5: Масса ед. | R5: Всего, кг | S5: Итого (м.п.) | T5: Масса ед. | U5: Всего, кг
A6: оси 3–4 / В–Г | B6: В/3, В/4 (1-1) | C6: Г/3, Г/4 (2-2) | D6: 4-4 | E6: 4-4 | F6: 5-5 | G6: 5-5 | H6: 1-1, 4-4 | J6: Ø10/200 | L6: 40 шт
A7: Арматура, (м.п.)
A8: Диаметр 32 А500С, L=м.п. | B8: =2*2*2.55+2*2*2.05 -> 18.4 | M8: =SUM(B8:L8) -> 18.4 | N8: =INDEX(Исходные!$B$13:$B$25,MATCH(32,Исходные!$A$13:$A$25,0)) -> 6.313 | O8: =M8*N8*$Q$2 -> 124.29034 | P8: =SUM(B8,C8) -> 18.4 | Q8: =N8 -> 6.313 | R8: =P8*Q8*$Q$2 -> 124.29034 | S8: =SUM(D8,E8,F8,G8,H8,I8,J8,K8,L8) -> 0 | T8: =N8 -> 6.313 | U8: =S8*T8*$Q$2 -> 0
A9: Диаметр 28 А500С, L=м.п. | C9: =2*2*2.55+2*2*2.05 -> 18.4 | D9: =4*7 -> 28 | E9: =4*7 -> 28 | F9: =4*7 -> 28 | G9: =4*7 -> 28 | M9: =SUM(B9:L9) -> 130.4 | N9: =INDEX(Исходные!$B$13:$B$25,MATCH(28,Исходные!$A$13:$A$25,0)) -> 4.834 | O9: =M9*N9*$Q$2 -> 674.47835 | P9: =SUM(B9,C9) -> 18.4 | Q9: =N9 -> 4.834 | R9: =P9*Q9*$Q$2 -> 95.171792 | S9: =SUM(D9,E9,F9,G9,H9,I9,J9,K9,L9) -> 112 | T9: =N9 -> 4.834 | U9: =S9*T9*$Q$2 -> 579.30656
A10: Диаметр 25 А500С, L=м.п. | H10: =4*6.9+4*6.9 -> 55.2 | M10: =SUM(B10:L10) -> 55.2 | N10: =INDEX(Исходные!$B$13:$B$25,MATCH(25,Исходные!$A$13:$A$25,0)) -> 3.853 | O10: =M10*N10*$Q$2 -> 227.57359 | P10: =SUM(B10,C10) -> 0 | Q10: =N10 -> 3.853 | R10: =P10*Q10*$Q$2 -> 0 | S10: =SUM(D10,E10,F10,G10,H10,I10,J10,K10,L10) -> 55.2 | T10: =N10 -> 3.853 | U10: =S10*T10*$Q$2 -> 227.57359
A11: Диаметр 20 А500С, L=м.п. | B11: =2*4*2.55+2*4*2.05 -> 36.8 | C11: =2*4*2.55+2*4*2.05 -> 36.8 | H11: =4*3.785+4*3.05 -> 27.34 | M11: =SUM(B11:L11) -> 100.94 | N11: =INDEX(Исходные!$B$13:$B$25,MATCH(20,Исходные!$A$13:$A$25,0)) -> 2.466 | O11: =M11*N11*$Q$2 -> 266.3423 | P11: =SUM(B11,C11) -> 73.6 | Q11: =N11 -> 2.466 | R11: =P11*Q11*$Q$2 -> 194.20243 | S11: =SUM(D11,E11,F11,G11,H11,I11,J11,K11,L11) -> 27.34 | T11: =N11 -> 2.466 | U11: =S11*T11*$Q$2 -> 72.139871
A12: Диаметр 18 А500С, L=м.п. | D12: =2*7 -> 14 | E12: =2*7 -> 14 | F12: =2*7 -> 14 | G12: =2*7 -> 14 | M12: =SUM(B12:L12) -> 56 | N12: =INDEX(Исходные!$B$13:$B$25,MATCH(18,Исходные!$A$13:$A$25,0)) -> 1.998 | O12: =M12*N12*$Q$2 -> 119.72016 | P12: =SUM(B12,C12) -> 0 | Q12: =N12 -> 1.998 | R12: =P12*Q12*$Q$2 -> 0 | S12: =SUM(D12,E12,F12,G12,H12,I12,J12,K12,L12) -> 56 | T12: =N12 -> 1.998 | U12: =S12*T12*$Q$2 -> 119.72016
A13: Диаметр 16 А500С, L=м.п. | D13: =2*7 -> 14 | E13: =2*7 -> 14 | F13: =2*7 -> 14 | G13: =2*7 -> 14 | M13: =SUM(B13:L13) -> 56 | N13: =INDEX(Исходные!$B$13:$B$25,MATCH(16,Исходные!$A$13:$A$25,0)) -> 1.578 | O13: =M13*N13*$Q$2 -> 94.55376 | P13: =SUM(B13,C13) -> 0 | Q13: =N13 -> 1.578 | R13: =P13*Q13*$Q$2 -> 0 | S13: =SUM(D13,E13,F13,G13,H13,I13,J13,K13,L13) -> 56 | T13: =N13 -> 1.578 | U13: =S13*T13*$Q$2 -> 94.55376
A14: Диаметр 10 А500С, L=м.п. | J14: =21*6.9+13*5.575+2*2.775+15*0.4+18*7.045+13*6.11+4*3.51+17*0.4+21*6.9+13*5.575+2*2.775+15*0.4+18*7.045+13*6.11+4*3.51+17*0.4 -> 912.01 | L14: =40*7*0.57 -> 159.6 | M14: =SUM(B14:L14) -> 1071.61 | N14: =INDEX(Исходные!$B$13:$B$25,MATCH(10,Исходные!$A$13:$A$25,0)) -> 0.617 | O14: =M14*N14*$Q$2 -> 707.46621 | P14: =SUM(B14,C14) -> 0 | Q14: =N14 -> 0.617 | R14: =P14*Q14*$Q$2 -> 0 | S14: =SUM(D14,E14,F14,G14,H14,I14,J14,K14,L14) -> 1071.61 | T14: =N14 -> 0.617 | U14: =S14*T14*$Q$2 -> 707.46621
A15: Диаметр 10 А240, L=м.п. | K15: =71*0.42 -> 29.82 | M15: =SUM(B15:L15) -> 29.82 | N15: =INDEX(Исходные!$B$13:$B$25,MATCH(10,Исходные!$A$13:$A$25,0)) -> 0.617 | O15: =M15*N15*$Q$2 -> 19.686866 | P15: =SUM(B15,C15) -> 0 | Q15: =N15 -> 0.617 | R15: =P15*Q15*$Q$2 -> 0 | S15: =SUM(D15,E15,F15,G15,H15,I15,J15,K15,L15) -> 29.82 | T15: =N15 -> 0.617 | U15: =S15*T15*$Q$2 -> 19.686866
A16: Диаметр 8 А240, L=м.п. | B16: =2*27*2.44+2*30*1.96 -> 249.36 | C16: =2*27*2.44+2*30*1.96 -> 249.36 | D16: =51*2.06+30*0.75+20*0.58 -> 139.16 | E16: =48*2.06+32*0.75+20*0.58 -> 134.48 | F16: =47*2.06+33*0.75+20*0.58 -> 133.17 | G16: =47*2.06+33*0.75+20*0.58 -> 133.17 | I16: =91*1.24+43*1.04 -> 157.56 | K16: =71*0.22 -> 15.62 | M16: =SUM(B16:L16) -> 1211.88 | N16: =INDEX(Исходные!$B$13:$B$25,MATCH(8,Исходные!$A$13:$A$25,0)) -> 0.395 | O16: =M16*N16*$Q$2 -> 512.20108 | P16: =SUM(B16,C16) -> 498.72 | Q16: =N16 -> 0.395 | R16: =P16*Q16*$Q$2 -> 210.78401 | S16: =SUM(D16,E16,F16,G16,H16,I16,J16,K16,L16) -> 713.16 | T16: =N16 -> 0.395 | U16: =S16*T16*$Q$2 -> 301.41707
A17: Масса чистая (без К зап), кг | B17: =SUMPRODUCT(B8:B16,$N$8:$N$16) -> 305.4052 | C17: =SUMPRODUCT(C8:C16,$N$8:$N$16) -> 278.1916 | D17: =SUMPRODUCT(D8:D16,$N$8:$N$16) -> 240.3842 | E17: =SUMPRODUCT(E8:E16,$N$8:$N$16) -> 238.5356 | F17: =SUMPRODUCT(F8:F16,$N$8:$N$16) -> 238.01815 | G17: =SUMPRODUCT(G8:G16,$N$8:$N$16) -> 238.01815 | H17: =SUMPRODUCT(H8:H16,$N$8:$N$16) -> 280.10604 | I17: =SUMPRODUCT(I8:I16,$N$8:$N$16) -> 62.2362 | ... L17: =SUMPRODUCT(L8:L16,$N$8:$N$16) -> 98.4732 | N17: Итого: | O17: =SUMPRODUCT(M8:M16,N8:N16) -> 2566.6474 | Q17: Итого: | R17: =SUMPRODUCT(P8:P16,Q8:Q16) -> 583.5968 | T17: Итого: | U17: =SUMPRODUCT(S8:S16,T8:T16) -> 1983.0505
A18: Всего с К зап, кг | B18: =B17*$Q$2 -> 326.78356 | C18: =C17*$Q$2 -> 297.66501 | D18: =D17*$Q$2 -> 257.21109 | E18: =E17*$Q$2 -> 255.23309 | F18: =F17*$Q$2 -> 254.67942 | G18: =G17*$Q$2 -> 254.67942 | H18: =H17*$Q$2 -> 299.71346 | I18: =I17*$Q$2 -> 66.592734 | ... L18: =L17*$Q$2 -> 105.36632 | O18: =SUM(O8:O16) -> 2746.3127 | R18: =SUM(R8:R16) -> 624.44858 | U18: =SUM(U8:U16) -> 2121.8641
A19: Контроль: чистая масса = «Ведомость» | O19: =ROUND(O17-Ведомость!O66,1) -> 0 | P19: ← должно быть 0
A21: Бетон В25, м³
A22: Бетон В25, м³ | B22: =2*0.6*0.6*(3.4-0.12) -> 2.3616 | C22: =2*0.6*0.6*(3.4-0.12) -> 2.3616 | D22: =0.45*(0.6-0.12)*5.9 -> 1.2744 | E22: =0.45*(0.6-0.12)*5.9 -> 1.2744 | F22: =0.45*(0.6-0.12)*5.9 -> 1.2744 | G22: =0.45*(0.6-0.12)*5.9 -> 1.2744 | H22: =0.3*(0.3-0.12)*(6.05+6.05-0.3)+0.2*(0.3-0.12)*(3.085+2.6) -> 0.84186 | J22: =(45.35)*0.12 -> 5.442 | M22: =SUM(B22:L22) -> 16.10466 | O22: =M22*Исходные!$B$10 -> 16.10466 | P22: =SUM(B22,C22) -> 4.7232 | R22: =P22*Исходные!$B$10 -> 4.7232 | S22: =SUM(D22,E22,F22,G22,H22,I22,J22,K22,L22) -> 11.38146 | U22: =S22*Исходные!$B$10 -> 11.38146
A23: Удельный расход (чистый), кг/м³ | O23: =IF(M22>0,O17/M22,0) -> 159.37296 | R23: =IF(P22>0,R17/P22,0) -> 123.55962 | U23: =IF(S22>0,U17/S22,0) -> 174.23516
A25: Прочие материалы, шт.
A26: АШ-1, д14, шт. | M26: =SUM(B26:L26) -> 0 | P26: =SUM(B26,C26) -> 0 | S26: =SUM(D26,E26,F26,G26,H26,I26,J26,K26,L26) -> 0
A27: АШ-2, д16, шт. | M27: =SUM(B27:L27) -> 0 | P27: =SUM(B27,C27) -> 0 | S27: =SUM(D27,E27,F27,G27,H27,I27,J27,K27,L27) -> 0
A28: АШ-3, д18, шт. | D28: 4 | E28: 4 | F28: 4 | G28: 4 | M28: =SUM(B28:L28) -> 16 | P28: =SUM(B28,C28) -> 0 | S28: =SUM(D28,E28,F28,G28,H28,I28,J28,K28,L28) -> 16
A29: АШ-4, д20, шт. | H29: 4 | M29: =SUM(B29:L29) -> 4 | P29: =SUM(B29,C29) -> 0 | S29: =SUM(D29,E29,F29,G29,H29,I29,J29,K29,L29) -> 4
A30: АШ-5, д22, шт. | M30: =SUM(B30:L30) -> 0 | P30: =SUM(B30,C30) -> 0 | S30: =SUM(D30,E30,F30,G30,H30,I30,J30,K30,L30) -> 0
A31: АШ-6, д25, шт. | H31: 16 | M31: =SUM(B31:L31) -> 16 | P31: =SUM(B31,C31) -> 0 | S31: =SUM(D31,E31,F31,G31,H31,I31,J31,K31,L31) -> 16
A32: АШ-7, д28, шт. | C32: 8 | D32: 8 | E32: 8 | F32: 8 | G32: 8 | M32: =SUM(B32:L32) -> 40 | P32: =SUM(B32,C32) -> 8 | S32: =SUM(D32,E32,F32,G32,H32,I32,J32,K32,L32) -> 32
A33: АШ-8, д32, шт. | B33: 8 | M33: =SUM(B33:L33) -> 8 | P33: =SUM(B33,C33) -> 8 | S33: =SUM(D33,E33,F33,G33,H33,I33,J33,K33,L33) -> 0
A34: ВН32, шт. (стыки ванной сваркой) | B34: 8 | M34: =SUM(B34:L34) -> 8 | P34: =SUM(B34,C34) -> 8 | S34: =SUM(D34,E34,F34,G34,H34,I34,J34,K34,L34) -> 0
A35: ВН28, шт. (стыки ванной сваркой) | C35: 8 | M35: =SUM(B35:L35) -> 8 | P35: =SUM(B35,C35) -> 8 | S35: =SUM(D35,E35,F35,G35,H35,I35,J35,K35,L35) -> 0
A36: ВН25, шт. (стыки ванной сваркой) | M36: =SUM(B36:L36) -> 0 | P36: =SUM(B36,C36) -> 0 | S36: =SUM(D36,E36,F36,G36,H36,I36,J36,K36,L36) -> 0
A37: ВН22, шт. (стыки ванной сваркой) | M37: =SUM(B37:L37) -> 0 | P37: =SUM(B37,C37) -> 0 | S37: =SUM(D37,E37,F37,G37,H37,I37,J37,K37,L37) -> 0
A38: ВН20, шт. (стыки ванной сваркой) | B38: 16 | C38: 16 | M38: =SUM(B38:L38) -> 32 | P38: =SUM(B38,C38) -> 32 | S38: =SUM(D38,E38,F38,G38,H38,I38,J38,K38,L38) -> 0

Sheet Исходные
A1: Блок 14, ул. Токомбаева — надстройка (технический этаж над лестницей и лифтом), отм. +18.350…+21.750, оси 3–4 / В–Г
A3: Объект | B3: 5,7,9-эт. жилые дома, ул. Токомбаева (Блоки 11–15) — Блок 14, проект ОсОО «Билд-Форм», стадия РП, раздел АС
A4: Что считается | B4: Надстройка над покрытием +18.350: 4 колонны (В/3, В/4, Г/3, Г/4) от стыка над +18.350 до +21.750, ригели +21.750 по осям В, Г, 3, 4, плита +21.750 с балками, сетки С-1 в узлах «3»
A5: Не входит | B5: 5 этаж и ниже (книга «Блок14_1-5этаж_арматура.xlsx»); ограждающие стены надстройки (в КЖ нет)
A6: Арматура / бетон | B6: А500С, А240 по ГОСТ 34028-2016; бетон В25 (АС-19 прим.6)
A8: Длина прутка, м | B8: 11.7
A9: К(зап) арматура | B9: 1.07
A10: К(зап) бетон | B10: 1
A12: Ø, мм | B12: кг/м
A13: 5 | B13: 0.154
A14: 6 | B14: 0.222
A15: 8 | B15: 0.395
A16: 10 | B16: 0.617
A17: 12 | B17: 0.888
A18: 14 | B18: 1.208
A19: 16 | B19: 1.578
A20: 18 | B20: 1.998
A21: 20 | B21: 2.466
A22: 22 | B22: 2.984
A23: 25 | B23: 3.853
A24: 28 | B24: 4.834
A25: 32 | B25: 6.313
A27: Аш (АС-33): Ø → масса 1 шт, кг
A28: 14 | B28: 0.19 | C28: Аш-1
A29: 16 | B29: 0.19 | C29: Аш-2
A30: 18 | B30: 0.26 | C30: Аш-3
A31: 20 | B31: 0.4 | C31: Аш-4
A32: 22 | B32: 0.6 | C32: Аш-5
A33: 25 | B33: 0.77 | C33: Аш-6
A34: 28 | B34: 1.1 | C34: Аш-7
A35: 32 | B35: 1.59 | C35: Аш-8
A37: Электроды | B37: 7 | C37: кг на 1 т арматуры (с К зап, норма вашего шаблона)
A38: Вязальная проволока | B38: 11 | C38: кг на 1 т
A39: Вулканит | B39: 2 | C39: шт на 1 т
A41: Площади для пересчёта расходников «на этаж» (как в основной книге)
A42: Прошлый объект (шаблон): этаж 18 × 18 м, м² | B42: =18*18 -> 324
A43: Надстройка: площадь плиты +21.750, м² | B43: 45.35 | C43: контур 6,95 × 7,095 м минус проёмы (лист «Проверки»)
A44: Гвозди 100 мм | B44: 250 | C44: кг на этаж 18×18
A45: Гвозди 70 мм | B45: 100 | C45: кг на этаж 18×18
A46: Пена монтажная | B46: 13 | C46: баллон на этаж 18×18
...

Sheet Ведомость
A1: Ведомость подсчёта арматуры — Блок 14, ул. Токомбаева — надстройка (технический этаж над лестницей и лифтом), отм. +18.350…+21.750, оси 3–4 / В–Г
A2: Общая длина = Кол-во элементов × Стержней в 1 элементе × Длина 1 шт.; Масса = Общая длина × кг/м. Синим — данные чертежей.
A4: № | B4: Конструкция | C4: Оси / место | D4: Марка | E4: Поз. | F4: Наименование | G4: Ø, мм | H4: Класс | I4: Шаг | J4: Кол-во элем. | K4: Стержней в элем. | L4: Длина 1 шт, м | M4: Общая длина, м | N4: кг/м | O4: Масса, кг | P4: Основание (лист, выноска) | Q4: Статус | R4: Примечание | S4: Группа | T4: Ключ
A5: 1 | B5: Колонны | C5: ось В: В/3, В/4 | D5: К-В | E5: 1 | F5: Вертикальные: угловые 4Ø32 (сеч.1-1) — ½ стержней, стык +800 | G5: 32 | H5: А500С | I5: — | J5: 2 | K5: 2 | L5: 2.55 | M5: =J5*K5*L5 -> 10.2 | N5: =INDEX(Исходные!$B$13:$B$25,MATCH(G5,Исходные!$A$13:$A$25,0)) -> 6.313 | O5: =M5*N5 -> 64.3926 | P5: АС-28 сеч.1-1; АС-22 рама В: над 18.350 колонны без выноски сечения → 1-1, как на 2–5 этажах; точки ванной сварки выше 18.350 | Q5: по проекту | R5: От стыка на +800 над +18.350 до верха плиты 21.750 − 50 = 2.55 м; на верхнем конце Аш (АС-30 узел «3», АС-31 Б-Б). | S5: Колонны | T5: К-В
A6: 2 | B6: Колонны | C6: ось В: В/3, В/4 | D6: К-В | E6: 5 | F6: Вертикальные: промежуточные 8Ø20 (сеч.1-1) — ½ стержней, стык +800 | G6: 20 | H6: А500С | I6: — | J6: 2 | K6: 4 | L6: 2.55 | M6: =J6*K6*L6 -> 20.4 | N6: =INDEX(Исходные!$B$13:$B$25,MATCH(G6,Исходные!$A$13:$A$25,0)) -> 2.466 | O6: =M6*N6 -> 50.3064 | P6: АС-28 сеч.1-1 поз.5 | Q6: по проекту | R6: L = 2.55 м. По АС-31 Б-Б «Аш-… свыше Ø20» — у Ø20 шайб нет; анкеровка Ø20 у верха не показана (ТРЕБУЕТСЯ УТОЧНЕНИЕ). | S6: Колонны | T6: К-В
A7: 3 | B7: Колонны | C7: ось В: В/3, В/4 | D7: К-В | E7: 1 | F7: Вертикальные: угловые 4Ø32 (сеч.1-1) — ½ стержней, стык +1300 | G7: 32 | H7: А500С | I7: — | J7: 2 | K7: 2 | L7: 2.05 | M7: =J7*K7*L7 -> 8.2 | N7: =INDEX(Исходные!$B$13:$B$25,MATCH(G7,Исходные!$A$13:$A$25,0)) -> 6.313 | O7: =M7*N7 -> 51.7666 | P7: АС-28 сеч.1-1; АС-22 рама В: над 18.350 колонны без выноски сечения → 1-1, как на 2–5 этажах; точки ванной сварки выше 18.350 | Q7: по проекту | R7: От стыка на +1300 над +18.350 до верха плиты 21.750 − 50 = 2.05 м; на верхнем конце Аш (АС-30 узел «3», АС-31 Б-Б). | S7: Колонны | T7: К-В
A8: 4 | B8: Колонны | C8: ось В: В/3, В/4 | D8: К-В | E8: 5 | F8: Вертикальные: промежуточные 8Ø20 (сеч.1-1) — ½ стержней, стык +1300 | G8: 20 | H8: А500С | I8: — | J8: 2 | K8: 4 | L8: 2.05 | M8: =J8*K8*L8 -> 16.4 | N8: =INDEX(Исходные!$B$13:$B$25,MATCH(G8,Исходные!$A$13:$A$25,0)) -> 2.466 | O8: =M8*N8 -> 40.4424 | P8: АС-28 сеч.1-1 поз.5 | Q8: по проекту | R8: L = 2.05 м. По АС-31 Б-Б «Аш-… свыше Ø20» — у Ø20 шайб нет; анкеровка Ø20 у верха не показана (ТРЕБУЕТСЯ УТОЧНЕНИЕ). | S8: Колонны | T8: К-В
A9: 5 | B9: Колонны | C9: ось В: В/3, В/4 | D9: К-В | E9: 10 | F9: Хомут наружный Ø8 L=2440: 13 + 1 + 13 = 27 шт (в свету 2800: 50+100×12+200+100×12+50) | G9: 8 | H9: А240 | I9: 100/200 | J9: 2 | K9: 27 | L9: 2.44 | M9: =J9*K9*L9 -> 131.76 | N9: =INDEX(Исходные!$B$13:$B$25,MATCH(G9,Исходные!$A$13:$A$25,0)) -> 0.395 | O9: =M9*N9 -> 52.0452 | P9: АС-28 поз.10 L=2440; шаг по АС-32 (схема дана до 18.350 — для тех. этажа принят тот же порядок) | Q9: принято (уточнить) | S9: Колонны | T9: К-В
A10: 6 | B10: Колонны | C10: ось В: В/3, В/4 | D10: К-В | E10: 11 | F10: Хомут внутренний Ø8 L=1960 ш.200: 2 шт × 15 рядов | G10: 8 | H10: А240 | I10: 200 | J10: 2 | K10: 30 | L10: 1.96 | M10: =J10*K10*L10 -> 117.6 | N10: =INDEX(Исходные!$B$13:$B$25,MATCH(G10,Исходные!$A$13:$A$25,0)) -> 0.395 | O10: =M10*N10 -> 46.452 | P10: АС-28 «11 хом.Ø8 ш.200», поз.11 L=1960; рядов 2800/200 + 1 = 15 | Q10: принято (уточнить) | S10: Колонны | T10: К-В
A11: 7 | B11: Колонны | C11: ось Г: Г/3, Г/4 | D11: К-Г | E11: 2 | F11: Вертикальные: угловые 4Ø28 (сеч.2-2) — ½ стержней, стык +800 | G11: 28 | H11: А500С | I11: — | J11: 2 | K11: 2 | L11: 2.55 | M11: =J11*K11*L11 -> 10.2 | N11: =INDEX(Исходные!$B$13:$B$25,MATCH(G11,Исходные!$A$13:$A$25,0)) -> 4.834 | O11: =M11*N11 -> 49.3068 | P11: АС-28 сеч.2-2; АС-23 рама Г: выноски «2-2 / 4Ø28 / 8Ø20» над 18.350 | Q11: по проекту | R11: От стыка на +800 над +18.350 до верха плиты 21.750 − 50 = 2.55 м; на верхнем конце Аш (АС-30 узел «3», АС-31 Б-Б). | S11: Колонны | T11: К-Г
A12: 8 | B12: Колонны | C12: ось Г: Г/3, Г/4 | D12: К-Г | E12: 5 | F12: Вертикальные: промежуточные 8Ø20 (сеч.2-2) — ½ стержней, стык +800 | G12: 20 | H12: А500С | I12: — | J12: 2 | K12: 4 | L12: 2.55 | M12: =J12*K12*L12 -> 20.4 | N12: =INDEX(Исходные!$B$13:$B$25,MATCH(G12,Исходные!$A$13:$A$25,0)) -> 2.466 | O12: =M12*N12 -> 50.3064 | P12: АС-28 сеч.2-2 поз.5 | Q12: по проекту | R12: L = 2.55 м. По АС-31 Б-Б «Аш-… свыше Ø20» — у Ø20 шайб нет; анкеровка Ø20 у верха не показана (ТРЕБУЕТСЯ УТОЧНЕНИЕ). | S12: Колонны | T12: К-Г
A13: 9 | B13: Колонны | C13: ось Г: Г/3, Г/4 | D13: К-Г | E13: 2 | F13: Вертикальные: угловые 4Ø28 (сеч.2-2) — ½ стержней, стык +1300 | G13: 28 | H13: А500С | I13: — | J13: 2 | K13: 2 | L13: 2.05 | M13: =J13*K13*L13 -> 8.2 | N13: =INDEX(Исходные!$B$13:$B$25,MATCH(G13,Исходные!$A$13:$A$25,0)) -> 4.834 | O13: =M13*N13 -> 39.6388 | P13: АС-28 сеч.2-2; АС-23 рама Г: выноски «2-2 / 4Ø28 / 8Ø20» над 18.350 | Q13: по проекту | R13: От стыка на +1300 над +18.350 до верха плиты 21.750 − 50 = 2.05 м; на верхнем конце Аш (АС-30 узел «3», АС-31 Б-Б). | S13: Колонны | T13: К-Г
A14: 10 | B14: Колонны | C14: ось Г: Г/3, Г/4 | D14: К-Г | E14: 5 | F14: Вертикальные: промежуточные 8Ø20 (сеч.2-2) — ½ стержней, стык +1300 | G14: 20 | H14: А500С | I14: — | J14: 2 | K14: 4 | L14: 2.05 | M14: =J14*K14*L14 -> 16.4 | N14: =INDEX(Исходные!$B$13:$B$25,MATCH(G14,Исходные!$A$13:$A$25,0)) -> 2.466 | O14: =M14*N14 -> 40.4424 | P14: АС-28 сеч.2-2 поз.5 | Q14: по проекту | R14: L = 2.05 м. По АС-31 Б-Б «Аш-… свыше Ø20» — у Ø20 шайб нет; анкеровка Ø20 у верха не показана (ТРЕБУЕТСЯ УТОЧНЕНИЕ). | S14: Колонны | T14: К-Г
A15: 11 | B15: Колонны | C15: ось Г: Г/3, Г/4 | D15: К-Г | E15: 10 | F15: Хомут наружный Ø8 L=2440: 13 + 1 + 13 = 27 шт (в свету 2800: 50+100×12+200+100×12+50) | G15: 8 | H15: А240 | I15: 100/200 | J15: 2 | K15: 27 | L15: 2.44 | M15: =J15*K15*L15 -> 131.76 | N15: =INDEX(Исходные!$B$13:$B$25,MATCH(G15,Исходные!$A$13:$A$25,0)) -> 0.395 | O15: =M15*N15 -> 52.0452 | P15: АС-28 поз.10 L=2440; шаг по АС-32 (схема дана до 18.350 — для тех. этажа принят тот же порядок) | Q15: принято (уточнить) | S15: Колонны | T15: К-Г
A16: 12 | B16: Колонны | C16: ось Г: Г/3, Г/4 | D16: К-Г | E16: 11 | F16: Хомут внутренний Ø8 L=1960 ш.200: 2 шт × 15 рядов | G16: 8 | H16: А240 | I16: 200 | J16: 2 | K16: 30 | L16: 1.96 | M16: =J16*K16*L16 -> 117.6 | N16: =INDEX(Исходные!$B$13:$B$25,MATCH(G16,Исходные!$A$13:$A$25,0)) -> 0.395 | O16: =M16*N16 -> 46.452 | P16: АС-28 «11 хом.Ø8 ш.200», поз.11 L=1960; рядов 2800/200 + 1 = 15 | Q16: принято (уточнить) | S16: Колонны | T16: К-Г
A17: 13 | B17: Ригели | C17: ось В, оси 3–4 (отм. +21.750) | D17: Р-В | E17: 2 | F17: Продольные угловые 4Ø28 (сеч.4-4), концы с Аш | G17: 28 | H17: А500С | I17: — | J17: 1 | K17: 4 | L17: 7 | M17: =J17*K17*L17 -> 28 | N17: =INDEX(Исходные!$B$13:$B$25,MATCH(G17,Исходные!$A$13:$A$25,0)) -> 4.834 | O17: =M17*N17 -> 135.352 | P17: АС-22 верхний ярус: выноска «4-4 / 4Ø28 / 2Ø18 / 2Ø16»; L = 6500 + 2×250 (до наружной грани крайних колонн, АС-30 узел «3») | Q17: по геометрии чертежа | S17: Ригели, балки, плита, С-1 | T17: Р-В
A18: 14 | B18: Ригели | C18: ось В, оси 3–4 (отм. +21.750) | D18: Р-В | E18: 6 | F18: Продольные средние верх/низ 2Ø18 (сеч.4-4), концы с Аш | G18: 18 | H18: А500С | I18: — | J18: 1 | K18: 2 | L18: 7 | M18: =J18*K18*L18 -> 14 | N18: =INDEX(Исходные!$B$13:$B$25,MATCH(G18,Исходные!$A$13:$A$25,0)) -> 1.998 | O18: =M18*N18 -> 27.972 | P18: АС-28 сеч.4-4 поз.6 | Q18: по геометрии чертежа | S18: Ригели, балки, плита, С-1 | T18: Р-В
A19: 15 | B19: Ригели | C19: ось В, оси 3–4 (отм. +21.750) | D19: Р-В | E19: 7 | F19: Боковые стержни 2Ø16 (сеч.4-4) | G19: 16 | H19: А500С | I19: — | J19: 1 | K19: 2 | L19: 7 | M19: =J19*K19*L19 -> 14 | N19: =INDEX(Исходные!$B$13:$B$25,MATCH(G19,Исходные!$A$13:$A$25,0)) -> 1.578 | O19: =M19*N19 -> 22.092 | P19: АС-28 сеч.4-4 поз.7 | Q19: по геометрии чертежа | S19: Ригели, балки, плита, С-1 | T19: Р-В
A20: 16 | B20: Ригели | C20: ось В, оси 3–4 (отм. +21.750) | D20: Р-В | E20: 12 | F20: Хомут Ø8 L=2060 ш.100 у опор (100×12), ш.150 в пролёте, 80×4 у балок плиты | G20: 8 | H20: А240 | I20: 100/150 | J20: 1 | K20: 51 | L20: 2.06 | M20: =J20*K20*L20 -> 105.06 | N20: =INDEX(Исходные!$B$13:$B$25,MATCH(G20,Исходные!$A$13:$A$25,0)) -> 0.395 | O20: =M20*N20 -> 41.4987 | P20: АС-28 поз.12; АС-29 «Расстановка хомутов в ригелях»; штриховки на ярусе 21.750 нет | Q20: по проекту | R20: Пролёт в свету 300…6200 мм, балки плиты в точках [1200, 4050] | S20: Ригели, балки, плита, С-1 | T20: Р-В
A21: 17 | B21: Ригели | C21: ось В, оси 3–4 (отм. +21.750) | D21: Р-В | E21: 17 | F21: Шпилька вертикальная Ø8 L=750: ш.200 у опор, ш.150 в пролёте | G21: 8 | H21: А240 | I21: 200/150 | J21: 1 | K21: 30 | L21: 0.75 | M21: =J21*K21*L21 -> 22.5 | N21: =INDEX(Исходные!$B$13:$B$25,MATCH(G21,Исходные!$A$13:$A$25,0)) -> 0.395 | O21: =M21*N21 -> 8.8875 | P21: АС-28 поз.17 | Q21: по проекту | S21: Ригели, балки, плита, С-1 | T21: Р-В
A22: 18 | B22: Ригели | C22: ось В, оси 3–4 (отм. +21.750) | D22: Р-В | E22: 16 | F22: Шпилька горизонтальная Ø8 L=580 ш.300 | G22: 8 | H22: А240 | I22: 300 | J22: 1 | K22: 20 | L22: 0.58 | M22: =J22*K22*L22 -> 11.6 | N22: =INDEX(Исходные!$B$13:$B$25,MATCH(G22,Исходные!$A$13:$A$25,0)) -> 0.395 | O22: =M22*N22 -> 4.582 | P22: АС-28 «шп.Ø8 А240 ш.300», поз.16 | Q22: принято (уточнить) | S22: Ригели, балки, плита, С-1 | T22: Р-В
A23: 19 | B23: Ригели | C23: ось Г, оси 3–4 (отм. +21.750) | D23: Р-Г | E23: 2 | F23: Продольные угловые 4Ø28 (сеч.4-4), концы с Аш | G23: 28 | H23: А500С | I23: — | J23: 1 | K23: 4 | L23: 7 | M23: =J23*K23*L23 -> 28 | N23: =INDEX(Исходные!$B$13:$B$25,MATCH(G23,Исходные!$A$13:$A$25,0)) -> 4.834 | O23: =M23*N23 -> 135.352 | P23: АС-23 верхний ярус: выноска «4-4 / 4Ø28 / 2Ø18 / 2Ø16»; L = 6500 + 2×250 (до наружной грани крайних колонн, АС-30 узел «3») | Q23: по геометрии чертежа | S23: Ригели, балки, плита, С-1 | T23: Р-Г
A24: 20 | B24: Ригели | C24: ось Г, оси 3–4 (отм. +21.750) | D24: Р-Г | E24: 6 | F24: Продольные средние верх/низ 2Ø18 (сеч.4-4), концы с Аш | G24: 18 | H24: А500С | I24: — | J24: 1 | K24: 2 | L24: 7 | M24: =J24*K24*L24 -> 14 | N24: =INDEX(Исходные!$B$13:$B$25,MATCH(G24,Исходные!$A$13:$A$25,0)) -> 1.998 | O24: =M24*N24 -> 27.972 | P24: АС-28 сеч.4-4 поз.6 | Q24: по геометрии чертежа | S24: Ригели, балки, плита, С-1 | T24: Р-Г
A25: 21 | B25: Ригели | C25: ось Г, оси 3–4 (отм. +21.750) | D25: Р-Г | E25: 7 | F25: Боковые стержни 2Ø16 (сеч.4-4) | G25: 16 | H25: А500С | I25: — | J25: 1 | K25: 2 | L25: 7 | M25: =J25*K25*L25 -> 14 | N25: =INDEX(Исходные!$B$13:$B$25,MATCH(G25,Исходные!$A$13:$A$25,0)) -> 1.578 | O25: =M25*N25 -> 22.092 | P25: АС-28 сеч.4-4 поз.7 | Q25: по геометрии чертежа | S25: Ригели, балки, плита, С-1 | T25: Р-Г
A26: 22 | B26: Ригели | C26: ось Г, оси 3–4 (отм. +21.750) | D26: Р-Г | E26: 12 | F26: Хомут Ø8 L=2060 ш.100 у опор (100×12), ш.150 в пролёте, 80×4 у балок плиты | G26: 8 | H26: А240 | I26: 100/150 | J26: 1 | K26: 48 | L26: 2.06 | M26: =J26*K26*L26 -> 98.88 | N26: =INDEX(Исходные!$B$13:$B$25,MATCH(G26,Исходные!$A$13:$A$25,0)) -> 0.395 | O26: =M26*N26 -> 39.0576 | P26: АС-28 поз.12; АС-29 «Расстановка хомутов в ригелях»; штриховки на ярусе 21.750 нет | Q26: по проекту | R26: Пролёт в свету 300…6200 мм, балки плиты в точках [4050] | S26: Ригели, балки, плита, С-1 | T26: Р-Г
A27: 23 | B27: Ригели | C27: ось Г, оси 3–4 (отм. +21.750) | D27: Р-Г | E27: 17 | F27: Шпилька вертикальная Ø8 L=750: ш.200 у опор, ш.150 в пролёте | G27: 8 | H27: А240 | I27: 200/150 | J27: 1 | K27: 32 | L27: 0.75 | M27: =J27*K27*L27 -> 24 | N27: =INDEX(Исходные!$B$13:$B$25,MATCH(G27,Исходные!$A$13:$A$25,0)) -> 0.395 | O27: =M27*N27 -> 9.48 | P27: АС-28 поз.17 | Q27: по проекту | S27: Ригели, балки, плита, С-1 | T27: Р-Г
A28: 24 | B28: Ригели | C28: ось Г, оси 3–4 (отм. +21.750) | D28: Р-Г | E28: 16 | F28: Шпилька горизонтальная Ø8 L=580 ш.300 | G28: 8 | H28: А240 | I28: 300 | J28: 1 | K28: 20 | L28: 0.58 | M28: =J28*K28*L28 -> 11.6 | N28: =INDEX(Исходные!$B$13:$B$25,MATCH(G28,Исходные!$A$13:$A$25,0)) -> 0.395 | O28: =M28*N28 -> 4.582 | P28: АС-28 «шп.Ø8 А240 ш.300», поз.16 | Q28: принято (уточнить) | S28: Ригели, балки, плита, С-1 | T28: Р-Г
A29: 25 | B29: Ригели | C29: ось 3, оси В–Г (отм. +21.750) | D29: Р-3 | E29: 2 | F29: Продольные угловые 4Ø28 (сеч.5-5), концы с Аш | G29: 28 | H29: А500С | I29: — | J29: 1 | K29: 4 | L29: 7 | M29: =J29*K29*L29 -> 28 | N29: =INDEX(Исходные!$B$13:$B$25,MATCH(G29,Исходные!$A$13:$A$25,0)) -> 4.834 | O29: =M29*N29 -> 135.352 | P29: АС-26 верхний ярус: выноска «5-5 / 4Ø28 / 2Ø18 / 2Ø16»; L = 6500 + 2×250 (до наружной грани крайних колонн, АС-30 узел «3») | Q29: по геометрии чертежа | S29: Ригели, балки, плита, С-1 | T29: Р-3
A30: 26 | B30: Ригели | C30: ось 3, оси В–Г (отм. +21.750) | D30: Р-3 | E30: 6 | F30: Продольные средние верх/низ 2Ø18 (сеч.5-5), концы с Аш | G30: 18 | H30: А500С | I30: — | J30: 1 | K30: 2 | L30: 7 | M30: =J30*K30*L30 -> 14 | N30: =INDEX(Исходные!$B$13:$B$25,MATCH(G30,Исходные!$A$13:$A$25,0)) -> 1.998 | O30: =M30*N30 -> 27.972 | P30: АС-28 сеч.5-5 поз.6 | Q30: по геометрии чертежа | S30: Ригели, балки, плита, С-1 | T30: Р-3
A31: 27 | B31: Ригели | C31: ось 3, оси В–Г (отм. +21.750) | D31: Р-3 | E31: 7 | F31: Боковые стержни 2Ø16 (сеч.5-5) | G31: 16 | H31: А500С | I31: — | J31: 1 | K31: 2 | L31: 7 | M31: =J31*K31*L31 -> 14 | N31: =INDEX(Исходные!$B$13:$B$25,MATCH(G31,Исходные!$A$13:$A$25,0)) -> 1.578 | O31: =M31*N31 -> 22.092 | P31: АС-28 сеч.5-5 поз.7 | Q31: по геометрии чертежа | S31: Ригели, балки, плита, С-1 | T31: Р-3
A32: 28 | B32: Ригели | C32: ось 3, оси В–Г (отм. +21.750) | D32: Р-3 | E32: 12 | F32: Хомут Ø8 L=2060 ш.100 у опор (100×12), ш.150 в пролёте, 80×4 у балок плиты | G32: 8 | H32: А240 | I32: 100/150 | J32: 1 | K32: 47 | L32: 2.06 | M32: =J32*K32*L32 -> 96.82 | N32: =INDEX(Исходные!$B$13:$B$25,MATCH(G32,Исходные!$A$13:$A$25,0)) -> 0.395 | O32: =M32*N32 -> 38.2439 | P32: АС-28 поз.12; АС-29 «Расстановка хомутов в ригелях»; штриховки на ярусе 21.750 нет | Q32: по проекту | R32: Пролёт в свету 300…6200 мм, балки плиты в точках [3460] | S32: Ригели, балки, плита, С-1 | T32: Р-3
A33: 29 | B33: Ригели | C33: ось 3, оси В–Г (отм. +21.750) | D33: Р-3 | E33: 17 | F33: Шпилька вертикальная Ø8 L=750: ш.200 у опор, ш.150 в пролёте | G33: 8 | H33: А240 | I33: 200/150 | J33: 1 | K33: 33 | L33: 0.75 | M33: =J33*K33*L33 -> 24.75 | N33: =INDEX(Исходные!$B$13:$B$25,MATCH(G33,Исходные!$A$13:$A$25,0)) -> 0.395 | O33: =M33*N33 -> 9.77625 | P33: АС-28 поз.17 | Q33: по проекту | S33: Ригели, балки, плита, С-1 | T33: Р-3
A34: 30 | B34: Ригели | C34: ось 3, оси В–Г (отм. +21.750) | D34: Р-3 | E34: 16 | F34: Шпилька горизонтальная Ø8 L=580 ш.300 | G34: 8 | H34: А240 | I34: 300 | J34: 1 | K34: 20 | L34: 0.58 | M34: =J34*K34*L34 -> 11.6 | N34: =INDEX(Исходные!$B$13:$B$25,MATCH(G34,Исходные!$A$13:$A$25,0)) -> 0.395 | O34: =M34*N34 -> 4.582 | P34: АС-28 «шп.Ø8 А240 ш.300», поз.16 | Q34: принято (уточнить) | S34: Ригели, балки, плита, С-1 | T34: Р-3
A35: 31 | B35: Ригели | C35: ось 4, оси В–Г (отм. +21.750) | D35: Р-4 | E35: 2 | F35: Продольные угловые 4Ø28 (сеч.5-5), концы с Аш | G35: 28 | H35: А500С | I35: — | J35: 1 | K35: 4 | L35: 7 | M35: =J35*K35*L35 -> 28 | N35: =INDEX(Исходные!$B$13:$B$25,MATCH(G35,Исходные!$A$13:$A$25,0)) -> 4.834 | O35: =M35*N35 -> 135.352 | P35: АС-27 верхний ярус: выноска «5-5 / 4Ø28 / 2Ø18 / 2Ø16»; L = 6500 + 2×250 (до наружной грани крайних колонн, АС-30 узел «3») | Q35: по геометрии чертежа | S35: Ригели, балки, плита, С-1 | T35: Р-4
A36: 32 | B36: Ригели | C36: ось 4, оси В–Г (отм. +21.750) | D36: Р-4 | E36: 6 | F36: Продольные средние верх/низ 2Ø18 (сеч.5-5), концы с Аш | G36: 18 | H36: А500С | I36: — | J36: 1 | K36: 2 | L36: 7 | M36: =J36*K36*L36 -> 14 | N36: =INDEX(Исходные!$B$13:$B$25,MATCH(G36,Исходные!$A$13:$A$25,0)) -> 1.998 | O36: =M36*N36 -> 27.972 | P36: АС-28 сеч.5-5 поз.6 | Q36: по геометрии чертежа | S36: Ригели, балки, плита, С-1 | T36: Р-4
A37: 33 | B37: Ригели | C37: ось 4, оси В–Г (отм. +21.750) | D37: Р-4 | E37: 7 | F37: Боковые стержни 2Ø16 (сеч.5-5) | G37: 16 | H37: А500С | I37: — | J37: 1 | K37: 2 | L37: 7 | M37: =J37*K37*L37 -> 14 | N37: =INDEX(Исходные!$B$13:$B$25,MATCH(G37,Исходные!$A$13:$A$25,0)) -> 1.578 | O37: =M37*N37 -> 22.092 | P37: АС-28 сеч.5-5 поз.7 | Q37: по геометрии чертежа | S37: Ригели, балки, плита, С-1 | T37: Р-4
A38: 34 | B38: Ригели | C38: ось 4, оси В–Г (отм. +21.750) | D38: Р-4 | E38: 12 | F38: Хомут Ø8 L=2060 ш.100 у опор (100×12), ш.150 в пролёте, 80×4 у балок плиты | G38: 8 | H38: А240 | I38: 100/150 | J38: 1 | K38: 47 | L38: 2.06 | M38: =J38*K38*L38 -> 96.82 | N38: =INDEX(Исходные!$B$13:$B$25,MATCH(G38,Исходные!$A$13:$A$25,0)) -> 0.395 | O38: =M38*N38 -> 38.2439 | P38: АС-28 поз.12; АС-29 «Расстановка хомутов в ригелях»; штриховки на ярусе 21.750 нет | Q38: по проекту | R38: Пролёт в свету 300…6200 мм, балки плиты в точках [3460] | S38: Ригели, балки, плита, С-1 | T38: Р-4
A39: 35 | B39: Ригели | C39: ось 4, оси В–Г (отм. +21.750) | D39: Р-4 | E39: 17 | F39: Шпилька вертикальная Ø8 L=750: ш.200 у опор, ш.150 в пролёте | G39: 8 | H39: А240 | I39: 200/150 | J39: 1 | K39: 33 | L39: 0.75 | M39: =J39*K39*L39 -> 24.75 | N39: =INDEX(Исходные!$B$13:$B$25,MATCH(G39,Исходные!$A$13:$A$25,0)) -> 0.395 | O39: =M39*N39 -> 9.77625 | P39: АС-28 поз.17 | Q39: по проекту | S39: Ригели, балки, плита, С-1 | T39: Р-4
A40: 36 | B40: Ригели | C40: ось 4, оси В–Г (отм. +21.750) | D40: Р-4 | E40: 16 | F40: Шпилька горизонтальная Ø8 L=580 ш.300 | G40: 8 | H40: А240 | I40: 300 | J40: 1 | K40: 20 | L40: 0.58 | M40: =J40*K40*L40 -> 11.6 | N40: =INDEX(Исходные!$B$13:$B$25,MATCH(G40,Исходные!$A$13:$A$25,0)) -> 0.395 | O40: =M40*N40 -> 4.582 | P40: АС-28 «шп.Ø8 А240 ш.300», поз.16 | Q40: принято (уточнить) | S40: Ригели, балки, плита, С-1 | T40: Р-4
A41: 37 | B41: Плита перекрытия | C41: 3–4 / В–Г | D41: ПМ-21.750 | E41: НX | F41: Нижняя осн. сетка, направление X (вдоль осей 3–4) | G41: 10 | H41: А500С | I41: 200 | J41: 1 | K41: 21 | L41: 6.9 | M41: =J41*K41*L41 -> 144.9 | N41: =INDEX(Исходные!$B$13:$B$25,MATCH(G41,Исходные!$A$13:$A$25,0)) -> 0.617 | O41: =M41*N41 -> 89.4033 | P41: АС-52 «План перекрытия на отм. 21.750»: «Осн. сетка Ø10 А500С ш.200×200» (верх и низ, как АС-54) | Q41: по геометрии чертежа | S41: Ригели, балки, плита, С-1 | T41: П-сетка
...

Sheet Раскрой 11,7м
A1: Раскрой под прутки 11,7 м — надстройка (самостоятельный заказ)
A3: Ø | B3: Класс | C3: Чистая длина, м | D3: Прутков 11,7 м, шт | E3: Масса заказа, кг | F3: Чистая масса, кг | G3: Отход, кг | H3: Отход, % | I3: Схемы раскроя (длины деталей, м × шт в прутке) × кол-во прутков
A4: 32 | B4: А500С | C4: 18.4 | D4: 2 | E4: =D4*Исходные!$B$8*INDEX(Исходные!$B$13:$B$25,MATCH(A4,Исходные!$A$13:$A$25,0)) -> 147.7242 | F4: =C4*INDEX(Исходные!$B$13:$B$25,MATCH(A4,Исходные!$A$13:$A$25,0)) -> 116.1592 | G4: =E4-F4 -> 31.565 | H4: =IF(E4>0,G4/E4,0) -> 0.21367521 | I4: 2.55×4 → 1 пр.; 2.05×4 → 1 пр.
A5: 28 | B5: А500С | C5: 130.4 | D5: 16 | E5: =D5*Исходные!$B$8*INDEX(Исходные!$B$13:$B$25,MATCH(A5,Исходные!$A$13:$A$25,0)) -> 904.9248 | F5: =C5*INDEX(Исходные!$B$13:$B$25,MATCH(A5,Исходные!$A$13:$A$25,0)) -> 630.3536 | G5: =E5-F5 -> 274.5712 | H5: =IF(E5>0,G5/E5,0) -> 0.3034188 | I5: 7×1 + 2.55×1 + 2.05×1 → 4 пр.; 7×1 → 12 пр.
A6: 25 | B6: А500С | C6: 55.2 | D6: 8 | E6: =D6*Исходные!$B$8*INDEX(Исходные!$B$13:$B$25,MATCH(A6,Исходные!$A$13:$A$25,0)) -> 360.6408 | F6: =C6*INDEX(Исходные!$B$13:$B$25,MATCH(A6,Исходные!$A$13:$A$25,0)) -> 212.6856 | G6: =E6-F6 -> 147.9552 | H6: =IF(E6>0,G6/E6,0) -> 0.41025641 | I6: 6.9×1 → 8 пр.
A7: 20 | B7: А500С | C7: 100.94 | D7: 10 | E7: =D7*Исходные!$B$8*INDEX(Исходные!$B$13:$B$25,MATCH(A7,Исходные!$A$13:$A$25,0)) -> 288.522 | F7: =C7*INDEX(Исходные!$B$13:$B$25,MATCH(A7,Исходные!$A$13:$A$25,0)) -> 248.91804 | G7: =E7-F7 -> 39.60396 | H7: =IF(E7>0,G7/E7,0) -> 0.13726496 | I7: 3.785×3 → 1 пр.; 2.55×2 + 2.05×3 → 1 пр.; 3.05×2 + 2.55×2 → 1 пр.; 2.05×5 → 2 пр.; 2.55×4 → 3 пр.; 3.785×1 + 3.05×2 → 1 пр.; 2.05×3 → 1 пр.
A8: 18 | B8: А500С | C8: 56 | D8: 8 | E8: =D8*Исходные!$B$8*INDEX(Исходные!$B$13:$B$25,MATCH(A8,Исходные!$A$13:$A$25,0)) -> 187.0128 | F8: =C8*INDEX(Исходные!$B$13:$B$25,MATCH(A8,Исходные!$A$13:$A$25,0)) -> 111.888 | G8: =E8-F8 -> 75.1248 | H8: =IF(E8>0,G8/E8,0) -> 0.4017094 | I8: 7×1 → 8 пр.
A9: 16 | B9: А500С | C9: 56 | D9: 8 | E9: =D9*Исходные!$B$8*INDEX(Исходные!$B$13:$B$25,MATCH(A9,Исходные!$A$13:$A$25,0)) -> 147.7008 | F9: =C9*INDEX(Исходные!$B$13:$B$25,MATCH(A9,Исходные!$A$13:$A$25,0)) -> 88.368 | G9: =E9-F9 -> 59.3328 | H9: =IF(E9>0,G9/E9,0) -> 0.4017094 | I9: 7×1 → 8 пр.
A10: 10 | B10: А500С | C10: 1071.61 | D10: 104 | E10: =D10*Исходные!$B$8*INDEX(Исходные!$B$13:$B$25,MATCH(A10,Исходные!$A$13:$A$25,0)) -> 750.7656 | F10: =C10*INDEX(Исходные!$B$13:$B$25,MATCH(A10,Исходные!$A$13:$A$25,0)) -> 661.18337 | G10: =E10-F10 -> 89.58223 | H10: =IF(E10>0,G10/E10,0) -> 0.11932117 | I10: 6.9×1 + 0.4×12 → 4 пр.; 7.045×1 + 3.51×1 + 0.57×2 → 8 пр.; 6.11×1 + 5.575×1 → 26 пр.; 7.045×1 + 0.57×8 → 24 пр.; 6.9×1 + 0.57×4 + 0.4×6 → 1 пр.; 7.045×1 + 2.775×1 + 0.57×3 → 4 пр.; 6.9×1 + 0.57×8 → 7 пр.; 6.9×1 + 0.4×10 → 1 пр.; 6.9×1 → 29 пр.
A11: 10 | B11: А240 | C11: 29.82 | D11: 3 | E11: =D11*Исходные!$B$8*INDEX(Исходные!$B$13:$B$25,MATCH(A11,Исходные!$A$13:$A$25,0)) -> 21.6567 | F11: =C11*INDEX(Исходные!$B$13:$B$25,MATCH(A11,Исходные!$A$13:$A$25,0)) -> 18.39894 | G11: =E11-F11 -> 3.25776 | H11: =IF(E11>0,G11/E11,0) -> 0.15042735 | I11: 0.42×27 → 2 пр.; 0.42×17 → 1 пр.
A12: 8 | B12: А240 | C12: 1211.88 | D12: 105 | E12: =D12*Исходные!$B$8*INDEX(Исходные!$B$13:$B$25,MATCH(A12,Исходные!$A$13:$A$25,0)) -> 485.2575 | F12: =C12*INDEX(Исходные!$B$13:$B$25,MATCH(A12,Исходные!$A$13:$A$25,0)) -> 478.6926 | G12: =E12-F12 -> 6.5649 | H12: =IF(E12>0,G12/E12,0) -> 0.013528694 | I12: 1.96×3 + 1.24×2 + 1.04×3 + 0.22×1 → 1 пр.; 0.75×15 + 0.22×2 → 8 пр.; 1.04×11 + 0.22×1 → 3 пр.; 1.96×5 + 1.24×1 + 0.58×1 → 23 пр.; 1.04×7 + 0.75×5 + 0.58×1 → 1 пр.; 2.44×4 + 1.24×1 + 0.58×1 → 27 пр.; 2.06×3 + 1.96×2 + 1.24×1 + 0.22×1 → 1 пр.; 2.06×5 + 1.24×1 → 38 пр.; 0.75×3 + 0.58×16 → 1 пр.; 0.58×13 + 0.22×18 → 1 пр.; 0.22×32 → 1 пр.
B13: ИТОГО | D13: =SUM(D4:D12) -> 264 | E13: =SUM(E4:E12) -> 3294.2052 | F13: =SUM(F4:F12) -> 2566.6474 | G13: =SUM(G4:G12) -> 727.55785 | H13: =IF(E13>0,G13/E13,0) -> 0.22085991
A15: Отход большой на коротких деталях (колонны 2,55/2,05 м, ригели 7,0 м, балки 6,9 м): остатки 4,6–4,8 м можно пустить на детали 5 этажа и ниже, если заказывать вместе.

Sheet Проверки
A1: Проверки и принятые решения — надстройка
A3: ПРИНЯТЫЕ РЕШЕНИЯ
A4: Состав надстройки | B4: АС-19 «Монтажная схема рам на отм. 21.750»: 4 колонны В/3, В/4, Г/3, Г/4 (6500 × 6500); рамы В, Г, 3, 4 — верхний ярус +21.750; АС-52 «План перекрытия на отм. 21.750».
A5: Колонны В/3, В/4 | B5: На раме В над +18.350 выноски сечения нет → сечение 1-1 (4Ø32 + 8Ø20), как на 2–5 этажах; на колоннах выше 18.350 — точки ванной сварки (стыки +800 / +1300).
A6: Колонны Г/3, Г/4 | B6: Рама Г: выноски «2-2 / 4Ø28 / 8Ø20» над 18.350.
A7: Длина вертикалей | B7: От стыка над +18.350 (½ стержней на +800, ½ на +1300 — АС-32) до верха плиты 21.750 − 50: 2,55 и 2,05 м; на верхних концах угловых стержней — Аш (АС-30 узел «3», АС-31 Б-Б).
A8: Ø20 колонн вверху | B8: АС-31 Б-Б: «Аш-… свыше Ø20» → на 8Ø20 шайб нет; как анкеруются Ø20 у верха, не показано — ТРЕБУЕТСЯ УТОЧНЕНИЕ (принято прямо, без отгиба).
A9: Хомуты колонн | B9: Схема АС-32 дана до 18.350. Для тех. этажа (в свету 3400 − 600 = 2800) принят тот же порядок: 50 + 100×12 + 200 + 100×12 + 50 → 27 наружных Ø8 L=2440, внутренние Ø8 L=1960 ш.200 — 2 × 15 рядов. Уточнить.
A10: Ригели +21.750 | B10: Рамы В, Г — сеч.4-4, рамы 3, 4 — сеч.5-5: 4Ø28 + 2Ø18 + 2Ø16; ОС/Ос и штриховки на ярусе нет. Длина 6500 + 2 × 250 = 7,0 м (до наружной грани крайних колонн, Аш). Хомуты поз.12 ш.100 у опор / 150 в пролёте, 80×4 у балок плиты; шпильки поз.16, 17.
A11: Плита +21.750 | B11: Контур по наружным граням ригелей 3, 4, В и со свесом 370 за ось Г (6,95 × 7,095 м); проёмы: шахта лифта 875 × 3085 мм (от ригеля 3 до 1100 от оси 3), проём у оси В 2600 × 485 мм. Осн. сетка Ø10 ш.200 верх и низ (стержни ≤ 7,05 м — без нахлёстов); Ф-1 и шпильки по площади.
A12: Балки плиты | B12: Две балки 1-1 крестом (300 мм, 2Ø25 + 2Ø25, L = 6,9 м — до наружных граней ригелей); две балки 4-4 (200 мм, 2Ø20 + 2Ø20): у шахты (от ригеля В до балки 1-1, L = 3,785 м) и над проёмом (L = 3,05 м). Хомуты по АС-57 (100×10 у опор при L > 6 м, ×3 у пересечений).
A13: С-1 | B13: АС-30 узел «3»: 5 рядов «попарно шаг 90» → 4 узла × 10 = 40 сеток 7Ø10 × 0,57.
A14: ОБНАРУЖЕНО ПРОТИВОРЕЧИЕ: Г/3, Г/4 | B14: На раме Г колонны надстройки есть (сеч.2-2), но сварки выше 18.350 не показаны, а на развёртках Дм-4 / Дм-5 (АС-40, 41) у всех стержней на 18.350 — Аш. Принято: колонны надстройки как у В/3, В/4 (стык над 18.350). Если стержни 2-2 надстройки должны заанкериваться в Дм — длина выпусков не указана, уточнить у проектировщика.
A15: Свес 370 | B15: Свес 370 за ось Г показан на плане 21.750; торцевых стержней сеч.6-6 и выпусков парапета на этом плане нет — не считались.
A17: КОНТРОЛЬНЫЕ ЦИФРЫ
A18: Чистая масса арматуры, кг | B18: =Ведомость!O66 -> 2566.6474
A19: Бетон В25, м³ | B19: ='По осям'!M22 -> 16.10466
A20: Сумма контрольных разниц (должна быть 0) | B20: =ABS('По осям'!O19)+ABS(потребность!E15) -> 0
